Workbook
Name _________xlfn.ROUNDBAHTUP: #NAME?
Name ________xlfn.ROUNDBAHTUP: #NAME?
Name _______xlfn.ROUNDBAHTUP: #NAME?
Name ______xlfn.BAHTTEXT: #NAME?
Name ______xlfn.ROUNDBAHTUP: #NAME?
Name _____xlfn.BAHTTEXT: #NAME?
Name _____xlfn.ROUNDBAHTUP: #NAME?
Name ____xlfn.BAHTTEXT: #NAME?
Name ____xlfn.ROUNDBAHTUP: #NAME?
Name ___xlfn.BAHTTEXT: #NAME?
Name ___xlfn.ROUNDBAHTUP: #NAME?
Name __xlfn.BAHTTEXT: #NAME?
Name __xlfn.ROUNDBAHTUP: #NAME?
Name aaaaaaaaaaaaaaa: ErrorHandler_1
Name aaaaaaaaaaaaaaa: ErrorHandler_1
Name aaaaaaaaaaaaaaa: ErrorHandler_1
Name ADGAEG: {0,0,0,0}
Name ADGAEG: {0,0,0,0}
Name AGAEGADGAG: {0,0,0,0}
Name AGAEGADGAG: {0,0,0,0}
Name AGAEGAG: {0,0,0,0}
Name AGAEGAG: {0,0,0,0}
Name AGAEGDG: {0,0,0,0}
Name AGAEGDG: {0,0,0,0}
Name area: PI()*1.5^2/4
Name coping: BLCH
Name coping: BLCH
Name coping: BLCH
Name DGAEGA: {0,0,0,0}
Name DGAEGA: {0,0,0,0}
Name DNFLSKF: ErrorHandler_1
Name DNFLSKF: ErrorHandler_1
Name DNFLSKF: ErrorHandler_1
Name fdsa: {#N/A,#N/A,FALSE,"명세표"}
Name fdsa: {#N/A,#N/A,FALSE,"명세표"}
Name foo: ErrorHandler_1
Name foo: ErrorHandler_1
Name foo: ErrorHandler_1
Name gdsfdsa: {0,0,0,0}
Name gdsfdsa: {0,0,0,0}
Name HTML_CodePage: 949
Name HTML_Description: ""
Name HTML_Email: "keppler@dava.kepco.co.kr"
Name HTML_Header: "220승압 기준단가(승압,계기분야)"
Name HTML_LastUpdate: "2000-11-21"
Name HTML_LineAfter: FALSE
Name HTML_LineBefore: TRUE
Name HTML_Name: "이정렬"
Name HTML_OBDlg2: TRUE
Name HTML_OBDlg4: TRUE
Name HTML_OS: 0
Name HTML_PathFile: "D:\My Documents\98기준단가.htm"
Name HTML_Title: "기준단가98상"
Name List: #REF!
Name L형표지: ErrorHandler_1
Name L형표지: ErrorHandler_1
Name L형표지: ErrorHandler_1
Name NI: #REF!
Name NOIM: #REF!
Name PANEL: 100%

Sheet 참조_조직
B2: 시공사업단_조직팀
C3: 단장 | D3: 김병은
C4: CM.사업관리팀 | D4: 김용일 | E4: 권오준 | F4: 박윤수 | G4: 함종근 | H4: 염동섭 | I4: 김태우
C5: 개통운영팀 | D5: 김영환
C6: 공사관리팀 | D6: 노세현 | E6: 이재영

Sheet 매뉴얼 Gateway
A2: ■ GTX-A 시공사업단현장 Project 매뉴얼 Gateway
B4: □ 공종매뉴얼
C5: Lv1 | D5: 담당 | E5: Lv2 | F5: Start | G5: Finish | H5: 매뉴얼(클릭하면 해당 공종 Process Map/매뉴얼로 연결)
C6: 소송(분쟁) | D6: 박윤수
C8: 총사업비 변경 | D8: 함종근 | H8: 프로세스맵 | I8: 수행매뉴얼 | J8: 수행지침 | K8: 표준서 | L8: Risk 매뉴얼 | M8: GTXA사업단 R&R
C9: (운영사)인수인계 | D9: 노세현
C11: 철도 종합시험운행(3단계) | D11: 김영환 | H11: 프로세스맵 | I11: 수행매뉴얼 | J11: 수행지침 | K11: 표준서 | L11: Risk 매뉴얼 | M11: GTXA사업단 R&R
C13: 준공도서 | D13: 김태우
C15: 용지 | D15: 김태우
C17: 내부업무 | D17: 염동섭
B20: □ 수행매뉴얼
B21: 1. GTXA사업단 R&R
B22: 2. 수행_Process Map
B23: 3. 수행_Manual
B24: 첨부 : GTX-A 전략과제 To-Do-List
B26: □ History 관리
B27: - '25.4월 Rev0 - 매뉴얼 작성(최초)
B28: - '25.7월 Rev1 - 조직 운영방안 개편에 따른 R&R 및 Gateway 추가 수정

Sheet Risk 매뉴얼(개통운영팀)
K1: Rev0
A2: No. | B2: Risk profiling | C2: Process | D2: 시점(When) | F2: Activity | J2: 산출물(Output) | K2: 매뉴얼 반영 위치
D3: Start | E3: Finish | F3: 목적(Why) | G3: 방법(How) | H3: 주관부서(Who) | I3: 협업부서 | K3: 매뉴얼 구분 | L3: activity 구분 | M3: LINK연결
A4: 4-1 | B4: 3단계 구간 중 민자공급 범위 이외의 재정구간 인수인계 지연에 따른 종합시험운행 일정 지연 Risk | C4: ㆍ사업시행자를 통한 재정구간의 세부공정계획 및 지연시 만회대책 협의 | F4: 철도종합시험운행 표준절차(SOP)에 따른 일정추진 | G4: ㆍ3단계 구간 중 재정구간에 대한 인수인계 전 사전현장 점검 및 미비사항에 대한 조치요구 ㆍ선행공정 지연 만회대책 수립(추가 비용포함) | H4: 개통운영팀 | I4: 각 공구 사업시행자 감리단 국가철도공단 | J4: 인수인계 점검계획 및 지연시 만회 대책수립 | K4: ㆍ수행메뉴얼-철도종합시험운행
A5: 4-2 | B5: 3단계 종합시험운행 시설물검증시험 항목 중 외부전문기관이 시행할 외주비용 Risk | C5: ㆍ외부전문기관 외주비용에 대한 주무관청 승인 | F5: 시설물검증시험 항목 중 외부전문기관 업무수행 범위에 민자구간이 반영되도록 사전협의(공단) | G5: 재정구간의 시설물검증시험 항목 중 외부전문기관 수행업무에 민자구간의 시험항목을 포함하여 같이 수행하도록 사전협의 추진 | H5: 개통운영팀 | I5: 사업시행자 감리단 국가철도공단 | J5: 철도종합시험운행 연간계획 | K5: ㆍ수행메뉴얼-철도종합시험운행 ㆍ수행지침
A6: 4-3 | B6: 3단계 종합시험운행 기간 중 이례사항 발생 시 처리절차 미수립에 따른 위험 Risk | C6: ㆍ민자구간 및 재정구간이 분리되어 통합적인 관리를 위한 협의체 구성 | F6: 주문관청과 사전협의하여 통합인터페이스 관리를 위한 전분야가 참석하는 협의체 구성 | G6: ㆍ3단계 개시 시점부터 관계기관이 참석하는 협의체 회의를 시행(매주 단위) ㆍ사전에 도출된 협의 안건을 관계분야간 협의하여 추진 | H6: 개통운영팀 | I6: 각 공구 사업시행자 감리단 국가철도공단 | J6: 종합시험운행 기간 중 기술지원계획(장애조치 포함) | K6: ㆍ수행메뉴얼-철도종합시험운행 ㆍ수행지침

Sheet GTXA사업단 R&R
D1: ■ 전기간 표준 R&R | W1: ☆ 총괄책임, ● 검토, ◎ Main 담당, ◐ 업무협조, ○ 협의 | AM1: Rev1 | AR1: end
D2: 업무분장 내용 | J2: 빈도 | K2: 업무시간 (Hr) | N2: 업무 수준 | W2: 업무 분개 | AM2: 비고 | AN2: 시공사업단 | AO2: Main 담당 | AR2: end
I3: 현장담당 | N3: 업무량 | O3: 중요도 | T3: 난이도 | U3: 총점 | W3: 소장 | X3: CM.공정팀 | AC3: 개통운영팀 | AG3: 사업관리팀(공무팀) | AK3: 관리팀 | AN3: 해당여부 | AO3: 적용 | AP3: 담당 | AQ3: mail | AR3: end
A4: lev | K4: 1회 | L4: Hr/월 | O4: 원가 | P4: 공정 | Q4: 안전 | R4: 품질 | S4: 계 | X4: 팀장 | Y4: CM | Z4: 대외 | AA4: 공정1 | AB4: 공정2 | AC4: 개통 | AD4: 기계 | AE4: 건축 | AF4: 전기 | AG4: 팀장 | AH4: 대내1 | AI4: 대외1 | AJ4: 대외2 | AK4: 팀장 | AL4: 관리1 | AN4: (현재 25.4월기준) | AQ4: 담당자 수 | AR4: end
D5: 구분 | E5: lev1 | F5: lev1 | G5: lev1 | H5: lev1 | W5: 김병은 | X5: 김용일 | Y5: 박윤수 | Z5: 권오준 | AA5: 이재영 | AC5: 김영환 | AD5: 노세현 | AE5: 박재천 | AF5: 원찬희 | AG5: 김희성 | AH5: 염동섭 | AI5: 함종근 | AJ5: 김태우 | AK5: 김천재 | AL5: 윤채림 | AR5: end
A6: 1 | B6: 273-1 | E6: 가설사무실 | F6: 가설건물 축조 | G6: 가설사무실 축조 검토 | H6: 가설전기 인입 여건 검토 | I6: 관리 | J6: 1회/총 | K6: 2.6666667 | L6: - | N6: 1.4714286 | O6: 0.14285714 | P6: 0.42857143 | Q6: 0 | R6: 0 | S6: 0.57142857 | T6: 1.8571429 | U6: 2.1885714 | AN6: 해당없음 | AO6: =IF(AN6="해당없음","해당없음",_xlfn.TEXTJOIN(",",TRUE,AP6:AP6)) -> 해당없음 | AP6: =IF(AN6="해당없음","해당없음",INDEX($W$5:$AL$5, MATCH("◎", $W6:AL6,0))) -> 해당없음 | AQ6: =IF(COUNTIF(W6:AL6,"◎")=1,"1인",COUNTIF(W6:AL6,"◎")&"인") -> 0인 | AR6: end
A7: 2 | B7: 273-2 | D7: 착공 전 | H7: 상/하수도 인입 가능 검토 | I7: 관리 | J7: 1회/총 | K7: 6.0833333 | L7: - | N7: 2.8857143 | O7: 0.42857143 | P7: 0.71428571 | Q7: 0 | R7: 0.42857143 | S7: 1.5714286 | T7: 2.2857143 | U7: 3.2971429 | AN7: 해당없음 | AO7: =IF(AN7="해당없음","해당없음",_xlfn.TEXTJOIN(",",TRUE,AP7:AP7)) -> 해당없음 | AP7: =IF(AN7="해당없음","해당없음",INDEX($W$5:$AL$5, MATCH("◎", $W7:AL7,0))) -> 해당없음 | AQ7: =IF(COUNTIF(W7:AL7,"◎")=1,"1인",COUNTIF(W7:AL7,"◎")&"인") -> 0인 | AR7: end
A8: 3 | B8: 273-3 | D8: 단계 | H8: 관정 및 정화조 설치 검토 | I8: 관리 | J8: 1회/총 | K8: 7.5714286 | L8: - | N8: 2.55 | O8: 0.83333333 | P8: 0.66666667 | Q8: 0 | R8: 0.33333333 | S8: 1.8333333 | T8: 2.5 | U8: 3.3866667 | AN8: 해당없음 | AO8: =IF(AN8="해당없음","해당없음",_xlfn.TEXTJOIN(",",TRUE,AP8:AP8)) -> 해당없음 | AP8: =IF(AN8="해당없음","해당없음",INDEX($W$5:$AL$5, MATCH("◎", $W8:AL8,0))) -> 해당없음 | AQ8: =IF(COUNTIF(W8:AL8,"◎")=1,"1인",COUNTIF(W8:AL8,"◎")&"인") -> 0인 | AR8: end
A9: 4 | B9: 11 | G9: 가설사무실 축조부지 임차 | H9: 임차부지 조사 | I9: 관리 | J9: 1회/총 | K9: 12.5 | L9: - | N9: 4.4571429 | O9: 1.7142857 | P9: 1.8571429 | Q9: 0 | R9: 0 | S9: 3.5714286 | T9: 3.1428571 | U9: 5.0114286 | AN9: 해당없음 | AO9: =IF(AN9="해당없음","해당없음",_xlfn.TEXTJOIN(",",TRUE,AP9:AP9)) -> 해당없음 | AP9: =IF(AN9="해당없음","해당없음",INDEX($W$5:$AL$5, MATCH("◎", $W9:AL9,0))) -> 해당없음 | AQ9: =IF(COUNTIF(W9:AL9,"◎")=1,"1인",COUNTIF(W9:AL9,"◎")&"인") -> 0인 | AR9: end
A10: 5 | B10: 12 | H10: 임차부지 확정 | I10: 관리 | J10: 1회/총 | K10: 2.7 | L10: - | N10: 4 | O10: 3.25 | P10: 2 | Q10: 0.66666667 | R10: 0.79166667 | S10: 6.7083333 | T10: 4.2083333 | U10: 6.3083333 | AN10: 해당없음 | AO10: =IF(AN10="해당없음","해당없음",_xlfn.TEXTJOIN(",",TRUE,AP10:AP10)) -> 해당없음 | AP10: =IF(AN10="해당없음","해당없음",INDEX($W$5:$AL$5, MATCH("◎", $W10:AL10,0))) -> 해당없음 | AQ10: =IF(COUNTIF(W10:AL10,"◎")=1,"1인",COUNTIF(W10:AL10,"◎")&"인") -> 0인 | AR10: end
A11: 6 | B11: 13 | H11: 임대인과 임차계약서 작성 | I11: 관리 | J11: 1회/총 | K11: 4.25 | L11: - | N11: 2.5428571 | O11: 0.85714286 | P11: 0.42857143 | Q11: 0 | R11: 0 | S11: 1.2857143 | T11: 3.1428571 | U11: 3.7885714 | AN11: 해당없음 | AO11: =IF(AN11="해당없음","해당없음",_xlfn.TEXTJOIN(",",TRUE,AP11:AP11)) -> 해당없음 | AP11: =IF(AN11="해당없음","해당없음",INDEX($W$5:$AL$5, MATCH("◎", $W11:AL11,0))) -> 해당없음 | AQ11: =IF(COUNTIF(W11:AL11,"◎")=1,"1인",COUNTIF(W11:AL11,"◎")&"인") -> 0인 | AR11: end
A12: 7 | B12: 14 | H12: 임차료 지급 | I12: 관리 | J12: 1회/총 | K12: 1.8333333 | L12: - | N12: 1.4142857 | O12: 0.42857143 | P12: 0 | Q12: 0 | R12: 0 | S12: 0.42857143 | T12: 1.5714286 | U12: 1.9085714 | AN12: 해당없음 | AO12: =IF(AN12="해당없음","해당없음",_xlfn.TEXTJOIN(",",TRUE,AP12:AP12)) -> 해당없음 | AP12: =IF(AN12="해당없음","해당없음",INDEX($W$5:$AL$5, MATCH("◎", $W12:AL12,0))) -> 해당없음 | AQ12: =IF(COUNTIF(W12:AL12,"◎")=1,"1인",COUNTIF(W12:AL12,"◎")&"인") -> 0인 | AR12: end
A13: 8 | B13: 15 | G13: 가설사무실 축조 집행승인 (예산내) | H13: 예산대비내역서 작성 | I13: 공무 | J13: 1회/총 | K13: 1.4 | L13: - | N13: 1.8291667 | O13: 0.25 | P13: 1.0416667 | Q13: 0.125 | R13: 0.125 | S13: 1.5416667 | T13: 1.7083333 | U13: 2.4066667 | AN13: 해당없음 | AO13: =IF(AN13="해당없음","해당없음",_xlfn.TEXTJOIN(",",TRUE,AP13:AP13)) -> 해당없음 | AP13: =IF(AN13="해당없음","해당없음",INDEX($W$5:$AL$5, MATCH("◎", $W13:AL13,0))) -> 해당없음 | AQ13: =IF(COUNTIF(W13:AL13,"◎")=1,"1인",COUNTIF(W13:AL13,"◎")&"인") -> 0인 | AR13: end
A14: 9 | B14: 16 | H14: 가설사무실 축조 집행승인 | I14: 공무 | J14: 1회/총 | K14: 4.5 | L14: - | N14: 3.8041667 | O14: 1.0416667 | P14: 1.4166667 | Q14: 0.125 | R14: 0.125 | S14: 2.7083333 | T14: 3.1666667 | U14: 4.5966667 | AN14: 해당없음 | AO14: =IF(AN14="해당없음","해당없음",_xlfn.TEXTJOIN(",",TRUE,AP14:AP14)) -> 해당없음 | AP14: =IF(AN14="해당없음","해당없음",INDEX($W$5:$AL$5, MATCH("◎", $W14:AL14,0))) -> 해당없음 | AQ14: =IF(COUNTIF(W14:AL14,"◎")=1,"1인",COUNTIF(W14:AL14,"◎")&"인") -> 0인 | AR14: end
A15: 10 | B15: 17 | H15: 업체선정의뢰 | I15: 공무 | J15: 1회/총 | K15: 2.3 | L15: - | N15: 2.5791667 | O15: 0.25 | P15: 1.0416667 | Q15: 0.125 | R15: 0.125 | S15: 1.5416667 | T15: 2.0416667 | U15: 2.9733333 | AN15: 해당없음 | AO15: =IF(AN15="해당없음","해당없음",_xlfn.TEXTJOIN(",",TRUE,AP15:AP15)) -> 해당없음 | AP15: =IF(AN15="해당없음","해당없음",INDEX($W$5:$AL$5, MATCH("◎", $W15:AL15,0))) -> 해당없음 | AQ15: =IF(COUNTIF(W15:AL15,"◎")=1,"1인",COUNTIF(W15:AL15,"◎")&"인") -> 0인 | AR15: end
A16: 11 | B16: 18 | H16: 입찰 | I16: 공무 | J16: 1회/총 | K16: 2 | L16: - | N16: 2.7041667 | O16: 0.29166667 | P16: 1.0416667 | Q16: 0.125 | R16: 0.125 | S16: 1.5833333 | T16: 2.375 | U16: 3.2983333 | AN16: 해당없음 | AO16: =IF(AN16="해당없음","해당없음",_xlfn.TEXTJOIN(",",TRUE,AP16:AP16)) -> 해당없음 | AP16: =IF(AN16="해당없음","해당없음",INDEX($W$5:$AL$5, MATCH("◎", $W16:AL16,0))) -> 해당없음 | AQ16: =IF(COUNTIF(W16:AL16,"◎")=1,"1인",COUNTIF(W16:AL16,"◎")&"인") -> 0인 | AR16: end
A17: 12 | B17: 19 | H17: 하도승인의뢰 | I17: 공무 | J17: 1회/총 | K17: 2.3 | L17: - | N17: 2.5375 | O17: 0.125 | P17: 1.0416667 | Q17: 0.125 | R17: 0.125 | S17: 1.4166667 | T17: 2.0416667 | U17: 2.9316667 | AN17: 해당없음 | AO17: =IF(AN17="해당없음","해당없음",_xlfn.TEXTJOIN(",",TRUE,AP17:AP17)) -> 해당없음 | AP17: =IF(AN17="해당없음","해당없음",INDEX($W$5:$AL$5, MATCH("◎", $W17:AL17,0))) -> 해당없음 | AQ17: =IF(COUNTIF(W17:AL17,"◎")=1,"1인",COUNTIF(W17:AL17,"◎")&"인") -> 0인 | AR17: end
A18: 13 | B18: 20 | H18: 계약 | I18: 공무 | J18: 1회/총 | K18: 2 | N18: 2.6625 | O18: 0.16666667 | P18: 1.0416667 | Q18: 0.125 | R18: 0.125 | S18: 1.4583333 | T18: 2.0833333 | U18: 3.0233333 | AN18: 해당없음 | AO18: =IF(AN18="해당없음","해당없음",_xlfn.TEXTJOIN(",",TRUE,AP18:AP18)) -> 해당없음 | AP18: =IF(AN18="해당없음","해당없음",INDEX($W$5:$AL$5, MATCH("◎", $W18:AL18,0))) -> 해당없음 | AQ18: =IF(COUNTIF(W18:AL18,"◎")=1,"1인",COUNTIF(W18:AL18,"◎")&"인") -> 0인 | AR18: end
A19: 14 | B19: 21 | G19: 가설사무실 축조 집행승인 | H19: 예산대비내역서 작성 | I19: 공무 | J19: 1회/총 | K19: 1.7 | L19: - | N19: 1.9958333 | O19: 0.33333333 | P19: 1.0416667 | Q19: 0.125 | R19: 0.125 | S19: 1.625 | T19: 2 | U19: 2.7233333 | AN19: 해당없음 | AO19: =IF(AN19="해당없음","해당없음",_xlfn.TEXTJOIN(",",TRUE,AP19:AP19)) -> 해당없음 | AP19: =IF(AN19="해당없음","해당없음",INDEX($W$5:$AL$5, MATCH("◎", $W19:AL19,0))) -> 해당없음 | AQ19: =IF(COUNTIF(W19:AL19,"◎")=1,"1인",COUNTIF(W19:AL19,"◎")&"인") -> 0인 | AR19: end
A20: 15 | B20: 22 | H20: 가설사무실 축조 집행승인 | I20: 공무 | J20: 1회/총 | K20: 4.5 | L20: - | N20: 4.3958333 | O20: 2.25 | P20: 1.4166667 | Q20: 0.125 | R20: 0.125 | S20: 3.9166667 | T20: 3.2083333 | U20: 5.1083333 | AN20: 해당없음 | AO20: =IF(AN20="해당없음","해당없음",_xlfn.TEXTJOIN(",",TRUE,AP20:AP20)) -> 해당없음 | AP20: =IF(AN20="해당없음","해당없음",INDEX($W$5:$AL$5, MATCH("◎", $W20:AL20,0))) -> 해당없음 | AQ20: =IF(COUNTIF(W20:AL20,"◎")=1,"1인",COUNTIF(W20:AL20,"◎")&"인") -> 0인 | AR20: end
A21: 16 | B21: 23 | H21: 업체선정의뢰 | I21: 공무 | J21: 1회/총 | K21: 2.9 | L21: - | N21: 2.7041667 | O21: 0.33333333 | P21: 1.0416667 | Q21: 0.125 | R21: 0.125 | S21: 1.625 | T21: 2.2083333 | U21: 3.1733333 | AN21: 해당없음 | AO21: =IF(AN21="해당없음","해당없음",_xlfn.TEXTJOIN(",",TRUE,AP21:AP21)) -> 해당없음 | AP21: =IF(AN21="해당없음","해당없음",INDEX($W$5:$AL$5, MATCH("◎", $W21:AL21,0))) -> 해당없음 | AQ21: =IF(COUNTIF(W21:AL21,"◎")=1,"1인",COUNTIF(W21:AL21,"◎")&"인") -> 0인 | AR21: end
A22: 17 | B22: 24 | H22: 입찰 | I22: 공무 | J22: 1회/총 | K22: 2 | L22: - | N22: 2.7041667 | O22: 0.375 | P22: 1.0416667 | Q22: 0.125 | R22: 0.125 | S22: 1.6666667 | T22: 2.5 | U22: 3.415 | AN22: 해당없음 | AO22: =IF(AN22="해당없음","해당없음",_xlfn.TEXTJOIN(",",TRUE,AP22:AP22)) -> 해당없음 | AP22: =IF(AN22="해당없음","해당없음",INDEX($W$5:$AL$5, MATCH("◎", $W22:AL22,0))) -> 해당없음 | AQ22: =IF(COUNTIF(W22:AL22,"◎")=1,"1인",COUNTIF(W22:AL22,"◎")&"인") -> 0인 | AR22: end
A23: 18 | B23: 25 | H23: 하도승인의뢰 | I23: 공무 | J23: 1회/총 | K23: 2.9 | L23: - | N23: 2.6625 | O23: 0.16666667 | P23: 1.0416667 | Q23: 0.125 | R23: 0.125 | S23: 1.4583333 | T23: 2.1666667 | U23: 3.09 | AN23: 해당없음 | AO23: =IF(AN23="해당없음","해당없음",_xlfn.TEXTJOIN(",",TRUE,AP23:AP23)) -> 해당없음 | AP23: =IF(AN23="해당없음","해당없음",INDEX($W$5:$AL$5, MATCH("◎", $W23:AL23,0))) -> 해당없음 | AQ23: =IF(COUNTIF(W23:AL23,"◎")=1,"1인",COUNTIF(W23:AL23,"◎")&"인") -> 0인 | AR23: end
A24: 19 | B24: 26 | H24: 계약 | I24: 공무 | J24: 1회/총 | K24: 2 | L24: - | N24: 2.6625 | O24: 0.20833333 | P24: 1.0416667 | Q24: 0.125 | R24: 0.125 | S24: 1.5 | T24: 2.2083333 | U24: 3.1316667 | AN24: 해당없음 | AO24: =IF(AN24="해당없음","해당없음",_xlfn.TEXTJOIN(",",TRUE,AP24:AP24)) -> 해당없음 | AP24: =IF(AN24="해당없음","해당없음",INDEX($W$5:$AL$5, MATCH("◎", $W24:AL24,0))) -> 해당없음 | AQ24: =IF(COUNTIF(W24:AL24,"◎")=1,"1인",COUNTIF(W24:AL24,"◎")&"인") -> 0인 | AR24: end
A25: 20 | B25: 27 | G25: 축조계획 수립 | H25: 도면 작성 및 검토 | I25: 공사 | J25: 1회/총 | K25: 16.375 | L25: - | N25: 3.6125 | O25: 0.66666667 | P25: 1.0416667 | Q25: 0.16666667 | R25: 0.125 | S25: 2 | T25: 2.21875 | U25: 3.62 | AN25: 해당없음 | AO25: =IF(AN25="해당없음","해당없음",_xlfn.TEXTJOIN(",",TRUE,AP25:AP25)) -> 해당없음 | AP25: =IF(AN25="해당없음","해당없음",INDEX($W$5:$AL$5, MATCH("◎", $W25:AL25,0))) -> 해당없음 | AQ25: =IF(COUNTIF(W25:AL25,"◎")=1,"1인",COUNTIF(W25:AL25,"◎")&"인") -> 0인 | AR25: end
A26: 21 | B26: 28 | H26: 경계 측량 | I26: 공사 | J26: 1회/총 | K26: 5.0625 | L26: - | N26: 2.83125 | O26: 1.7916667 | P26: 1.5416667 | Q26: 0.16666667 | R26: 0.20833333 | S26: 3.7083333 | T26: 2.625 | U26: 3.9741667 | AN26: 해당없음 | AO26: =IF(AN26="해당없음","해당없음",_xlfn.TEXTJOIN(",",TRUE,AP26:AP26)) -> 해당없음 | AP26: =IF(AN26="해당없음","해당없음",INDEX($W$5:$AL$5, MATCH("◎", $W26:AL26,0))) -> 해당없음 | AQ26: =IF(COUNTIF(W26:AL26,"◎")=1,"1인",COUNTIF(W26:AL26,"◎")&"인") -> 0인 | AR26: end
A27: 22 | B27: 29 | H27: 공정계획 수립 | I27: 공사 | J27: 1회/총 | K27: 8.3125 | L27: - | N27: 3.20625 | O27: 0.95833333 | P27: 1.5833333 | Q27: 0.16666667 | R27: 0.16666667 | S27: 2.875 | T27: 2.78125 | U27: 4.0825 | AN27: 해당없음 | AO27: =IF(AN27="해당없음","해당없음",_xlfn.TEXTJOIN(",",TRUE,AP27:AP27)) -> 해당없음 | AP27: =IF(AN27="해당없음","해당없음",INDEX($W$5:$AL$5, MATCH("◎", $W27:AL27,0))) -> 해당없음 | AQ27: =IF(COUNTIF(W27:AL27,"◎")=1,"1인",COUNTIF(W27:AL27,"◎")&"인") -> 0인 | AR27: end
A28: 23 | B28: 30 | H28: 시공계획서 작성 | I28: 공사 | J28: 1회/총 | K28: 9.75 | L28: - | N28: 3.06875 | O28: 0.041666667 | P28: 0.54166667 | Q28: 0.79166667 | R28: 0.83333333 | S28: 2.2083333 | T28: 2.53125 | U28: 3.6941667 | AN28: 해당없음 | AO28: =IF(AN28="해당없음","해당없음",_xlfn.TEXTJOIN(",",TRUE,AP28:AP28)) -> 해당없음 | AP28: =IF(AN28="해당없음","해당없음",INDEX($W$5:$AL$5, MATCH("◎", $W28:AL28,0))) -> 해당없음 | AQ28: =IF(COUNTIF(W28:AL28,"◎")=1,"1인",COUNTIF(W28:AL28,"◎")&"인") -> 0인 | AR28: end
A29: 24 | B29: 31 | H29: 자재 신청 | I29: 공사 | J29: 1회/총 | K29: 4.125 | L29: - | N29: 2.6625 | O29: 0.33333333 | P29: 1.9166667 | Q29: 0.16666667 | R29: 0.41666667 | S29: 2.8333333 | T29: 2.25 | U29: 3.4316667 | AN29: 해당없음 | AO29: =IF(AN29="해당없음","해당없음",_xlfn.TEXTJOIN(",",TRUE,AP29:AP29)) -> 해당없음 | AP29: =IF(AN29="해당없음","해당없음",INDEX($W$5:$AL$5, MATCH("◎", $W29:AL29,0))) -> 해당없음 | AQ29: =IF(COUNTIF(W29:AL29,"◎")=1,"1인",COUNTIF(W29:AL29,"◎")&"인") -> 0인 | AR29: end
A30: 25 | B30: 73 | F30: 사무실 개설 (셋팅) | G30: 업무분장 관리 | I30: 공무 | J30: 1회/총 | K30: 2.7 | L30: - | N30: 4.3333333 | O30: 3 | P30: 3 | Q30: 3 | R30: 3 | S30: 12 | T30: 4.6666667 | U30: 7.8666667 | AN30: 해당없음 | AO30: =IF(AN30="해당없음","해당없음",_xlfn.TEXTJOIN(",",TRUE,AP30:AP30)) -> 해당없음 | AP30: =IF(AN30="해당없음","해당없음",INDEX($W$5:$AL$5, MATCH("◎", $W30:AL30,0))) -> 해당없음 | AQ30: =IF(COUNTIF(W30:AL30,"◎")=1,"1인",COUNTIF(W30:AL30,"◎")&"인") -> 0인 | AR30: end
A31: 26 | B31: 75 | G31: 사무실 운영관련 용역업체 선정(무인경비, 청소, 음식물처리 등) | I31: 관리 | J31: 1회/총 | K31: 5.3333333 | L31: - | N31: 3.4 | O31: 0.85714286 | P31: 0 | Q31: 0 | R31: 0 | S31: 0.85714286 | T31: 2 | U31: 3.1314286 | AN31: 해당없음 | AO31: =IF(AN31="해당없음","해당없음",_xlfn.TEXTJOIN(",",TRUE,AP31:AP31)) -> 해당없음 | AP31: =IF(AN31="해당없음","해당없음",INDEX($W$5:$AL$5, MATCH("◎", $W31:AL31,0))) -> 해당없음 | AQ31: =IF(COUNTIF(W31:AL31,"◎")=1,"1인",COUNTIF(W31:AL31,"◎")&"인") -> 0인 | AR31: end
A32: 27 | B32: 76 | G32: 지정주유소 검토 및 선정 | I32: 관리 | J32: 1회/총 | K32: 5.5 | L32: - | N32: 3.2571429 | O32: 1.5714286 | P32: 0.14285714 | Q32: 0 | R32: 0 | S32: 1.7142857 | T32: 2 | U32: 3.2457143 | AN32: 해당없음 | AO32: =IF(AN32="해당없음","해당없음",_xlfn.TEXTJOIN(",",TRUE,AP32:AP32)) -> 해당없음 | AP32: =IF(AN32="해당없음","해당없음",INDEX($W$5:$AL$5, MATCH("◎", $W32:AL32,0))) -> 해당없음 | AQ32: =IF(COUNTIF(W32:AL32,"◎")=1,"1인",COUNTIF(W32:AL32,"◎")&"인") -> 0인 | AR32: end
A33: 28 | B33: 78 | G33: 현장내 제반 운영 규칙 정립 | I33: 공무 | J33: 1회/총 | K33: 3.5 | L33: - | N33: 4 | O33: 0 | P33: 0 | Q33: 0 | R33: 0 | S33: 0 | T33: 5 | U33: 5.6 | AN33: 해당없음 | AO33: =IF(AN33="해당없음","해당없음",_xlfn.TEXTJOIN(",",TRUE,AP33:AP33)) -> 해당없음 | AP33: =IF(AN33="해당없음","해당없음",INDEX($W$5:$AL$5, MATCH("◎", $W33:AL33,0))) -> 해당없음 | AQ33: =IF(COUNTIF(W33:AL33,"◎")=1,"1인",COUNTIF(W33:AL33,"◎")&"인") -> 0인 | AR33: end
A34: 29 | B34: 79 | F34: 사무실 임차 (가설사무실 축조 불가시) | G34: 사무실 필요면적 검토 | I34: 공무 | J34: 1회/총 | K34: 12 | L34: - | N34: 3.5291667 | O34: 0.70833333 | P34: 0.25 | Q34: 0 | R34: 0.16666667 | S34: 1.125 | T34: 3.375 | U34: 4.3366667 | AN34: 해당없음 | AO34: =IF(AN34="해당없음","해당없음",_xlfn.TEXTJOIN(",",TRUE,AP34:AP34)) -> 해당없음 | AP34: =IF(AN34="해당없음","해당없음",INDEX($W$5:$AL$5, MATCH("◎", $W34:AL34,0))) -> 해당없음 | AQ34: =IF(COUNTIF(W34:AL34,"◎")=1,"1인",COUNTIF(W34:AL34,"◎")&"인") -> 0인 | AR34: end
A35: 30 | B35: 80 | G35: 임차사무실 조사 | I35: 관리 | J35: 1회/총 | K35: 7.1666667 | L35: - | N35: 3.9714286 | O35: 2.1428571 | P35: 1.4285714 | Q35: 0 | R35: 0 | S35: 3.5714286 | T35: 3.1428571 | U35: 4.8171429 | AN35: 해당없음 | AO35: =IF(AN35="해당없음","해당없음",_xlfn.TEXTJOIN(",",TRUE,AP35:AP35)) -> 해당없음 | AP35: =IF(AN35="해당없음","해당없음",INDEX($W$5:$AL$5, MATCH("◎", $W35:AL35,0))) -> 해당없음 | AQ35: =IF(COUNTIF(W35:AL35,"◎")=1,"1인",COUNTIF(W35:AL35,"◎")&"인") -> 0인 | AR35: end
A36: 31 | B36: 81 | G36: 채권 확보 방안 수립 | I36: 관리 | J36: 1회/총 | K36: 3.8333333 | L36: - | N36: 2.95 | O36: 1.75 | P36: 0 | Q36: 0 | R36: 0 | S36: 1.75 | T36: 3.25 | U36: 4.13 | AN36: 해당없음 | AO36: =IF(AN36="해당없음","해당없음",_xlfn.TEXTJOIN(",",TRUE,AP36:AP36)) -> 해당없음 | AP36: =IF(AN36="해당없음","해당없음",INDEX($W$5:$AL$5, MATCH("◎", $W36:AL36,0))) -> 해당없음 | AQ36: =IF(COUNTIF(W36:AL36,"◎")=1,"1인",COUNTIF(W36:AL36,"◎")&"인") -> 0인 | AR36: end
A37: 32 | B37: 82 | G37: 임차 계약 | I37: 관리 | J37: 1회/총 | K37: 3.3333333 | L37: - | N37: 3.2 | O37: 2.25 | P37: 0.5 | Q37: 0 | R37: 0 | S37: 2.75 | T37: 3.25 | U37: 4.43 | AN37: 해당없음 | AO37: =IF(AN37="해당없음","해당없음",_xlfn.TEXTJOIN(",",TRUE,AP37:AP37)) -> 해당없음 | AP37: =IF(AN37="해당없음","해당없음",INDEX($W$5:$AL$5, MATCH("◎", $W37:AL37,0))) -> 해당없음 | AQ37: =IF(COUNTIF(W37:AL37,"◎")=1,"1인",COUNTIF(W37:AL37,"◎")&"인") -> 0인 | AR37: end
A38: 33 | B38: 83 | G38: 사무실 임차 집행승인 | H38: 예산내 집행 | I38: 공무 | J38: 1회/총 | K38: 7.8333333 | L38: - | N38: 2.9625 | O38: 1.4166667 | P38: 1.25 | Q38: 0 | R38: 0.16666667 | S38: 2.8333333 | T38: 2.4166667 | U38: 3.685 | AN38: 해당없음 | AO38: =IF(AN38="해당없음","해당없음",_xlfn.TEXTJOIN(",",TRUE,AP38:AP38)) -> 해당없음 | AP38: =IF(AN38="해당없음","해당없음",INDEX($W$5:$AL$5, MATCH("◎", $W38:AL38,0))) -> 해당없음 | AQ38: =IF(COUNTIF(W38:AL38,"◎")=1,"1인",COUNTIF(W38:AL38,"◎")&"인") -> 0인 | AR38: end
A39: 34 | B39: 84 | H39: 예산초과 집행 | I39: 공무 | J39: 1회/총 | K39: 9.8333333 | L39: - | N39: 3.4208333 | O39: 2.125 | P39: 1.25 | Q39: 0 | R39: 0.16666667 | S39: 3.5416667 | T39: 2.6666667 | U39: 4.21 | AN39: 해당없음 | AO39: =IF(AN39="해당없음","해당없음",_xlfn.TEXTJOIN(",",TRUE,AP39:AP39)) -> 해당없음 | AP39: =IF(AN39="해당없음","해당없음",INDEX($W$5:$AL$5, MATCH("◎", $W39:AL39,0))) -> 해당없음 | AQ39: =IF(COUNTIF(W39:AL39,"◎")=1,"1인",COUNTIF(W39:AL39,"◎")&"인") -> 0인 | AR39: end
A40: 35 | B40: 86-1 | E40: 현장준비팀 운영 (T/K) | F40: 선급공사비 예산편성 | G40: 설계사(계속공사) 계약금액 협의 | I40: 공무 | L40: - | AN40: 해당없음 | AO40: =IF(AN40="해당없음","해당없음",_xlfn.TEXTJOIN(",",TRUE,AP40:AP40)) -> 해당없음 | AP40: =IF(AN40="해당없음","해당없음",INDEX($W$5:$AL$5, MATCH("◎", $W40:AL40,0))) -> 해당없음 | AQ40: =IF(COUNTIF(W40:AL40,"◎")=1,"1인",COUNTIF(W40:AL40,"◎")&"인") -> 0인 | AR40: end
...

Sheet 수행_Manual
F1: ■ 수행매뉴얼 Manual
F2: 9 | H2: 16 | I2: 6 | J2: 6 | K2: 2 | L2: 2 | M2: 20 | N2: 20 | O2: 20 | P2: 20
B3: 현장명 | C3: 담당자 | D3: 업무 | E3: 현장 | F3: 매뉴얼 | I3: 시점 (When) | K3: 내용 | O3: In-Put(CODE) | P3: Out-Put(CODE) | Q3: 수행지침 | R3: 표준서
A4: NO. | D4: 구분 | E4: 작성 | F4: No | G4: Code | H4: 업무 내용 | I4: Start | J4: Finish | O4: 1 | P4: 1 | T4: GTX-A 시공사업단
E5: 부서 | I5: 시기 | J5: 시기 | K5: 목적 | L5: 방법 (How) | M5: 주관부서 (Who) | N5: 협업부서 | O5: 산출물(What/시스템) | P5: 산출물(What/시스템)
H6: 수행매뉴얼 | K6: 목적 | L6: 방법
G8: 착공 전 | H8: 가설사무실
G9: 착공 전 | H9: 가설사무실 축조 검토
A10: 1 | B10: 진해신항남방파호안1-2공구 현장 | C10: 김창진 | D10: 관리 | E10: 관리팀 | G10: 착공 전 | H10: 가설전기 인입 여건 검토 | K10: • 가설사무실에서 사용할 전기인입을 위한 여건 검토 | L10: • 한국전력공사에 전기사용신청서 제출 - 향후 전기설비 단선결선도 등 필요하므로 전기공사업체 대리신청 • 전기안전공사에 사용전 점검 신청 • 전기안전공사의 사용전 점검 시행 및 전기 인입 | M10: 관리 | N10: 공사팀, 공무•설계팀 | O10: 현장 부담 금액 (변압기 이후 인입공사는 현장 부담임) | P10: 전기인입공사 신청 | T10: =VLOOKUP(A10,'GTXA사업단 R&R'!$A$6:$AO$1274,41,) -> 해당없음
A11: 2 | B11: 진해신항남방파호안1-2공구 현장 | C11: 김창진 | D11: 관리 | E11: 관리팀 | G11: 착공 전 | H11: 상/하수도 인입 가능 검토 | K11: • 가설사무실에서 사용할 상하수도 인입을 위한 검토 | L11: • 상하수도 설치가능 업체 조사 및 비교견적 접수 • 상하수도 인입을 위한 현장품의 및 설치 시행 - 상수하수도 인입 계획 및 의사결정 시 필요자료(도면, 견적서 등)를 첨부하여 품의 • 상하수도 인입 설치 공사 시행 - 인입 공사 중 계약조건에 따른 업무 수행 모니터링 | M11: 관리 | N11: 공사팀, 공무•설계팀 | O11: 현장 부담 금액 산출 자료 (계량기 이후 급수공사는 현장 부담) 인근 상수도 정보 (위치, 직경, 수압, 관망도, 접속지점 등) 사무실 예상 급수 용량 | P11: 상수도 인입공사 신청서 | T11: =VLOOKUP(A11,'GTXA사업단 R&R'!$A$6:$AO$1274,41,) -> 해당없음
A12: 3 | B12: 진해신항남방파호안1-2공구 현장 | C12: 김창진 | D12: 관리 | E12: 관리팀 | G12: 착공 전 | H12: 관정 및 정화조 설치 검토 | K12: • 상수도 인입 불가 시 지하수를 사용할 수 있는 여건 검토 | L12: • 관정 및 정화조 설치 업체 모색 및 비교견적 접수 • 관정 및 정화조 설치를 위한 현장품의 및 설치 시행 - 지하수관리-수질검사(지자체 상하수도 사업소,보건소)/지하수 오염방지 조치 - 오수분뇨관리-오수처리 시설 설치/오수처리시설의 운영관리(위탁 등) 내용 | M12: 관리 | N12: 공사팀, 공무•설계팀 | O12: 상수도 미인입시 허가관정 검토, 오수처리시설(단독정화조) - 환경영향평가 적용후 규모산정 | P12: 오수처리시설 설치신고 오수처리시설 준공검사 | T12: =VLOOKUP(A12,'GTXA사업단 R&R'!$A$6:$AO$1274,41,) -> 해당없음
G13: 착공 전 | H13: 가설사무실 축조부지 임차
A14: 4 | B14: 진해신항남방파호안1-2공구 현장 | C14: 김창진 | D14: 관리 | E14: 관리팀 | G14: 착공 전 | H14: 임차부지 조사 | K14: • 가설사무실을 축조할 수 있는 부지 조사 | L14: • 가설사무실 축조를 위한 부지의 검토 - 가설전기 인입 여건 확인 (한전인입금 과다발생 지양) - 상/하수도 인입가능 검토 및 관정/정화조 설치여부 검토 - 도시가스 인입 여건 확인 - 토지에 대한 근저당권, 현장과의 접근성, 면적 등 | M14: 관리 | N14: 공사팀, 공무•설계팀 | O14: 접근성, 인허가 가능여부, 토지개발비 및 원상복구 조건, 임대비 등의 종합적 검토 필요 | P14: 임차 가능 예상부지 산출 | T14: =VLOOKUP(A14,'GTXA사업단 R&R'!$A$6:$AO$1274,41,) -> 해당없음
A15: 5 | B15: 진해신항남방파호안1-2공구 현장 | C15: 김창진 | D15: 관리 | E15: 관리팀 | G15: 착공 전 | H15: 임차부지 확정 | K15: • 가설사무실 축조를 위한 부지의 확정 | L15: • 가설사무실 축조부지 조사결과에 따른 적정부지 선정 | M15: 관리 | N15: 공사팀, 공무•설계팀 | O15: 임차 부지선정 품의 | P15: 임차 부지 결정 | T15: =VLOOKUP(A15,'GTXA사업단 R&R'!$A$6:$AO$1274,41,) -> 해당없음
A16: 6 | B16: 진해신항남방파호안1-2공구 현장 | C16: 김창진 | D16: 관리 | E16: 관리팀 | G16: 착공 전 | H16: 임대인과 임차계약서 작성 | K16: • 가설사무실 축조를 위한 부지의 임차계약 진행 | L16: • 가설사무실 축조부지 임차계약 품의 실시 (현장전결) - 면적, 현장접근성, 보증금, 임대료 등 고려 • 등기부등본 상에 금융기관의 근저당권과 지상권이 설정되어 있는 토지를 임차한 경우 해당 금융기관의 토지사용 동의서 필요 | M16: 관리 | N16: 법무지원팀 | O16: 전체 현황 법무 DLS 검토요청 (임차료 지급 시기 및 기간포함) | P16: 현장사무실 부지 임차계약 | T16: =VLOOKUP(A16,'GTXA사업단 R&R'!$A$6:$AO$1274,41,) -> 해당없음
A17: 7 | B17: 진해신항남방파호안1-2공구 현장 | C17: 김창진 | D17: 관리 | E17: 관리팀 | G17: 착공 전 | H17: 임차료 지급 | K17: • 가설사무실 부지 임차계약 이후 임차료 지급 | L17: • 가설건축물 축조신고 - 가설건축물 축조신고 및 축조신고필증 得 - 가설건축물 축조신고 조건 사항 이행 (배수설비 설치조건 등) | M17: 관리 | N17: 자금팀 | O17: 자금신청 | P17: 자금집행 | T17: =VLOOKUP(A17,'GTXA사업단 R&R'!$A$6:$AO$1274,41,) -> 해당없음
G18: 착공 전 | H18: 가설사무실 축조 집행승인
A19: 8 | B19: 진해신항남방파호안1-2공구 현장 | C19: 김창진 | D19: 공무 | E19: 공무설계팀 | G19: 착공 전 | H19: 예산대비내역서 작성 | K19: • 가설사무실 축조 발주 시 사용 가능한 실행 예산 확인 | L19: • 본실행 편성이전 가설사무실 축조시 단가승인 필요 - 비교견적, 산출근거, 타현장비교를 통한 단가 적정성 검토 - 가설사무실 축조면적 검토 (타현장대비, 기준인원 산출) - 숙소 등 발주자(감리 포함) 이용시설 검토 : 도급 반영 여부 | M19: 공무 | N19: 토목견적팀 | O19: 가설사무실 축조 단가승인 자료 | P19: 가설사무실 축조 단가승인 품의서 | T19: =VLOOKUP(A19,'GTXA사업단 R&R'!$A$6:$AO$1274,41,) -> 해당없음
A20: 9 | B20: 진해신항남방파호안1-2공구 현장 | C20: 김창진 | D20: 공무 | E20: 공무설계팀 | G20: 착공 전 | H20: 가설사무실 축조 집행승인 | K20: • 가설사무실 축조를 위한 집행승인 | L20: • 실행 이내 가설사무실 축조를 위한 집행승인 - 예산금액 및 기준면적 이내 집행 확인 | M20: 공무 | N20: 토목수행팀 | O20: 가설사무실 축조 집행승인 자료 | P20: 가설사무실 축조 집행승인 품의서 | T20: =VLOOKUP(A20,'GTXA사업단 R&R'!$A$6:$AO$1274,41,) -> 해당없음
A21: 10 | B21: 진해신항남방파호안1-2공구 현장 | C21: 김창진 | D21: 공무 | E21: 공무설계팀 | G21: 착공 전 | H21: 업체선정의뢰 | K21: • 가설사무실 축조 업체선정을 위한 입찰 Pool 구성 | L21: • 업체선정의뢰검토서 등 작성 - 단가승인 및 집행승인 바탕으로 예산대비내역서 등 첨부하여 작성 • 현장설명서 작성 - 현장설명서 표준양식 사용하여 현장설명서 작성 및 특수조건 확인 | M21: 공무 | N21: 토목수행팀, 외주관리팀 | O21: 예산대비내역서 계약내역서 현장설명서(특수조건) 업체선정의뢰검토서 | P21: 업체선정의뢰 품의서 | T21: =VLOOKUP(A21,'GTXA사업단 R&R'!$A$6:$AO$1274,41,) -> 해당없음
A22: 11 | B22: 진해신항남방파호안1-2공구 현장 | C22: 김창진 | D22: 공무 | E22: 공무설계팀 | G22: 착공 전 | H22: 입찰 | K22: • 입찰 Pool 중 최저가 업체 선정을 위한 입찰 | L22: • 현장설명회 및 입찰 실시 - 현장설명회 진행 시 참석대상자 참석가능여부 사전확인 - 인감증명서, 사용인감계, 위임장, 재직증명서 준비 요청 - 현장설명회 이후 현장설명서 간인을 통한 현장설명 증빙자료 확보 - 필요시 현장설명회 녹화실시 | M22: 공무 | N22: 외주관리팀 | O22: 현장설명회 자료 현장설명서 간인본 | P22: 현장설명회 참여업체 투찰금액 | T22: =VLOOKUP(A22,'GTXA사업단 R&R'!$A$6:$AO$1274,41,) -> 해당없음
A23: 12 | B23: 진해신항남방파호안1-2공구 현장 | C23: 김창진 | D23: 공무 | E23: 공무설계팀 | G23: 착공 전 | H23: 하도승인의뢰 | K23: • 낙찰된 업체의 하도급계약을 위한 승인의뢰 | L23: • 기술자료 해당유무 확인, 안전보건능력평가, 견적금액대비표 작성 - 기술자료 해당유무 확인 대외공문 발송 및 회신 수령 - 안전보건능력평가 자료 작성 요청 및 안전팀 PM에 사내공문 발송 • 이외 업체선정의뢰 시 사용했던 자료 준비하여 하도승인의뢰 상신 | M23: 공무 | N23: 토목수행팀, 토목안전팀, 외주관리팀 | O23: 기술자료 해당유무 확인 안전보건능력평가 견적금액대비표 | P23: 하도승인의뢰 품의서 | T23: =VLOOKUP(A23,'GTXA사업단 R&R'!$A$6:$AO$1274,41,) -> 해당없음
A24: 13 | B24: 진해신항남방파호안1-2공구 현장 | C24: 김창진 | D24: 공무 | E24: 공무설계팀 | G24: 착공 전 | H24: 계약 | K24: • 하도급 업체 계약 | L24: • 계약 이후 필요한 프로세스 확인 - 고용보험 하수급인 사업주 승인 신청 - 채권신탁계약서 날인본 등기송부 채근 - 도급 반영항목일 경우 관통보 및 KISCON 등재 | M24: 공무 | N24: 외주관리팀 | O24: - | P24: 하도급 계약서 | T24: =VLOOKUP(A24,'GTXA사업단 R&R'!$A$6:$AO$1274,41,) -> 해당없음
G25: 착공 전 | H25: 축조계획 수립
A26: 20 | B26: 진해신항남방파호안1-2공구 현장 | C26: 김창진 | D26: 공사 | E26: 공사팀 | G26: 착공 전 | H26: 도면 작성 및 검토 | K26: • 가설사무실 축조를 위한 도면 작성 및 검토 | L26: • 가설사무실 축조업체와의 도면 작성 및 배치 검토 - 탕비실, 회의실 등에 필요한 가벽 배치 - 책상 배치에 따른 전등/전열기구 배치 | M26: 공사 | O26: - | P26: 설계도면 | T26: =VLOOKUP(A26,'GTXA사업단 R&R'!$A$6:$AO$1274,41,) -> 해당없음
A27: 21 | B27: 진해신항남방파호안1-2공구 현장 | C27: 김창진 | D27: 공사 | E27: 공사팀 | G27: 착공 전 | H27: 경계 측량 | K27: • 가설사무실 부지경계 확정을 위한 측량 필요 | L27: • 한국국토정보공사를 통한 지적측량 실시 - 향후 분쟁발생시 당위성 확보 • 지적측량 실시 전 현장품의 실시 (공통공사비 중 가설사무실 축조 항목에 예산 편성 필요) | M27: 공사 | O27: 측량계획서 | P27: 측량성과표 | T27: =VLOOKUP(A27,'GTXA사업단 R&R'!$A$6:$AO$1274,41,) -> 해당없음
A28: 22 | B28: 진해신항남방파호안1-2공구 현장 | C28: 김창진 | D28: 공사 | E28: 공사팀 | G28: 착공 전 | H28: 공정계획 수립 | K28: • 가설사무실 착공 및 입주까지의 공정계획 수립 | L28: • 현장사무실 입주시기를 고려한 세부공정 계획 수립 • 가설사무실 축조지연 방지위한 세부공정 검토(소단위 작업, 자재반입)하여 공정계획 수립 | M28: 공사 | O28: 가설사무실 축조 계획 | P28: 가설사무실 축조 공정표 | T28: =VLOOKUP(A28,'GTXA사업단 R&R'!$A$6:$AO$1274,41,) -> 해당없음
A29: 23 | B29: 진해신항남방파호안1-2공구 현장 | C29: 김창진 | D29: 공사 | E29: 공사팀 | G29: 착공 전 | H29: 시공계획서 작성 | K29: • 가설사무실 축조를 위한 공사계획서 작성 | L29: • 가설사무실 축조 공사계획서 작성 및 안전공사발표회 실시 | M29: 공사 | O29: 설계도면, 측량성과표, 가설사무실 축조 공정표 | P29: 시공계획서 | T29: =VLOOKUP(A29,'GTXA사업단 R&R'!$A$6:$AO$1274,41,) -> 해당없음
A30: 24 | B30: 진해신항남방파호안1-2공구 현장 | C30: 김창진 | D30: 공사 | E30: 공사팀 | G30: 착공 전 | H30: 자재 신청 | K30: • 가설사무실 축조를 위해 시기별 필요한 자재 신청 | L30: • 지급자재에 대한 자재청구서 작성 및 내부결재 실시 - 품목, 설계량, 반입수량, 일자 등 확인 | M30: 공사 | N30: 관리팀 | O30: 가설사무실 축조 공정표 | P30: 자재신청서 | T30: =VLOOKUP(A30,'GTXA사업단 R&R'!$A$6:$AO$1274,41,) -> 해당없음
G31: 착공 전 | H31: 사무실 개설 (셋팅)
A32: 25 | B32: 진해신항남방파호안1-2공구 현장 | C32: 김창진 | D32: 공무 | E32: 공무설계팀 | G32: 착공 전 | H32: 업무분장 관리 | K32: • 업무간 공백을 최소화 하기 위한 팀/개인별 업무분장 | L32: • 업무 항목 상세화 및 팀별 업무분배 실시 - 팀별 업무분배로 업무분장이 불명확한 경우 개인별 업무분장 실시 • 향후 누락된 업무 항목에 대해서는 부서간 회의를 통한 업무분배 재실시 | M32: 공무 | N32: 품질팀, 안전팀, 관리팀, 공사팀 | O32: 표준업무분장표 | P32: 업무분장표 | T32: =VLOOKUP(A32,'GTXA사업단 R&R'!$A$6:$AO$1274,41,) -> 해당없음
A33: 26 | B33: 진해신항남방파호안1-2공구 현장 | C33: 김창진 | D33: 관리 | E33: 관리팀 | G33: 착공 전 | H33: 사무실 운영관련 용역업체 선정 (무인경비, 청소, 음식물처리 등) | K33: • 현장사무실 운영의 제반사항을 위한 업체 선정 | L33: • 현장 무인경비, 청소인원, 음식물처리업체 선정 품의 실시 - 비교견적 및 인원채용공고 등 필요업무 수행 | M33: 관리 | N33: 공무팀 | O33: 비교견적 실시 | P33: 업체선정 및 계약 체결 (품의 포함) | T33: =VLOOKUP(A33,'GTXA사업단 R&R'!$A$6:$AO$1274,41,) -> 해당없음
A34: 27 | B34: 진해신항남방파호안1-2공구 현장 | C34: 김창진 | D34: 관리 | E34: 관리팀 | G34: 착공 전 | H34: 지정주유소 검토 및 선정 | K34: • 현장 및 직원 차량 주유를 위한 지정주유소 선정 | L34: • 인근 주유소 금액 및 접근성 비교 및 선정 품의 - 비교견적 접수 및 민원사항 고려 | M34: 관리 | N34: 공사팀, 공무•설계팀 | O34: 임지, 단가, 공급수량 적기 가능여부 검토 | P34: 업체선정 | T34: =VLOOKUP(A34,'GTXA사업단 R&R'!$A$6:$AO$1274,41,) -> 해당없음
A35: 28 | B35: 진해신항남방파호안1-2공구 현장 | C35: 김창진 | D35: 공무 | E35: 공무설계팀 | G35: 착공 전 | H35: 현장내 제반 운영 규칙 정립 | K35: • 현장 운영을 위한 근무시간, 경상비 지급등 운영 규칙 정립 | L35: • 현장 기본항목에 대한 기준 수립 - 근무시간(근로계약 조건, 법적 준수사항 고려, 휴게시간 등) - 유류비, 귀향여비, 출장비, 회사차량관리, 지급품, 통신비, 현장숙소, 직원식당, 경조사, 연차 | M35: 관리 | O35: - | P35: 현장 운영 규칙 | T35: =VLOOKUP(A35,'GTXA사업단 R&R'!$A$6:$AO$1274,41,) -> 해당없음
G36: 착공 전 | H36: 사무실 임차 (축조 불가시)
A37: 29 | B37: 진해신항남방파호안1-2공구 현장 | C37: 김창진 | D37: 공무 | E37: 공무설계팀 | G37: 착공 전 | H37: 사무실 필요면적 검토 | K37: • 현장 기준인원에 따른 사무실 필요면적 검토 | L37: • 법정인원 배치기준 및 현장 운영계획에 따른 적정인원 반영하여 사무실 필요면적 검토 - 현장대리인, 안전관리자, 품질관리자 법정인원 확인 - 인력운영계획에 따른 현장 배치예정 인원 확인 | M37: 관리 | O37: 현장 인력운영 계획 | T37: =VLOOKUP(A37,'GTXA사업단 R&R'!$A$6:$AO$1274,41,) -> 해당없음
A38: 30 | B38: 진해신항남방파호안1-2공구 현장 | C38: 김창진 | D38: 관리 | E38: 관리팀 | G38: 착공 전 | H38: 임차사무실 조사 | K38: • 임차사무실 선정을 위한 조사 | L38: • 근저당권, 주차여유대수, 기존인테리어 유무, 소음 유무, 현장과의 접근성, 인허가 가능여부, 토지개발비 및 원상복구 조건, 임대비 등 종합적 검토 | M38: 관리 | N38: 공사팀, 공무•설계팀 | O38: 임차사무실 후보지 | P38: 임차사무실 결정 | T38: =VLOOKUP(A38,'GTXA사업단 R&R'!$A$6:$AO$1274,41,) -> 해당없음
A39: 31 | B39: 진해신항남방파호안1-2공구 현장 | C39: 김창진 | D39: 관리 | E39: 관리팀 | G39: 착공 전 | H39: 채권 확보 방안 수립 | K39: • 채권확보 방안 수립을 통한 임차보증금 확보 방안 • 임차보증금 회수방안 검토 • 공동도급안분금 회수방안 검토 | L39: • 임차보증금 회수 리스크 헷지를 위한 방안 모색 - 임대인의 지급보증서 발급 - 보증보험 가입 등 - 1순위 전세권 설정 불가시 100% 월세계약(보증금 최소화 요구) - 보증금 환수-1순위 전세권 설정한 경우와 1순위 전세권 설정 불가한 경우의 환수 절차 이행 | M39: 관리 | N39: 공무•설계팀, 법무지원팀 | O39: - | P39: 전세권 설정(보증보험 가입) 금전채권신탁, 채권양도계약 | T39: =VLOOKUP(A39,'GTXA사업단 R&R'!$A$6:$AO$1274,41,) -> 해당없음
A40: 32 | B40: 진해신항남방파호안1-2공구 현장 | C40: 김창진 | D40: 관리 | E40: 관리팀 | G40: 착공 전 | H40: 임차 계약 | K40: • 임차계약을 통한 사무실 임차 | L40: • 현장사무실 임대차계약 품의 실시 (현장전결) - 면적, 현장접근성, 보증금, 임대료 등 고려 | M40: 관리 | N40: 법무지원팀 | O40: 계약 조건에 대한 법무 DLS 검토 결과 | P40: 임대차계약 품의서 | T40: =VLOOKUP(A40,'GTXA사업단 R&R'!$A$6:$AO$1274,41,) -> 해당없음
A41: 33 | B41: 진해신항남방파호안1-2공구 현장 | C41: 김창진 | D41: 공무 | E41: 공무설계팀 | G41: 착공 전 | H41: 사무실 임차 집행승인(예산 내) | K41: • 집행승인을 통한 사무실 임차 | L41: • 본실행 편성이전 단가승인 필요 - 비교견적, 산출근거, 타현장비교를 통한 단가 적정성 검토 - 가설사무실 축조면적 검토 (타현장대비, 당현장 기준인원 산출) - 발주자(감리포함) 이용시설 검토 : 도급반영여부 확인 • 예산대비내역서, 집행금액 비교표, 실행/집행산출근거 등 첨부하여 현장전결 실시 | M41: 공무 | N41: 토목견적팀, 토목수행팀 | O41: - | P41: 현장사무실 임대 집행승인 품의서 | T41: =VLOOKUP(A41,'GTXA사업단 R&R'!$A$6:$AO$1274,41,) -> 해당없음
...

Sheet 수행_Process Map
B1: ■ 수행매뉴얼 Process Map
J3: ▼ | K3: 착공 전 | CP3: ▼ | CQ3: 착공 | IJ3: ▼ | IK3: 시공 | SN3: ▼ | SO3: 준공
RE4: 공사보험 청구
B5: 프로세스 | K5: 가설사무실 | Q5: 현장준비팀 운영 (T/K) | W5: 착공신고/각종인허가 | AC5: 공정 관리 | AI5: 안전 관리 | AO5: 품질 관리 | AU5: 공동도급 운영 | BA5: 본실행예산 | BG5: 현장인원 배치 | BM5: 외주 KOM/하도급 발주 | BS5: 도급 관리 | BY5: 현장차량 신청 | CE5: 자재 관리 | CK5: 원가 관리 | CQ5: 가설사무실 | CW5: 현장준비팀 운영 (T/K) | DC5: 착공신고/각종인허가 | DI5: 공정 관리 | DO5: 착공식 | DU5: 현황/확인 측량 | EA5: 현장여건 분석 | EG5: 안전 관리 | EM5: 품질 관리 | ES5: 현장주도 VE | EY5: 설계도서 검토서 제출 | FE5: 공사손해보험 가입 | FK5: 공동도급 운영회의 | FQ5: 본실행예산 | FW5: 외주 KOM/하도급 발주 | GC5: 도급 관리 | GI5: 현장차량 신청 | GO5: 자재 관리 | GU5: 노무 관리 | HA5: 환경 관리 | HG5: 원가 관리 | HM5: 공사시스템 셋팅 | HS5: 착공보고회 | HY5: 현장소장관련보고 | IE5: 리스크 기회관리부 | IK5: 도급관리 | IQ5: CF관리 | IW5: 발주처관리 | JC5: 대관업무 | JI5: 대내감사 | JO5: 대외점검 | JU5: 시공관리 | KA5: 품질관리 | KM5: 계측관리 | KS5: 문서관리 | KY5: 도면관리 | LE5: 정보 보호활동 | LK5: 자재관리 | LQ5: 회계/서무 관리 | LW5: 노무관리 | MC5: 환경관리 | MI5: 선급금 | MO5: 작업지시서 | MU5: 직영공사 | NA5: 공정관리 | NG5: 공동도급사 관리 | NM5: 안전관리 | NS5: 보건관리 | NY5: 민원처리/기술용역비 | OE5: 준공시예정원가 관리 | OK5: 경영계획 | OQ5: 설계변경 | OW5: 단가승인 | PC5: 변경실행예산 | PI5: 하도급 계약(최초) | PU5: 하도급 계약(변경) | QA5: 하도급 계약(정산) | QG5: 하도급 계약(타절) | QS5: 하도급 관리 | QY5: 집행관리 | RQ5: 소송/Claim | RW5: 중대재해 조치(최초) | SC5: 중대재해 조치(2차) | SI5: 현황/확인 측량 | SO5: 도급관리 | SU5: 원가관리 | TA5: 공정관리 | TG5: 대관업무 | TM5: 발주처 요구사항 | TS5: 시공평가보고서 | TY5: 품질관리 | UE5: 문서관리 | UK5: 회계/서무 관리 | UQ5: 노무관리 | UW5: 준공식 | VC5: 준공계획 보고 | VI5: 도급/하도급 정산 | VO5: 예비준공검사 서류준비 | VU5: 발주처 자료제출 | WA5: 국토안전관리원 자료제출 | WG5: 준공보고
K7: ▧시기 : 착공전 ▧결정 : 현장소장 ▧주관 : 공사/공무 ▧협의 : 수행팀, 견적팀 ▧목적 : 가설사무실 축조 혹은 사무실임대를 결정하여, 현장사무실 개설을 함. | Q7: ▧시기 : 실시설계 착수 전 ▧결정 : 담당임원 ▧주관 : 공무 ▧협의 : 수행팀 ▧목적 : 기본설계 이후 실시설계 및 우선공사분 진행을 위해 현장준비팀 운영이 필요함. | W7: ▧시기 : 공사 착수 전 ▧결정 : 현장소장 ▧주관 : 공무/관리 ▧협의 : 수행팀 ▧목적 : 공사도급계약서에 따른 착공신고서 제출 및 공사 착수를 위한 각종 인허가 승인 | AC7: ▧시기 : 현장착공 후 ▧결정 : 현장소장 ▧주관 : 공사(공정) ▧협의 : 토목수행팀 ▧목적 : 실공사 직전 공정계획 수립을 통한 공정표 도출 | AI7: ▧시기 : 현장착공 후 ▧결정 : 현장소장 ▧주관 : 안전 ▧협의 : 토목안전팀 ▧목적 : 산안비 집행계획 수립을 통한 안전보건관리 실행안 마련 | AO7: ▧시기 : 착공전 ▧결정 : 현장소장 ▧주관 : 품질 ▧협의 : 품질팀 ▧목적 : 현장 중점품질관리사항, 품질방침, 품질목표 수립 본부 품질활동/지침/시스템 초기세팅, 문서분류기준 수립, 자재수급계획 수립 | AU7: ▧시기 : 현장착공 후 ▧결정 : 현장소장 ▧주관 : 공무설계 ▧협의 : 토목수행팀 ▧목적 : 공동도급 운영협정서 체결 등 공동도급사간의 현장운영에 대한 합의사항 도출 | BA7: ▧시기 : 실착공 전 ▧결정 : 현장소장 ▧주관 : 공무설계 ▧협의 : 토목견적팀 ▧목적 : 현장집행을 위한 예산 편성 | BG7: ▧시기 : 현장착공 후 ▧결정 : 현장소장 ▧주관 : 공무설계 ▧협의 : 토목수행팀 ▧목적 : 현장운영에 필요한 적정, 적기의 투입인원 산정 및 선정 | BM7: ▧시기 : 실착공 전 ▧결정 : 현장소장 ▧주관 : 공무설계 ▧협의 : 토목수행팀 ▧목적 : 공정, 예산, 공종을 고려한 최적의 집행(안) 수립 | BS7: ▧시기 : 현장착공 후 ▧결정 : 현장소장 ▧주관 : 공무설계 ▧협의 : 토목수행팀 ▧목적 : 발주처와의 유기적인 업무가 가능한 도급관리 절차 확인 | BY7: ▧시기 : 현장착공 후 ▧결정 : 현장소장 ▧주관 : 공무설계 및 관리 ▧협의 : 토목수행팀 ▧목적 : 현장운영에 부합되는 적정 차량의 적기 투입 | CE7: ▧시기 : 실착공 전 ▧결정 : 현장소장 ▧주관 : 관리 ▧협의 : 건설자재관리팀 ▧목적 : 단가 조사를 통한 집행(안) 수립 및 원가율 검토 | CK7: ▧시기 : 현장착공 후 ▧결정 : 현장소장 ▧주관 : 공무설계 ▧협의 : 토목수행팀 ▧목적 : 원가관리를 통한 적정 이익 확보 | CQ7: ▧시기 : 공사계획서 , 인허가 승인 완료 이 후 ▧결정 : 현장소장 ▧주관 : 공사/공무 ▧협의 : 수행팀 ▧목적 : 현장 인원의 업무를 위한 가설사무실 축조(사무실 본동, 시험실, 안전교육장, 회의실, 상황실등) | CW7: ▧시기 : 공사 착공 전 ▧결정 : 현장소장 ▧주관 : 공무/공사 ▧협의 : 수행팀 ▧목적 : 공사 착수 전(Pre-work 진행 단계) 현장준비팀 투입으로 발굴된 PJT Risk, 유관기관의 Needs에 대한 정보단절 방지와 착공 전 업무의 수행 | DC7: ▧시기 : 착공 시 ▧결정 : 현장소장 ▧주관 : 공무/공사/관리 ▧협의 : 수행팀 ▧목적 : 공사 착공 신고 및 법적 배치인원 선임(현장대리인 등), 공사 착수에 필요한 인허가 승인 | DI7: ▧시기 : 착공 시 ▧결정 : 현장소장 ▧주관 : 공사 ▧협의 : 수행팀 ▧목적 : | DO7: ▧시기 : 착공직후(필요시) ▧결정 : 현장소장 ▧주관 : 공무 ▧협의 : 견적팀, 수행팀 ▧목적 : 사업시작을 공식화 하고 발주처 및 지역언론, 주민들과의 관계 강화 | DU7: ▧시기 : 착공계 직후 ▧결정 : 현장소장 ▧주관 : 공사/공무 ▧협의 : 견적팀, 수행팀 ▧목적 : 실공사 직전 공사(확인)측량 및 연도변조사를 실시하여 설계 일치여부를 확인하고, 공사구간을 확정함. | EA7: ▧시기 : 착공 직후 ▧결정 : 공사팀장/현장소장 ▧주관 : 공사 ▧협의 : 공무-설계팀, 관리팀 ▧목적 : 현장주변 여건 분석을 통해 사전 Risk요인 제거 | EG7: ▧시기 : 착공 단계 ▧결정 : 안전팀장/현장소장 ▧주관 : 안전 ▧협의 : 토목안전팀 ▧목적 : 안전보건 관계법령 및 사내 기준을 준수한 현장 안전보건체계를 초기 정립, 공사장 안전사고 방지 및 공사관계자의 안전인식 개선을 위한 교육 등 | EM7: ▧시기 : 착공 단계 ▧결정 : 품질팀장/현장소장 ▧주관 : 품질/공사 ▧협의 : SEQ RM팀/토목품질팀 ▧목적 : 건진법 시행령 제89조 제1항에 따라 품질관리계획서를 작성하여 현장 품질관리 업무 수행 및 활동 | ES7: ▧시기 : 실 착공 후 3개월 이내 ▧결정 : 현장소장 ▧주관 : 수행팀 ▧협의 : 발주처 및 감리단 ▧목적 : 현장원가 절감 item 발굴 | EY7: ▧시기 : 착공 단계 ▧결정 : 공무팀장/현장소장 ▧주관 : 공무 ▧협의 : 토목견적팀/토목수행팀/외주관리팀/토목스마트엔지니어링팀 ▧목적 : 내역서, 도면, 수량산출서 검토하여 현장 문제 item 확인 및 리스크 hedge | FE7: ▧시기 : 착공 단계 ▧결정 : 공무팀장/현장소장 ▧주관 : 공무 ▧협의 : 자금팀/수행팀 ▧목적 : 공사손해보험 가입 및 검토 | FK7: ▧시기 : 착공 단계 ▧결정 : 공무팀장/현장소장 ▧주관 : 공무 ▧협의 : 수행팀 ▧목적 : 현장 운영에 대한 공동도급사간의 의견 취합 및 합의사항 도출 및 운영방안 수립/해결안 제시 | FQ7: ▧시기 : 착공 단계 ▧결정 : 공무팀장/현장소장 ▧주관 : 공무 ▧협의 : 수행팀 ▧목적 : 현장 운영에 대한 공동도급사간의 의견 취합 및 합의사항 도출 및 운영방안 수립/해결안 제시 | FW7: ▧시기 : 하도급 발주전 ▧결정 : 현장소장 ▧주관 : 공무/공사/관리 ▧협의 : 외주관리팀/건설자재관리팀/견적팀/수행팀/GPSRM팀 ▧목적 : 현장운여을 위한 하도급 발주전략 적정성 검토 및 지급/지입자재 분류 | GC7: ▧시기 : 착공 단계 ▧결정 : 공무팀장/현장소장 ▧주관 : 공무 ▧협의 : 수행팀 ▧목적 : 발주처와의 유기적인 업무가 가능한 도급관리 절차 확인 | GI7: ▧시기 : 착공 단계 ▧결정 : 공무팀장/현장소장 ▧주관 : 공무 ▧협의 : 수행팀/행정운영지원팀 ▧목적 : 현장에 필요한 차량의 운영/집행에 대한 승인 및 소요차량 적기 신청 | GO7: ▧시기 : 착공 단계 ▧결정 : 관리팀장/현장소장 ▧주관 : 관리 ▧협의 : 건설자재관리팀/토목안전팀 ▧목적 : 현지 구입자재의 단가 조사를 통한 집행(안) 수립 및 원가율 검토 및 업체 선정을 통한 적기 물품 수급 | GU7: ▧시기 : 착공 단계 ▧결정 : 관리팀장/현장소장 ▧주관 : 관리 ▧협의 : 토목 기획팀/HR지원팀 ▧목적 : 현장 인력소요계획 검토 및 직원 근로계약 관리 | HA7: ▧시기 : 착공 단계 ▧결정 : 관리팀장/현장소장 ▧주관 : 관리 ▧협의 : SEQ RM팀 ▧목적 : 대외기관 및 발주처 점검 계획 수립 및 환경 사고 재발 방지 | HG7: ▧시기 : 착공 단계 ▧결정 : 관리팀장/현장소장 ▧주관 : 관리 ▧협의 : SEQ RM팀 ▧목적 : 대외기관 및 발주처 점검 계획 수립 및 환경 사고 재발 방지 | HM7: ▧시기 : 착공 단계 ▧결정 : 공무팀장/현장소장 ▧주관 : 공무 ▧협의 : 토목수행팀/토목견적팀/외주계약팀 ▧목적 : 현장의 발주, 기성, 원가, 손익관리를 위한 기본사항 입력 후 도급 실행관리와 적기 외주관리 | HS7: ▧시기 : 착공 단계 ▧결정 : 공무팀장/현장소장 ▧주관 : 공무 ▧협의 : 토목수행팀/토목견적팀/토목안전팀/토목품질팀/토목계약관리팀/GP,SRM팀/외주계약팀/SEQ RM팀/토목기획팀등 ▧목적 : 현장 운용 계획 검토 및 문제 발생 사전 예방 | HY7: ▧시기 : 착공 단계 ▧결정 : 공무팀장/현장소장 ▧주관 : 공무 ▧협의 : 토목수행팀 ▧목적 : 현장소장 교체시 인수인계서 작성으로 현장 업무공백 최소화 | IE7: ▧시기 : 착공 단계 ▧결정 : 품질팀장/현장소장 ▧주관 : 품질 ▧협의 : SEQ RM팀 ▧목적 : 현장 업무수행시 발생할 가능성이 있는 잠재적인 이슈 및 리스크를 파악하여 발생을 예방, 발생시 리스크에 따른 손실을 최소화 | IK7: ▧시기 : 공사단계 주기적 실시 ▧결정 : 현장소장 / 공무팀장 ▧주관 : 설계 / 공무 ▧협의 : 공사 ▧목적 : 총체(차수)계약 변경 및 설계변경 등 도급계약관리, 도급기성 관리 등을 통한 청구/수금 관리 | IQ7: ▧시기 : 매월 ▧결정 : 현장소장 / 공무팀장 ▧주관 : 공무 / 설계 ▧협의 : 토목수행팀 ▧목적 : 집행/수금계획 관리를 통한 보다 명확한 CF관리 및 자금수지 계획 수립 | IW7: ▧시기 : 매년, 발생시 ▧결정 : 현장소장 / 공무팀장 ▧주관 : 설계 ▧협의 : 공사 ▧목적 : 효율적인 대관업무 진행 및 당사 이미지제고를 위한 발주처 요청자료 제공, 현장 방문응대 실시 | JC7: ▧시기 : 발생시 ▧결정 : 현장소장 ▧주관 : 공무/공사/관리/안전 ▧협의 : 현장 ▧목적 : 현장의 공정추진을 위한 각종 인허가 및 신고 업무 수행 | JI7: ▧시기 : 발생시 ▧결정 : 현장소장 ▧주관 : 공무/공사/관리/안전 ▧협의 : 현장 ▧목적 : 사내 제규정 준수 여부 감사 및 업무 수행의 효율성 진단 | JO7: ▧시기 : 발생시 ▧결정 : 공사팀장/공무팀장/현장소장 ▧주관 : 설계/공사 ▧협의 : 토목품질팀/토목견적팀/토목수행팀/외주계약팀 ▧목적 : 대외감사 수검을 위한 자료 준비, 감사 수검 및 대응 | JU7: ▧시기 : 공사착공전, 공사시 ▧결정 : 공사팀장/품질팀장/안전팀장/현장소장 ▧주관 : 품질/공사/안전 ▧협의 : 토목스마트엔지니어링팀/토목안전팀 ▧목적 : 시공단계 전과 시공단계의 원활한 공사 관리와 전반적인 안전, 품질, 자재, 환경 등의 관리 | KA7: ▧시기 : 공사착공전, 공사시 ▧결정 : 발주처 ▧주관 : 품질 ▧목적 : 발주자 요구사항의 계약 및 충족을 위한 품질관리계획 수립, 품질시험계획에 따른 품질시험·검사의 적기, 적정빈도 실시여부 | KM7: ▧시기 : 연약지반 개량시점 ▧결정 : 공사팀장, 품질팀장 ▧주관 : 현장 공사/품질팀 ▧협의 : 공무설계팀/안전팀 ▧목적 : 연약지반 개량시점에 맞춰 계측기 설치위치, 방법, 계측결과 확인(보고서 참고) | KS7: ▧시기 : 발생시 ▧결정 : 현장소장 ▧주관 : 관리/공무 ▧협의 : 행정운영지원팀,SEQ RM팀 ▧목적 : 현장운영중 발생되는 문서의 작성, 배부및 접수체계의 효율성을 제고를 통한 진행중 열람의 용이성 확보 | KY7: ▧시기 : 도면 변경 사항 발생시 ▧결정 : 현장소장 ▧주관 : 공무설계/공사 ▧목적 : 최신 개정된 도면에 대한 각 팀, 협력업체 공유하여 도면 관리 잘못에 따른 재공사 및 보수작업을 방지 | LE7: ▧시기 : 발생시 ▧결정 : 현장소장 ▧주관 : 정보보호담당자/IT자산관리담당자 ▧협의 : IT기획팀 ▧목적 : 현장의 정보자산 및 IT자산의 적정 관리를 통한 회사자산의 보호 및 업무 효율성 제고 | LK7: ▧시기 : 발생시 ▧결정 : 현장소장 ▧주관 : 현장 ▧협의 : 관리팀/공무팀/공사팀 ▧목적 : 설계 및 시방에 요구되는 자재의 품질확보 및 소요 자재 적기반입 | LQ7: ▧시기 : 매월 마감시, 상시 ▧결정 : 관리팀장/현장소장 ▧주관 : 관리 ▧협의 : 회계팀/자금팀/행정운영지원팀/HR지원팀 ▧목적 : 현장 전반적인 회계와 서무관리를 통한 직원들의 업무 지원 | LW7: ▧시기 : 채용발생시, 산재 발생시 ▧결정 : 관리팀장/안전팀장/현장소장 ▧주관 : 관리/안전 ▧협의 : 토목기획팀/HR지원팀 ▧목적 : 현장직원 채용관리 및 산재발생시 요양관리&합의 도출 | MC7: ▧시기 : 점검 발생시 ▧결정 : 관리팀장/현장소장 ▧주관 : 관리 ▧협의 : SEQ RM팀 ▧목적 : 현장 환경관리를 통한 점검 대비 및 환경사고에 대한 RISK방지 | MI7: ▧시기 : 선급금 발생시 ▧결정 : 공무팀장/현장소장 ▧주관 : 공무 ▧협의 : 토목수행팀/외주관리팀 ▧목적 : 현장 CF관리 및 적기 선급금 수령 및 지급 | MO7: ▧시기 : 작업지시사항 발생시 ▧결정 : 공사팀장/공무팀장/현장소장 ▧주관 : 공사/공무 ▧협의 : 토목수행팀/토목견적팀 ▧목적 : 설계 외 작업에 대한 수량 검토 및 승인, 작업지시서 관련 문제 해결방안 수립 | MU7: ▧시기 : 직영공사 공종 발생시 ▧결정 : 공사팀장/품질팀장/관리팀장/공무팀장/현장소장 ▧주관 : 공사/공무 ▧협의 : 토목수행팀/토목계약관리팀 ▧목적 : 직영공사 수행시 추가 원가를 방지하고 원활한 공사 수행을 위한 사전 준비 및 직영공사 관리와 각종 계약 및 승인처리 | NA7: ▧시기 : 공사 전 및 공사 수행시 상시 ▧결정 : 공사팀장/현장소장 ▧주관 : 공사(공정) ▧협의 : 토목수행팀 ▧목적 : 현장 공사 착수 전 부터 준공까지 공정관리를 수시로 진행하여 원활한 공사 관리와 연간 예산을 차질없이 소화 | NG7: ▧시기 : 공사 전 및 공사 수행시 상시 ▧결정 : 공무팀장/관리팀장/현장소장 ▧주관 : 공무 ▧협의 : 토목수행팀/토목국내영업팀/회계팀 ▧목적 : 안분미수, 원가약정 협의, 신탁계약 및 법정관리를 통한 공동도급사 관리 | NM7: ▧시기 : 공사 실 착공시 ▧결정 : 안전보건총괄책임자(현장소장) ▧주관 : 현장소장, 안전 ▧협의 : 토목안전팀 ▧목적 : 공사 수행으로 발생되는 사고 예방을 목적으로 안전교육, 산업안전보건관리비 집행, 현장 위험요인 파악 및 개선 등 업무 추진 | NS7: ▧시기 : 공사 실 착공시 상시 ▧결정 : 안전팀장/안전보건총괄책임자(현장소장) ▧주관 : 현장소장, 안전팀 ▧협의 : 토목안전팀/안전보건팀 ▧목적 : 공사 수행으로 발생되는 보건관리일반업무, MSDS관리, 작업환경 측정 등 근로자의 건강과 보험에 대한 관리 | NY7: ▧시기 : 공사 실 착공시 상시 ▧결정 : 관리팀장/공무팀장/현장소장 ▧주관 : 공무 ▧협의 : 토목수행팀/언론홍보팀/토목견적팀/자금팀 ▧목적 : 발생되는 민원 및 언론취재에 대한 대응 및 기술용역비 집행/실적관리 | OE7: ▧시기 : 매월 마감시 ▧결정 : 현장소장 ▧주관 : 공무/공사/관리 ▧협의 : 수행팀/회계팀 ▧목적 : 현장의 대내외 여건 변경, 도급 설계변경 등 현안이슈 반영에 따른 준공시예정원가 변동 관리 | OK7: ▧시기 : 매년 9~10월 ▧결정 : 현장소장 ▧주관 : 공무/공사/관리 ▧협의 : 수행팀 ▧목적 : 현장의 년도별 사업수지 및 자금수지 목표 수립 | OQ7: ▧시기 : 발주처별 상이하나 반기 or 분기 ▧결정 : 공무팀장/현장소장 ▧주관 : 공무 ▧협의 : ▧목적 : 현장의 설계변경 사유발생시 설계변경과 승인을 위한 발주처와의 협의 진행 | OW7: ▧시기 : 실정보고 제출/승인 or 도급변경계약 완료시기 ▧결정 : 토목견적팀장 ▧주관 : 공무 ▧협의 : ▧목적 : 신규공사에 대한 적정 공사금액을 확정하고 증감내용 분석 및 하도급변경계약 반영 | PC7: ▧시기 : 토목견적팀 기준별 1회 ▧결정 : 토목사업본부장 ▧주관 : 공무, 토목견적팀 ▧협의 : 토목사업관리팀 ▧목적 : 본실행대비 변경사항 (신규공사, 수량증감)에 대해 실행예산 반영하고 기승인예산에 대한 단가조정(필요시) | PI7: ▧시기 : 공종별 발주시기별 수시 ▧결정 : 1) 경쟁입찰 : 토목수행팀장, 외주담당임원 2) 수의계약(10억초과) : 토목담당임원, 외주담당임원 ▧주관 : 공무, 토목수행팀 ▧협의 : 토목사업관리팀, 토목견적팀 ▧목적 : 공사수행을 위한 발주전략 선정 및 업체선정, 계약체결 | PU7: ▧시기 : 계약내용 변경 및 공사 진행 사항 변경시 ▧결정 : 공무팀장/현장소장 ▧주관 : 공무 ▧협의 : 토목수행팀/외주관리팀 ▧목적 : 하도급 업체별 변경계약 및 계약반영 | QA7: ▧시기 : 계약내용 변경 및 공사 진행 사항 변경시 정산 ▧결정 : 공사팀장/공무팀장/현장소장 ▧주관 : 공무/공사 ▧목적 : 하도급 업체별 변경계약 및 계약반영 정산 | QG7: ▧시기 : 타절 발생시 ▧결정 : 공무팀장/현장소장 ▧주관 : 공무 ▧목적 : 타절 발생시 최종 공사물량 정산에 따른 계약체결 | QS7: ▧시기 : 계약내용 변경 및 공사 진행 사항 변경시 정산 ▧결정 : 공사팀장/공무팀장/현장소장 ▧주관 : 공무/공사 ▧목적 : 하도급 업체별 변경계약 및 계약반영 정산 | QY7: ▧시기 : 컨티 및 여건 발생시, 긴급공사비 발생시 ▧결정 : 공사팀장/공무팀장/현장소장 ▧주관 : 공무 ▧목적 : 컨티 및 여건 발생시 하도급 집행승인 및 변경계약, 긴급공사 집행 품의 | RE7: ▧시기 : 공사중 피해물량 혹은 손해 발생시 ▧결정 : 공사팀장/공무팀장/현장소장 ▧주관 : 공무 ▧목적 : 발생할 수 있는 피해를 미리 예측하고, 그에 따른 물량을 사전에 검토하여 프로젝트 예산에 반영하거나 추가 대책 마련(보험금 수령 및 하도급 변경계약) | RQ7: ▧시기 : 소송 및 Claim 발생시 ▧결정 : 공무팀장/현장소장 ▧주관 : 공무 ▧목적 : 분쟁 사안에 대한 현장 계약조건 분석 및 승소 가능성 분석 및 협의, 소송/진행상황 모니터링 | RW7: ▧시기 : 발생시 ▧결정 : 현장소장 ▧주관 : 안전/공무 ▧협의 : 안전팀 ▧목적 : 중대재해 발생 시 긴급조치로 2차 재해를 방지하고, 사후 대응조직을 구성하여 신속하게 사건을 수습하고 작업을 재개하며, 향후 유사재해를 방지코자 함 | SC7: ▧시기 : 발생시 ▧결정 : 현장소장 ▧주관 : 현장 ▧협의 : 토목안전팀/안전보건팀 ▧목적 : 사고의 근본원인 조사 및 대책 수립. 과실 책임자 선정. 중대재해 수사기관 대응 및 법적 Risk 최소화를 통한 금전적 손실 최소화. | SI7: ▧시기 : 측량시 ▧결정 : 공무팀장/공사팀장/현장소장 ▧주관 : 공사 ▧협의 : 토목수행팀/토목견적팀/토목안전팀 ▧목적 : 현장 공사 수행에 필요한 공사 현황 및 확인 측량을 진행(계약~측량) | SO7: ▧시기 : 준공시 ▧결정 : 공사팀장/공무팀장/품질팀장/현장소장 ▧주관 : 공무 ▧협의 : 토목계약지원팀/GP,SRM팀/토목품질팀/토목계약관리팀/컴플라이언스RM팀/발주처/자금팀 ▧목적 : 최종 준공 도급내역서 청구 및 발주처 설계도서 제출 | SU7: ▧시기 : 준공시 ▧결정 : 관리팀장/공무팀장/현장소장 ▧주관 : 공무 ▧협의 : 토목수행팀/토목기획팀 ▧목적 : 준공금청구, 준공충담금 설정, 준공시예정원가 검토 | TA7: ▧시기 : 준공시 ▧결정 : 공사팀장/현장소장 ▧주관 : 공사 ▧협의 : - ▧목적 : 준공공정표 작성, 잔여공사 공정관리, 공정DATA관리를 통한 공사 중 지연 RISK hedge | TG7: ▧시기 : 준공시 ▧결정 : 공사팀장 ▧주관 : 공사 ▧협의 : - ▧목적 : 준공공정표 작성, 잔여공사 공정관리, 공정DATA관리를 통한 공사 중 지연 RISK hedge | TM7: ▧시기 : 준공시 ▧결정 : 공사팀장 ▧주관 : 공사 ▧협의 : - ▧목적 : 준공시 보완할 부분에 대한 Punch List정리 및 발주처 요구에 대한 계획수립 후 조치(협의 승인) | TS7: ▧시기 : 준공후 ▧결정 : 현장 전 부서/공무팀장/현장소장 ▧주관 : 현장소장 ▧협의 : 토목품질팀 ▧목적 : 현장 각 부서팀에서 관리 항목 작성 및 시공평가보고서 취합 후 발주처 제출 | TY7: ▧시기 : 준공시 ▧결정 : 현장소장 ▧주관 : 품질 ▧협의 : 품질팀 ▧목적 : 발주처 준공 승인에 필요한 품질활동(각종 시험성적서 정리, 준공전 하자 조치) | UE7: ▧시기 : 준공시 ▧결정 : 관리팀장 ▧주관 : 관리 ▧협의 : - ▧목적 : 준공시 현장 프로젝트 문서 등재 및 담당자 지정, 최종 문서 제출 확인 및 결재 상신 | UK7: ▧시기 : 준공시 ▧결정 : 관리팀장/품질팀장/공무팀장 ▧주관 : 관리, 공무 ▧협의 : - ▧목적 : 준공시 현철수계획 수립을 통한 각종 철수 및 정산업무수행 및 직원 인사발령의뢰 | UQ7: ▧시기 : 준공시 ▧결정 : 관리팀장/안전팀장/현장소장 ▧주관 : 관리/안전 ▧협의 : - ▧목적 : 상용직 및 일용직 퇴직금 정산, 산재환자 본사이관 업무 | UW7: ▧시기 : 준공시 ▧결정 : 관리팀장/공무팀장/현장소장 ▧주관 : 관리/공무 ▧협의 : 발주처 ▧목적 : 준공식 행사를 위해 필요한 사전준비, 성공적인 준공식 행사 수행 | VC7: ▧시기 : 준공시 ▧결정 : 공무팀장/현장소장 ▧주관 : 공무 ▧협의 : 토목수행팀/자금팀/토목품질팀/토목스마트엔지니어링팀/토목기획팀 ▧목적 : 계약준공일에 맞춰 적기준공에 필요한 사안들을 계획 및 검토, 본사 준공계획보고 및 직원 철수계획 수립 | VI7: ▧시기 : 준공시 ▧결정 : 공무팀장/현장소장 ▧주관 : 공무 ▧협의 : 토목수행팀/외주관리팀/토목수행팀/발주처/감리 ▧목적 : 원활한 준공을 위한 도급정산내역서 작성 및 하도급 정산 | VO7: ▧시기 : 준공시 ▧결정 : 현장 전체 팀/현장소장 ▧주관 : 전체 팀 ▧협의 : 토목품질팀 ▧목적 : 원활한 준공을 위한 예비준공 서류준비(각 팀) | VU7: ▧시기 : 준공시 ▧결정 : 공사팀장/공무팀장/현장소장 ▧주관 : 공사/공무 ▧협의 : 토목품질팀/토목수행팀 ▧목적 : 준공시 최종 발주처 제출 자료 취합 및 승인 | WA7: ▧시기 : 준공시 ▧결정 : 공사팀장/공무팀장/품질팀장/안전팀장/현장소장 ▧주관 : 공사/공무/품질/안전 ▧협의 : 토목품질팀 ▧목적 : 국토안전관리원 제출 자료 취합 및 최종 제출(준공보고서, 관리대장, 준공내역서, 시방서 등) | WG7: ▧시기 : 준공시 ▧결정 : 공무팀장/현장소장 ▧주관 : 공무 ▧협의 : 토목품질팀/토목스마트엔지니어링팀/토목견적팀/자재구매팀 ▧목적 : 준공정산요약보고, 감사보고서, 준공정산자료 최종 작성을 통한 원활한 적기 준공
B13: Input Data (시스템/데이터) | K13: 단가승인 근거 (전자결재/품의서) | Q13: 실시설계 예산 근거 (전자결재/품의서) | W13: 공사도급계약서 | AC13: 설계도서(도면, 시방서 등) | AO13: 설계도서(도면, 시방서 등) | BA13: 견적실행예산서 | BG13: 공정 추진 계획 | BM13: 설계도서(도면, 시방서 등) | BY13: 실행예산서/단가승인서 | CE13: 견적서 | CK13: 마감 자료 | CQ13: 시공계획서 작성 (개인 PC) | CW13: 단가및집행승인 검토자료 | DC13: 유해위험방지계획서 | DI13: 예정공정표 | DU13: 경계측량 의뢰서 (전자결재/품의서) | EA13: 관련기관 회의록 | EG13: 설계도서 (도면, 시방서 등) | ES13: 참여 전문가 List | EY13: 설계도서(도면, 시방서 등) | FE13: 보험가입 관련 내역 | FK13: 표준 공동도급 협약서 | FQ13: 현장 R/O | FW13: 설계도서(도면, 시방서 등) | GI13: 실행예산서/단가승인서 | GO13: 자재소요계획서 | GU13: 조직운영계획 | HA13: 환경관리계획서 | HG13: 현장관리내역서 | HM13: 프로젝트관리 현장정보 | HS13: 착공보고회 발표자료 | IK13: 실정보고 공문 | IQ13: 공사시스템 | JC13: 유관기관 List (인허가 승인 기관 등) | JI13: 감사 준비 자료 List (경영진단팀, 토목사업지원팀) | JO13: 각종 영향평가 관리대장 | JU13: 예정 공정표 | KA13: CPMS 문서 | KG13: 반입송장 | KM13: 예산대비내역서, 업체선정의뢰서, 입찰심의 관리 | KS13: 수발신공문 (코러스, e캐비넷) | KY13: 기록관리 (현장 서류) | LE13: 각종계약서, 사내규정, 지침서,매뉴얼,시스템문서 | LK13: 자재 신청서 | LQ13: 영수증, 계산서, 세금계산서 | MC13: 환경시설 List | MI13: 선급금 청구서 | MO13: 작업지시서 발급 적정성 검토서류 | MU13: 직영 시공 검토서 | NA13: 3 Weeks 작성 | NG13: 공동도급운영 협정서 | NM13: 산업안전보건관리비 사용계획서 | NS13: 안전보건관리 계획 | NY13: 민원조사보고서 | OE13: 매출원가 (공사시스템) | OK13: 향후 발생 원가 (재무전망) | OQ13: 설계도서(도면, 시방서 등) | OW13: 실행단가 산출근거 | PC13: 기승인 단가승인 (전자결재/품의서) | PI13: 공종별 예산대비내역서 | PO13: 수의계약 검토자료 (품의서/전자결재) | PU13: 설계변경(실정보고) 승인자료 | QA13: 공사 수행 실적 | QG13: 공사 수행 실적 | QM13: 간접비 집행 근거 | QS13: 공사 투입원가 | QY13: 현장 여건 | RE13: 피해물량 사전 검토 자료 | RK13: 공사손해보험 접수 | RQ13: 승소가능성 검토서 | SC13: 사고 관련 자료 | SI13: 용역 검토자료 | SO13: 정산, 간접비 집계표 | SU13: 합계잔액시산표 | TA13: 공사 실적 | TM13: 펀치리스트 | TS13: 위치별 업체 시공 현황 | UE13: 프로젝트문서 원본 | UK13: 현장 철수 계획 (철수인원, 시기) | UQ13: 근로계약서 | VC13: 설계변경 자료 | VI13: 설계변경 자료 | VO13: 예비준공검사 자료 | VU13: 시공상세도 및 발주처 제출자료 | WA13: 국토안전관리원 자료 | WG13: 준공보고서
K15: 집행승인 근거 (전자결재/품의서) | W15: 법정 인원 선임계 | CW15: 우선시공 검토자료 | DC15: 공사안전보건대장 | FE15: 보험약관(안) | HG15: 공동공사비 집행 자료 | HM15: 본실행예산내역서 | HS15: 준공시 예정원가검토서 | IK15: 계약변경 요청 공문 | IQ15: 경영계획 수립자료 | JO15: 점검 대상 현장 통보 공문 | KA15: 현장확인 | KM15: 지반조사 결과 보고서 | LE15: 연구노트,도면,영업실적, 경영보고서,인사관련서류 | LK15: 현지 구입 승인신청서 | MI15: 선금보증증권 | MU15: 직영 시공계획서 | NA15: 토목pmis 작업일보 | NG15: 공동도급 안분금 청구 공문 | NM15: 장비작업계획서 | NS15: 작업환경측정 계획표 | OE15: 향후 실정보고 예상 | OK15: 예정공정표(P6) | OW15: 전문업체 견적서 | PC15: 기집행 근거자료 (경상비/여건보고/집행승인) | PI15: 외주자재 KOM검토자료 | PO15: 업체선정의뢰 (공동사 추천공문) | PU15: 하도승인의뢰서 | QA15: 간접비 집행 근거 | QG15: 계약해지 예고 공문 | QM15: 노임/장비/자재 체불현황 | QS15: 자재 투입 현황 | RE15: 피해복구 내역서 | SI15: 현장설명서 | SO15: 설계변경 승인자료 | SU15: 집행실적 (외주,직영,경상비,자재 등) | VC15: 컨티전시/여건보고 자료 | VI15: 간접비 실적 증빙
K17: 업체선정의뢰 근거 (외주시스템) | DC17: 안전관계자선임보고서 | HG17: 간접공사비 집행 자료 | HS17: 최초 공정계획 (Baseline) | IK17: 물가변동 보고서 | IQ17: 재무전망 | KM17: 실시설계 도면 (필요시 원설계자 의견서) | LE17: 노트북,본체, 테블릿,서버,VPN | LK17: 철근가공장 선정품의 | NA17: 작업일보 | OE17: 컨틴젼시/여건보고 등 | OK17: 도급기성 청구/수금 | OW17: 현장여건 현황자료 | PC17: 현장여건 현황자료 | PI17: 발주설명회 KOM | PO17: 입찰참여 적격심사자료 (신용등급, 시평액, 기술자료 등) | VC17: 컨티전시/여건보고 자료
K19: 하도승인의뢰 근거 (외주시스템) | DC19: 최초위험성평가 | HG19: 직영분(지급자재 등) 집행 자료 | HS19: 민원별 관리방안 | IK19: 간접비 등 증빙서류 | IQ19: 안분청구공문 | KM19: 설계안정성 검토서(DFS) | PI19: 예가/도급대비내역서 (관통보) | PO19: 저가심의 검토자료(시공사) 하도급 자기심사표(발주처)
B21: Output Data (시스템/데이터) | K21: 단가승인 (전자결재/품의서) | Q21: 실시설계 예산 승인 (전자결재/품의서) | W21: 인허가 승인 공문 | AC21: 공정표 및 CP | AI21: 산업안전보건관리비 집행계획 | AO21: 중점 품질관리 사항 | AU21: 공동도급 운영회의록 | BA21: 본실행예산서 | BG21: 현장조직도 | BM21: 하도급 발주계획(서) | BS21: 도급관리 처리절차(서) | BY21: 현장차량 집행승인 결재서 | CE21: 단가 목록 및 단가별 견적대비표 | CK21: 경상비 투자분석 양식 | CQ21: 시공계획서, 인허가 승인 (건설사업관리단, 지자체) | CW21: 단가승인 (전자결재/품의서) | DC21: 발주처 승인 공문 | DI21: 예정공정표 | DO21: 집행승인 (전자결재/품의서) | DU21: 용역 집행승인 (전자결재/품의서) | EA21: 민원 대장 | EG21: 개인보호구 지급대장 | EM21: ITP, ITC (개인PC) | ES21: VE 성과보고서 | EY21: 설계도서 검토서 | FE21: 보험가입 계약서 | FK21: 공동도급 협약서(날인본) | FQ21: 본실행 예산 (준공시예정원가율) | FW21: 관리내역서 | GC21: 도급관리 처리절차(서) | GI21: 현장차량 입고 | GO21: 자재 보관/불출 관리대장 | GU21: 근로계약서 | HA21: 환경관리비 사용계획서 | HG21: 준공시예정원가 검토서 | HM21: 외주발주계획 (공사시스템) | HS21: 착공보고회 회의록 | HY21: 업무 인수인계서 | IE21: 리스크/기회 관리부 | IK21: 계약변경 요청자료 | IQ21: 자금관리 | IW21: 발주처 조직도 | JC21: 각종 인허가 승인 공문 | JI21: 감사 결과 보고서 | JO21: 감사 결과 보고서 | JU21: 3 week DPM | KA21: 품질관리계획서 | KG21: 품질시험계획서 | KM21: 계약서 | KS21: 발송대장,접수대장 (코러스,e캐비넷) | KY21: 도면 배부 및 기록대장 (현장 서류) | LE21: 반납확인서, 인수 확인서 | LK21: 자재소요계획서 (DQMS/검수요청서) | LQ21: eFMS재무회계 입력값 | LW21: 근로계약서 | MC21: 환경관리 check List | MI21: 기성수금현황 관리대장 | MO21: 작업지시서 | MU21: 노무/장비/자재 계약서 | NA21: P6 공정표(실적 update) | NG21: 안분미수 관리대장 | NM21: 안전보건에 관한 협의체 회의록 | NS21: 작업환경측정 결과표 | NY21: 민원 면담회의록 | OE21: 월마감 자료 (공사시스템/원가마감) | OK21: 사업 및 자금수지 (재무전망/투입계획) | OQ21: CCLS (Change Control Log Sheet) | OW21: 단가승인내역서 | PC21: 변경실행내역서 | PI21: 업체선정 의뢰서 (전자결재/품의서) | PO21: 수의업체 선정의뢰서 (전자결재/품의서) | PU21: (변경)하도급계약서 | QA21: (정산)하도급계약서 | QG21: (타절)하도급계약서 | QM21: (타절)예산대비내역서 | QS21: 동반성장 To-Do-List | QY21: 하도급 변경계약서 | RE21: 보험금 수령현황 | RQ21: 소송/진행상황 모니터링 | RW21: 사고 보고서 | SC21: 언론접촉일지 | SI21: 측량계획서 | SO21: 준공도서 | SU21: 공무/회계원가 대비표 | TA21: 주요공종 실적 DATA | TG21: 각종 시설 폐쇄신고 (폐기물, 환경, 정화조, 오수 등) | TM21: 발주처 요구사항 조치계획 | TS21: 시공평가보고서 | TY21: 협력업체 하자 펀치리스트 | UE21: 프로젝트문서 제출확인서 | UK21: 인사발령 | UQ21: 퇴직금 정산 | UW21: 준공식 | VC21: 준공계획보고서 | VI21: 최종도급계약서 | VO21: 예비 준공검사 승인 | VU21: 발주처 자료 검토 승인 | WA21: 발주처 인수 통보서 | WG21: 준공정산자료
K23: 집행승인 (전자결재/품의서) | AC23: 공정 Risk 분석 리포트 | AU23: 공동도급 운영협정서 | BG23: 인력운영계획서 | BM23: 자재 발주계획(서) | BY23: 현장차량 입고 | CE23: 안전용품 구입업체 선정 품의서 | CK23: 월별 마감 분석자료 양식 | CW23: 집행승인 (전자결재/품의서) | DO23: 착공식 행사계획 (개인PC) | DU23: 용역 업체선정의뢰서 (전자결재/구매시스템) | EA23: 문화재 발굴조사 보고서 | EM23: 현장평가, CSI등록 (DQMS, CSI) | EY23: 지반조사 보고 검토서 | FK23: 신탁 계약서 | FW23: 공종별 예산대비내역서 | GO23: 주요자재 관리대장 | HA23: 세륜기운행일지 | HS23: 현장 관리방안 Feedback | IK23: 변경 설계도서 | IQ23: 안분관리대장 | IW23: 실정보고 자료 | JU23: 각종 작업일보 | KA23: 검교정관리대장 | KG23: 품질관리비 사용내역 | KM23: 계측기 설치검토서, 회의록 | KY23: 도면 배부 및 접수확인서 (현장 서류) | LK23: 공인기관성적서 (CSI/시험성적서) | LQ23: eFMS자금관리 입력값 | MC23: 환경관리비 집행 현황 | NG23: 안분미수 회수 업무 (가압류 예고, 가압류, 소송) | NM23: 노사협의체 회의록 | NS23: 일반건강검진 결과표 | NY23: 민원처리비/기술용역비 집행 현황 | OE23: 준공시예정원가 검토서 (개인PC) | OQ23: 설계변경 검토서 및 내역서 | OW23: 단가승인 자료 (전자결재/품의서) | PC23: 변경실행 결쟄문서 (전자결재/품의서) | PI23: 입찰(견적)대비내역서 | PO23: 저가심의(실행초과)검토 (품의서/결재문서) | PU23: (변경)예산대비내역서 | QA23: (정산)예산대비내역서 | QG23: 기투입 자재 처리 방안 | QS23: Back Charge | SC23: 합의서(공증) | SI23: 측량보고서 | SO23: 준공계 | SU23: 준공인원 운영계획 | TA23: 공정 L/L | TG23: 사업 준공 보고 (황경영향평가 등) | TY23: 주요자재수불부 | UK23: 시험장비, 안전시설물, 통신설비 등 철수 및 정산
K25: 업체선정의뢰 품의 (전자결재/품의서) | AC25: 공정 단축(안) 수립 | AU25: 공동도급 신탁계약서 | BG25: 인사발령 | CK25: Risk 대응에 대한 지침서 | DU25: 용역 하도승인의뢰서 (전자결재/구매시스템) | EA25: 지장물 이설 협의 결과 공문 | EM25: KOM 결과보고서 (개인PC) | FW25: 하도급 발주설명회 | GO25: 송장 관리 file철 | HA25: 지정폐기물 신고서 | IK25: 기성공사 실적증명서 | IW25: 현안사항 및 보고자료 | JU25: 시공실적 DATA | KA25: 각종시험 성적서 | KG25: 품질시험 총괄표 | KM25: 계측결과 보고서 | LK25: 공장점검 결과보고 (전자결재/대외공문) | LQ25: 회계전표 전자결재 승인 | MC25: 환경교육일지 | NG25: 채권신탁계약서 | NM25: 위험성평가 회의록 | NS25: 유소견자 관리대장 | OE25: 관리내역서 (개인PC) | OQ25: 발주처 승인 공문 | OW25: 관리내역서 (단가승인 반영본) | PC25: 관리내역서 (변경실행 반영본) | PI25: 하도승인의뢰서 (전자결재/품의서) | PO25: 하도급 계약서 (계약이행보증 포함) | QS25: 협력업체 투자분석 | SC25: 산재/근재보험 처리 | SO25: 계약금액조정 청구 공문
K27: 하도승인의뢰 품의 (전자결재/품의서) | DU27: 용역 계약서 (전자결재/구매시스템) | EM27: 공장검사 결과보고서 (개인PC) | FW27: 외주KOM | GO27: 유류지급 관리대장 | HA27: 비점오염저감시설 관리대장 | IW27: 브리핑 서류 | KA27: 콘크리트 타설대장 | KG27: 공인기관의뢰시험 성적서 | KM27: 지하안정영향평가서 | NM27: 장비작업계획서 | OE27: 월간현황보고 (개인PC) | PC27: 준공시예정원가 검토서 | PI27: 하도급계약체결 통보서 (DL→발주처 공문) | PO27: 건설공사대장 KISCON | QS27: 적자공종 만회방안
AC29: 계획공정 수정(안) | DU29: 용역 보고서 (전자결재/대외공문)
B31: 본사
K32: 단가승인 | Q32: 예산 승인 | AC32: 공정KOM | AU32: 공동도급 신탁계약 | BA32: 본실행예산 편성 | BG32: 현장인원 배치 | BM32: 외주KOM | BY32: 차량신청 품의서 | CE32: 현지구입 신청서 | CW32: 단가승인 | DI32: Baseline 승인 | DO32: 착공식 집행승인 | DU32: 측량용역 집행승인 | EM32: 품질KOM | FQ32: 본실행예산 결정 | IK32: 기술도서 사전검토 | IQ32: 월마감시 CF 수기보정 | KA32: 품질지원 | KG32: 부실벌점 자가진단 | KM32: 시공계획발표 | OE32: 월마감 후 정기보고자료 검토 | OK32: 경영계획 모니터링 | OW32: 단가승인 검토/승인 | PC32: 변경실행예산 검토/승인 | PI32: 외주/자재 KOM | PO32: 수의업체선정 승인 | RW32: 상황실 개설 | SC32: 민/형사적 합의 지원 | SO32: 계약금액조정 청구 검토 | TY32: 준공전 사전점검
K33: [토목견적팀] ▧ 가설사무실 축조 혹은 사무실 임대에 대한 단가승인 (본실행 편성 전) | Q33: [토목수행팀] ▧ 실시설계 및 현장운영비에 대한 예산 승인 ㆍ입안 : 현장준비팀, T/F팀, PM ㆍ검토 : 수행파트장, 수행팀장 ㆍ결정 : 담당임원 ㆍ팀장협의 : 견적팀장, 사업지원팀장, 기획팀장, 스마트엔지니어링팀장, 회계팀장 ㆍ임원협의 : 기획담당임원, 회계담당임원 | AC33: [토목수행팀] ▧시기 : 최초 도급계약 후 1개월 이내 ▧목적 : 구간별 착수시점 / 공정 R&O 확인, 최초공정계획 수립 일정 공유 ▧결과 : 공정 KOM 회의록 | AU33: [토목견적팀] ▧시기 : 최초 도급계약 후 1개월 이내 ▧목적 : 공동도급 신탁계약 체결을 통한 안분미수 최소화 ▧결과 : 공동도급 신탁계약서 | BA33: [토목견적팀] ▧시기 : 본실행작성일로부터 1개월 내 ▧목적 : 본실행 셋팅 ▧결과 : 본실행예산서 | BG33: [토목수행팀] ▧시기 : 최초 도급계약체결시 ▧목적 : 현장 셋팅을 위한 최소인원 투입 ▧결과 : 현장 최소인원 투입 (현장소장, 공무 등) | BM33: [토목수행팀] ▧시기 : 외주발주계획 수립일로부터 1개월 이내 ▧목적 : 외주발주계획 수립 ▧결과 : 하도급 발주계획(서) | BY33: [토목수행팀] ▧시기 : 품의서 상신일로부터 1개월 이내 ▧목적 : 차량신청 품의 승인 ▧결과 : 현장차량 집행승인 결재서 | CE33: [건설자재관리팀] ▧시기 : 현지구입신청서 작성일로부터 1개월 이내 ▧목적 : 현지구입 자재 집행 ▧결과 : 현지구입 자재 신청서 | CW33: [토목견적팀] ▧ 현장준비팀 운영 및 우선시공분에 대한 단가승인 (본실행 편성 전) | DI33: [토목수행팀] ▧ Baseline 승인 ㆍ입안 : 현장소장, 공정PM ㆍ검토 : 수행파트장, 수행팀장 ㆍ결정 : 담당임원 | DO33: [토목수행팀] ▧시기 : 필요시 ▧목적 : 현장여건에 따른 착공식 시행 검토 및 품의 승인 ▧결과 : 착공식 집행승인 (전자결재/품의서) | DU33: [토목수행팀] ▧시기 : 필요시 ▧목적 : 현장여건에 따른 측량계획 검토 및 품의 승인 ▧결과 : 측량용역 집행승인 (전자결재/품의서) | EM33: [토목품질팀] ▧ 시기 : 실착공전 ▧ 목적 : 현장개설 후 본공사 착수 전, 품질 마인드셋,품질관리계획서 적정성 검토 지원 본부 내 시행 중 품질개선 활동, 품질관련 시스템 등 교육 ▧ 결과 : 품질KOM 결과보고서 | IK33: [토목계약관리팀] ▧시기 : 설계변경 및 계약변경 전 ▧목적 : 환경 방침 등 계약변경시 법적 위배항목 적절성 검토 ▧결과 : 기술도서 사전검토 사내공문 | IQ33: [토목수행팀] ▧시기 : 월마감 이후 ▧목적 : 시스템상 미반영된 데이터 수기보정을 통한 정확한 CF관리 ▧결과 : CF계획 오류로 인한 손실을 방지 | KA33: [토목품질팀] ▧ 시기 : 분기별 1회(현장마다) ▧ 목적 : 현장의 하자 및 벌점 Risk 제거, 품질지침 이행 여부 확인, Q-BP 설계변경 ITEM 도출 ▧ 결과 : 품질점검보고서, 지적사항 조치보고서 | KG33: [토목품질팀] ▧ 시기 : 매월 ▧ 목적 : 현장의 부실벌점 자가진단 이행 관리, NG 분석하여 재발방지대책 실효성 검증 ▧ 결과 : 부실벌점 자가진단 집계표, 부실벌점 NG 대시보드 | KM33: [토목품질팀] ▧ 시공계획발표회 참관 예상하자 저감을 위한 현장지원 | OE33: [토목수행팀] ▧ 준공시예정원가 검토 ▧ 관리내역서 검토 (분기별 1회) ▧ 원가율 변동 확인 ▧ 경영실적모니터링 자료 취합 ▧ 재무 Indicator 검토 ▧ 사업수지/자금수지 실적 확인 | OK33: [토목수행팀] ▧ 사업수지/자금수지 검토 및 확인 | OW33: [토목견적팀] | PC33: [토목견적팀] | PI33: [토목수행팀]. [외주관리팀] | PO33: [토목수행팀] | RW33: 안전보건경영실 ▧주관 : 안전기획팀장(CSO) ▧목적 : 외부 대응체계구축 ▧방법 : 상활실 개설 유관부서 지원요청 ▧결과 : 법적 Risk 및 언론 대응체계 구축 | SC33: ▧주관 : 본부 안전팀 ▧지원 : 법무지원팀 ▧목적 : 금전적 손실 최소화 ▧방법 : 협력사와 손해배상금 분배비율 등 의사결정 법률검토 ▧결과 : 중처법 대응 언론 Risk 감소 | SO33: ▧주관 : 본부 계약관리팀 ▧지원 : 법무지원팀(필요시) ▧목적 : 금전적 손실 최소화 ▧방법 : 계약금액 조정 관련 후속조치 사항에 대해 준공대가 수령 전 청구 공문 발송 ▧결과 : 계약금액 조정 청구 공문 | TY33: [토목품질팀] ▧ 시기 : 준공전 90일 ▧ 목적 : 모든 하자를 준공전에 누락없이 조치(2회 시행) ▧ 결과 : 준공전 사전점검 보고서, 지적사항 조치보고서
CW38: 집행 승인 | DU38: 연도변조사 집행승인 | KA38: 품질교육 | KG38: 현장평가/공지 | PC38: 변경실행예산 검토/승인 | PI38: 하도급 발주설명회 | PO38: 업체선정의뢰 검토승인 | TY38: 하자보증서 발행검토
CW39: [토목수행팀] ▧ 우선시공분 집행 승인 ㆍ입안 : 현장준비팀, T/F팀, PM ㆍ검토 : 수행파트장, 수행팀장 ㆍ결정 : 담당임원 ㆍ팀장협의 : 견적팀장, 사업지원팀장, 기획팀장, 스마트엔지니어링팀장, 회계팀장 ㆍ임원협의 : 기획담당임원, 회계담당임원 | DU39: [토목수행팀] ▧시기 : 필요시 ▧목적 : 현장여건에 따른 연도변조사계획 검토 및 품의 승인 ▧결과 : 연도변조사 집행승인 (전자결재/품의서) | KA39: [토목품질팀] ▧ 시기 : 반기 1회 ▧ 목적 : 품질팀장, 공사팀장을 대상으로 품질 Risk 수평전개를 통한 하자예방으로 부실벌점 Zero 달성 및 하자보수비 절감 ▧ 결과 : 교육교재, 교육설문지 | KG39: [토목품질팀] ▧ 시기 : 1, 4, 7, 10월 ▧ 목적 : 현장 수준 평가를 공지하여 현장이 인지하도록 하여 더 잘할 수 있게 동기부여 ▧ 결과 : 현장평가 결과/공지 문서 | OE39: 준공시예정원가변동보고서 접수 | PC39: [토목사업관리팀] | PI39: [토목수행팀]. [외주관리팀] | PO39: [토목수행팀]. [외주관리팀] | TY39: [토목품질팀] ▧ 시기 : 도급 하자보증서 발급전 15일 이내 ▧ 목적 : 법적보증기간 준수 여부확인(발주처 대응) ▧ 결과 : 하자보증기간 산정 내역, 하자보증서
OE40: [회계팀] ▧ 원가율 변동 보고 공유
KA44: 시공계획 발표회 | KG44: Q-BP 수평전개 | PC44: 준공시예정원가 검토 | PI44: 저가심의/실행초과심의 검토 | PO44: 하도승인/최초계약
KA45: [토목품질팀] ▧ 시기 : 공종 착수 30일 전 ▧ 목적 : 현장과 본사 전문가가 함께 시공계획을 검토하여 하자 Risk 제거 ▧ 결과 : 시공계획 검토서, 회의록 | KG45: [토목품질팀] ▧ 시기 : 매월 ▧ 목적 : 깊이 고민한 하자의 근본 원인과 재발방지대책이 잘 작동하는 사례 발굴 ▧ 결과 : 우수 Q-BP 등재 | OE45: 경상비 재승인 | PC45: [토목수행팀] | PI45: [토목수행팀] | PO45: [토목수행팀]. [외주관리팀]
OE46: [토목수행팀] ▧시기 : 예산대비120% 초과 예정시 ▧목적 : 공사기간 및 경상비 월투입에 대한 검토 및 재승인 ▧결과 : 현장 경상비 (변경) 집행계획 승인
B54: 현장 | H54: 공무
K55: 가설사무실 축조 집행승인 | Q55: 선급공사비 예산편성 | W55: 착공신고서 | AU55: 공동도급 운영회의 (필요시) | BA55: 본실행 작성 협의 | BG55: 직원운영계획 수립 | BM55: 하도급 발주계획 수립 | BS55: 발주처 업무처리 절차 작성 | BY55: 차량신청 집행승인 및 결재 | CK55: 경상비 투자분석 양식 확정 | CQ55: 가설사무실 축조 | CW55: 선급공사비 예산편성 | DO55: 착공식 행사 준비 | DU55: 착수전 측량 업체 선정 | EY55: 설계도서 검토 용역 업체 선정 | FE55: 보험가입 내역 검토 | FK55: 공동도급 원가약정 체결 | FQ55: 본실행 작성 협의 | FW55: 하도급 발주계획 | GO55: 자재 소요계획서 작성 | HG55: 관리내역서 작성 | HS55: 착공보고회 자료 작성 | HY55: 인수인계서 | IK55: 건설공사관리대장(키스콘) 업데이트 | IQ55: 도급기성/선급금 수금계획 작성 | JC55: 유관 부서 담당 업무 및 담당자 조사 | JI55: 감사 대비 자료 준비 | KM55: 업체선정 | LE55: 정보보호 교육 및 훈련 | LQ55: 월마감 | MI55: 선급금 신청 | MO55: 발급적정성에 대한 본사 협의 | MU55: 직영공사 준비 | NG55: 원가약정 협의 | NM55: 산업안전보건관리비 집행관리 | NY55: 언론취재(보도) | OE55: 월마감 | OK55: 경영목표 달성회의 | OQ55: 물가변동 | OW55: 신규 실행단가 산출근거 작성 | PC55: 기승인 단가승인 자료 취합 | PI55: 하도급 대상 공종 및 물량 산정 | PO55: 실행대비 초과사유 검토 및 본사 협의 | PU55: 공종별 변경 수량산출서 작성 | QA55: 간접비 사용내역 정산 | QG55: 노임/장비비/자재비/기타비용 등 체불현황 파악 | QM55: 계약 외 공사로 인한 미지급금 산정 | QS55: (기성지급)월별 간접비 사용금액 취합 | QY55: 컨틴젼시 | RE55: 공사손해보험 접수 | RK55: 공사손해보험 사전공사 집행승인 | RQ55: 분쟁 사안에 대한 현장 계약조건 및 승소 가능성 분석 | SI55: (선정)예산대비내역서 작성 | SO55: 준공 설계도서 제출 | SU55: Cash Flow 관리 | TG55: 가설사무실 원상복구 | TS55: 하도급관리 항목 작성 | UE55: 프로젝트문서 제출확인서 수령 | UK55: 현장 철수 직원 인사발령 의뢰 | VC55: 도급관련 준공 전망 작성 | VI55: 간접비 최종 정산 금액 작성 | VU55: 하도급 현황/연락처 제출 | WG55: 준공현장 L&L 작성
