Workbook

Sheet 대시보드
B2: 동탄트램 집행단계 실무 매뉴얼 & 지식 DB 작성 현황 대시보드
B4: ❚ [집행단계 v6] 8대 공종(토목·궤도·건축·신호·통신·전기) 263개 작업단위별 작성 및 DB 연동 현황
B6: 전체 액티비티 | D6: 표준서 작성 | F6: 수행지침 작성 | H6: 체크리스트 작성 | J6: 상세절차서(HTML) 연동 | L6: 현장 리스크 DB
B7: =E21&" 개" | D7: =F21&" 개 (100%)" | F7: =G21&" 개 (100%)" | H7: =H21&" 개 (100%)" | J7: =I21&" 개 (100%)" | L7: =J21&" 개 (87.8%)"
B10: ❚ 1. 공종별 매뉴얼 및 리스크 DB 작성 현황
B12: 순번 | C12: 구분 | D12: 대공종 | E12: 작업수 (L4) | F12: 표준서 | G12: 수행지침 | H12: 체크리스트 | I12: HTML 연동 | J12: 리스크 DB | K12: 달성률 | L12: 진행 상태
B13: 1 | C13: 토목공사 | D13: 사전토공사 | E13: =COUNTA('사전토공사'!F2:F31) | F13: =COUNTA('사전토공사'!K2:K31) | G13: =COUNTA('사전토공사'!M2:M31) | H13: =COUNTA('사전토공사'!O2:O31) | I13: =COUNTA('사전토공사'!F2:F31) | J13: =COUNTA('사전토공사'!S2:S31) | K13: =IF(E13>0, F13/E13, 1) | L13: 작성 완료
B14: 2 | C14: 토목공사 | D14: 지장물이설 | E14: =COUNTA('지장물이설'!F2:F39) | F14: =COUNTA('지장물이설'!K2:K39) | G14: =COUNTA('지장물이설'!M2:M39) | H14: =COUNTA('지장물이설'!O2:O39) | I14: =COUNTA('지장물이설'!F2:F39) | J14: =COUNTA('지장물이설'!S2:S39) | K14: =IF(E14>0, F14/E14, 1) | L14: 작성 완료
B15: 3 | C15: 토목공사 | D15: 상부강화노반 | E15: =COUNTA('상부강화노반'!F2:F37) | F15: =COUNTA('상부강화노반'!K2:K37) | G15: =COUNTA('상부강화노반'!M2:M37) | H15: =COUNTA('상부강화노반'!O2:O37) | I15: =COUNTA('상부강화노반'!F2:F37) | J15: =COUNTA('상부강화노반'!S2:S37) | K15: =IF(E15>0, F15/E15, 1) | L15: 작성 완료
B16: 4 | C16: 궤도공사 | D16: 콘크리트도상 | E16: =COUNTA('콘크리트도상'!F2:F24) | F16: =COUNTA('콘크리트도상'!K2:K24) | G16: =COUNTA('콘크리트도상'!M2:M24) | H16: =COUNTA('콘크리트도상'!O2:O24) | I16: =COUNTA('콘크리트도상'!F2:F24) | J16: =COUNTA('콘크리트도상'!S2:S24) | K16: =IF(E16>0, F16/E16, 1) | L16: 작성 완료
B17: 5 | C17: 건축공사 | D17: 건축 | E17: =COUNTA('건축'!E2:E51) | F17: =COUNTA('건축'!J2:J51) | G17: =COUNTA('건축'!L2:L51) | H17: =COUNTA('건축'!N2:N51) | I17: =COUNTA('건축'!E2:E51) | J17: =COUNTA('건축'!R2:R51) | K17: =IF(E17>0, F17/E17, 1) | L17: 작성 완료
B18: 6 | C18: 시스템공사 | D18: 신호 | E18: =COUNTA('신호'!E2:E23) | F18: =COUNTA('신호'!J2:J23) | G18: =COUNTA('신호'!L2:L23) | H18: =COUNTA('신호'!N2:N23) | I18: =COUNTA('신호'!E2:E23) | J18: =COUNTA('신호'!R2:R23) | K18: =IF(E18>0, F18/E18, 1) | L18: 작성 완료
B19: 7 | C19: 시스템공사 | D19: 통신 | E19: =COUNTA('통신'!E2:E33) | F19: =COUNTA('통신'!J2:J33) | G19: =COUNTA('통신'!L2:L33) | H19: =COUNTA('통신'!N2:N33) | I19: =COUNTA('통신'!E2:E33) | J19: =COUNTA('통신'!R2:R33) | K19: =IF(E19>0, F19/E19, 1) | L19: 작성 완료
B20: 8 | C20: 시스템공사 | D20: 전기 | E20: =COUNTA('전기'!E2:E33) | F20: =COUNTA('전기'!J2:J33) | G20: =COUNTA('전기'!L2:L33) | H20: =COUNTA('전기'!N2:N33) | I20: =COUNTA('전기'!E2:E33) | J20: =COUNTA('전기'!R2:R33) | K20: =IF(E20>0, F20/E20, 1) | L20: 매뉴얼 완료 (리스크 작성중)
B21: - | C21: 합계 | D21: 8대 공종 통합 | E21: =SUM(E13:E20) | F21: =SUM(F13:F20) | G21: =SUM(G13:G20) | H21: =SUM(H13:H20) | I21: =SUM(I13:I20) | J21: =SUM(J13:J20) | K21: =AVERAGE(K13:K20) | L21: 전 공종 완료
B23: ❚ 2. 동적 매뉴얼 주요 기능 구현 현황
B25: 주요 기능 | D25: 핵심 내용 및 구현 현황 | L25: 적용 상태
B26: 시공 사진·영상 시각화 | D26: 공종별 현장 시공 사진, 3D BIM 모델 및 품질 시험 동영상 1:1 매핑 완료 (263개 전 작업) | L26: 구현 완료
B27: 전문시방서(KCS) 원문 연동 | D27: 국토교통부 KCS 전문시방서 PDF(1페이지 원문) 및 관련 법령 링크 바로 열기 구현 | L27: 구현 완료
B28: 문장별 상세절차서(HTML) 연동 | D28: 체크리스트 각 항목 클릭 시 해당 작업의 1:1 독자 상세절차서(HTML) 즉시 연동 | L28: 구현 완료
B29: 단일 화면 패키지 구성 | D29: 1개 작업 단위에 표준서, 수행지침, 체크리스트, 상세절차서를 한 화면에 통합 제공 | L29: 구현 완료
B30: 현장 시공 데이터 누적 관리 | D30: 동탄 현장에서 발생하는 시험 성적서, 사진 데이터(v6)를 실시간 누적·업데이트 | L30: 구현 완료
B32: ❚ 3. 주요 보고 및 향후 추진 계획
B34: 구분 | C34: 보고 안건 | E34: 주요 내용 | L34: 진행 상황
B35: 안건 1 | C35: 동탄 현장 기반 매뉴얼 연속 업데이트 승인 | E35: 동탄 현장 실무 데이터를 바탕으로 매뉴얼(v6 ➔ v7)을 지속 보완·운영하는 체계 승인 | L35: 승인 완료
B36: 안건 2 | C36: 사내 매뉴얼 시스템 통합 및 자산화 | E36: 완성된 매뉴얼을 사내 표준 시스템에 탑재하여 향후 신규 트램 사업 수주 시 재활용 | L36: 추진 중

Sheet 공정매뉴얼
A1: 동탄도시철도(트램) 1·2공구 WBS 계층 구조별 표준서·수행지침·체크리스트 상세 매핑표
A3: L2 코드 | B3: L3 코드 | C3: L3 대공종명 | D3: L4 코드 | E3: 작업단위 (Level 4 Task/Activity) | F3: 표준서 (Standard) [정량적 절대 기술 기준] | G3: 수행지침 (Guideline) [작업 절차 및 주의사항] | H3: 체크리스트 (Checklist) [완료 검측 표준] | I3: 담당 분야 | J3: 첨부서류 연계 상세 설계기준 (구조, 토질, 선로 등) | K3: 집행단계 리스크 체크리스트 (260614 트램 표준) | L3: 협력사 시공/공사관리 자문 (정주건설 / 트리폴건설)
A4: 1000 행정·인허가 (Project Management & Permitting)
A5: 1000 | B5: 1000-1 | C5: 행정·인허가 준비 및 관계기관 협의 | D5: 1000-1-1 | E5: 인허가 관련 법령 검토 및 체크리스트 작성 | F5: ● 도시철도법 제17조(사업계획승인) 및 국토교통부 도시철도 건설 규칙 수립 요건 준수 | G5: [작업 절차] 1. 사전 준비 단계: - 설계 도서 및 시방 기준을 분석하여 인허가 관련 법령 검토 및 체크리스트 작성 작업을 위한 현장 실측 및 경계 측량을 수행함. 2. 본 시공 단계: - 최신 법제처 정보 기반 관련 법령 테이블 작성 작업을 표준 시공 절차에 준하여 시행하며, 실시간 수평도 및 치수 공차를 관리함. 3. 검사 및 마감 단계: - 인허가 서류 구비 요건 만족 확인 체크리스트 사전 작성 시험 및 품질 검사를 실측하고 기준값 만족 여부를 기록함. 부서 간 조율을 통한 법적 의무 이행 조치 사항 기록 작업을 거쳐 노면 정리 및 안전 조치를 완료함. [주의사항 (하자이력 연계)] 최신 개정 법령 미반영으로 인허가 승인 보완 지시 및 사업 기간 지연 | H5: □ 법제처 최신 개정 법령 반영 확인 □ 서류 요건(설계도서, 사업계획서 등) 검토 완료 □ 인허가 체크리스트 작성 완료 및 승인 [집행단계 리스크 체크사항 (LLBS 연계)] □ 용지 보상 내역에 분묘 이장비(유연/무연)가 별도로 책정되어 있는가? □ 용지 보상 지연 시 굴착 작업구(갱구) 진입이 가능한 대체 루트가 있는가? □ 부지 내 기존 도로가 보상 문제로 폐쇄될 경우 대체 진입로 계획이 있는가? □ 개발제한구역, 상수원보호구역 등 특수 규제 지역 포함 여부 및 예상 인허가 소요 기간이 공정표(CP)에 반영되었는가? | I5: 행정 | J5: ● 관련분야 설계기준서 준수 | K5: ● 최신 개정 법령 미반영으로 인허가 승인 보완 지시 및 사업 기간 지연 리스크를 검토하였는가? | L5: ● 협력사 자문 내용 없음 또는 해당사항 없음
A6: 1000 | B6: 1000-1 | C6: 행정·인허가 준비 및 관계기관 협의 | D6: 1000-1-2 | E6: 관계기관 협의자료 작성 및 공식 공문 발송 | F6: ● 행정 효율 지침 및 지자체별 인허가 협의 공문 규격 표준 규정 | G6: [작업 절차] 1. 사전 준비 단계: - 설계 도서 및 시방 기준을 분석하여 관계기관 협의자료 작성 및 공식 공문 발송 작업을 위한 현장 실측 및 경계 측량을 수행함. 2. 본 시공 단계: - 표준 공문 양식 및 도서 작성 요령 준수 작업을 표준 시공 절차에 준하여 시행하며, 실시간 수평도 및 치수 공차를 관리함. 3. 검사 및 마감 단계: - 기지 및 선로 주변 민원 발생 우려 지역의 관계기관 검토서 첨부 시험 및 품질 검사를 실측하고 기준값 만족 여부를 기록함. 관련 공문 접수번호 대장 등록 및 추적 작업을 거쳐 노면 정리 및 안전 조치를 완료함. [주의사항 (하자이력 연계)] 비공식 협의 및 누락 자료 제출로 인한 공문 반려 및 재작성 소요(2주 지연) | H6: □ 구비 서류(설계도서, 영향평가서 등) 누락 확인 □ 공식 협의 공문 대장 등록 및 발송 확인 □ 접수증 발급 및 발급 일자 기록 완료 [집행단계 리스크 체크사항 (LLBS 연계)] □ 사업 부지 내 잔존하는 영업 시설(공장, 종교시설)의 현황과 예상 보상비가 사업비에 책정되었는가? □ 용지 보상 현황도(Map)와 공정표(Schedule)를 연동하여 지연 일수를 산정하고 있는가? □ 용지 보상 지연 시 굴착 작업구(갱구) 진입이 가능한 대체 루트가 있는가? □ 개발제한구역, 상수원보호구역 등 특수 규제 지역 포함 여부 및 예상 인허가 소요 기간이 공정표(CP)에 반영되었는가? | I6: 행정 | J6: ● 관련분야 설계기준서 준수 | K6: ● 공식 접수 및 대장 기록 누락 자료 제출로 인한 공문 반려 및 재작성 소요(2주 지연) 리스크를 검토하였는가? | L6: ● 협력사 자문 내용 없음 또는 해당사항 없음
A7: 1000 | B7: 1000-1 | C7: 행정·인허가 준비 및 관계기관 협의 | D7: 1000-1-3 | E7: 관계기관 피드백 분석 및 조치 방안 수립 | F7: ● 민원 처리 및 행정절차법상 의견 제출 및 피드백 공식 조치 절차 | G7: [작업 절차] 1. 사전 준비 단계: - 설계 도서 및 시방 기준을 분석하여 관계기관 피드백 분석 및 조치 방안 수립 작업을 위한 현장 실측 및 경계 측량을 수행함. 2. 본 시공 단계: - 회신 공문 보완 지시사항 분석 및 조치 부서 지정 작업을 표준 시공 절차에 준하여 시행하며, 실시간 수평도 및 치수 공차를 관리함. 3. 검사 및 마감 단계: - 보완 설계 도면 및 설명자료 작성 지침 배포 시험 및 품질 검사를 실측하고 기준값 만족 여부를 기록함. 관계기관 담당자 사전 면담을 통한 대안 타당성 조율 작업을 거쳐 노면 정리 및 안전 조치를 완료함. [주의사항 (하자이력 연계)] 관계기관 보완 요건의 자의적 해석에 따른 부실 보완 및 2차 보완 지시 지연 | H7: □ 피드백 지시사항 카테고리별 분류 및 대책 수립 □ 조치결과 보고서 작성 및 증빙 자료 확보 □ 관계기관 재검토 승인 결과 확보 완료 [집행단계 리스크 체크사항 (LLBS 연계)] □ 사업 부지 내 잔존하는 영업 시설(공장, 종교시설)의 현황과 예상 보상비가 사업비에 책정되었는가? □ 부지 내 기존 도로가 보상 문제로 폐쇄될 경우 대체 진입로 계획이 있는가? □ 용지 보상 지연 시 굴착 작업구(갱구) 진입이 가능한 대체 루트가 있는가? □ B/P장, 크러셔장 등 주요 가설 설비 설치 위치에 대한 인허가(비산먼지, 소음, 점용) 가능성을 사전 확인했는가? | I7: 행정 | J7: ● 관련분야 설계기준서 준수 | K7: ● 관계기관 보완 요건의 자의적 해석에 따른 부실 보완 및 2차 보완 지시 지연 리스크를 검토하였는가? | L7: ● 협력사 자문 내용 없음 또는 해당사항 없음
A8: 1000 | B8: 1000-2 | C8: 기본설계 도면검토 및 착공신고 처리 | D8: 1000-2-1 | E8: 기본설계도서 기술검토 및 검토의견서 작성 | F8: ● 건설공사 사업관리방식 검토기준 및 업무수행지침 제81조(설계도서 등의 검토) | G8: [작업 절차] 1. 사전 준비 단계: - 설계 도서 및 시방 기준을 분석하여 기본설계도서 기술검토 및 검토의견서 작성 작업을 위한 현장 실측 및 경계 측량을 수행함. 2. 본 시공 단계: - 평면/종단 선형 설계도서 정밀 판독 작업을 표준 시공 절차에 준하여 시행하며, 실시간 수평도 및 치수 공차를 관리함. 3. 검사 및 마감 단계: - 트램 최대 구배(최대 60‰) 및 최소 곡선반경(본선 R25m 이상) 적합성 확인 시험 및 품질 검사를 실측하고 기준값 만족 여부를 기록함. 설계사 검토의견서 공식 송부 및 회신 요청 작업을 거쳐 노면 정리 및 안전 조치를 완료함. [주의사항 (하자이력 연계)] 종평면 종단 구배 한계값 미충족 도면을 거르지 못하여 궤도 재설계 발생 | H8: □ 트램 기술기준 만족 여부(곡선반경, 구배 등) 확인 □ 종단면 설계 요철 한계값 검토 완료 □ 설계자 피드백 반영 완료 확인 [집행단계 리스크 체크사항 (LLBS 연계)] □ 사업 부지 내 잔존하는 영업 시설(공장, 종교시설)의 현황과 예상 보상비가 사업비에 책정되었는가? □ 연약지반 구간의 보상 지연 시 이를 만회할 공법(PC, 프리로딩 생략 등)이 있는가? □ 유용토를 성토할 구간의 보상 완료 시점이 굴착 시점과 일치하는가? □ 개발제한구역, 상수원보호구역 등 특수 규제 지역 포함 여부 및 예상 인허가 소요 기간이 공정표(CP)에 반영되었는가? | I8: 행정 | J8: ● [선로설계] 본선 최소곡선반경 25m, 정거장 300m 이상 적용 ● [선로설계] 완화곡선 최소길이 L=0.5xV (부득이한 경우 대차 중심간 거리 11.4m 이상) ● [선로설계] 최대구배: 본선 60‰ 이하, 정거장 밖 60‰ 이하 (정거장 내 3/1,000 이하, 차량 미유치 측선 45/1,000 이하) ● [선로설계] 종곡선 반경: 본선 800m 이상 (부득이한 경우 350m) ● [선로설계] 선로중심간격: 본선 3.5m 이상 (차량 한계 2.7m x 3.6m, 건축 한계 3.1m x 3.8m) | K8: ● 종평면 종단 구배 한계값 미충족 도면을 거르지 못하여 궤도 재설계 발생 리스크를 검토하였는가? | L8: ● 협력사 자문 내용 없음 또는 해당사항 없음
A9: 1000 | B9: 1000-2 | C9: 기본설계 도면검토 및 착공신고 처리 | D9: 1000-2-2 | E9: 착공신고 구비서류 적정성 검토 및 조립 | F9: ● 건설기술진흥법 시행규칙 제38조(착공신고 구비서류) 규격 만족 여부 | G9: [작업 절차] 1. 사전 준비 단계: - 설계 도서 및 시방 기준을 분석하여 착공신고 구비서류 적정성 검토 및 조립 작업을 위한 현장 실측 및 경계 측량을 수행함. 2. 본 시공 단계: - 현장대리인, 안전관리자, 보건관리자 선임서 및 자격증 확인 작업을 표준 시공 절차에 준하여 시행하며, 실시간 수평도 및 치수 공차를 관리함. 3. 검사 및 마감 단계: - 착공 전 안전관리계획서, 유해위험방지계획서 첨부 여부 검토 시험 및 품질 검사를 실측하고 기준값 만족 여부를 기록함. 공사수행계획서 및 세부 예정공정표 조립 작업을 거쳐 노면 정리 및 안전 조치를 완료함. [주의사항 (하자이력 연계)] 현장대리인 경력 누락 또는 안전관리자 자격 위반 서류 제출로 인한 착공계 반려 | H9: □ 핵심 기술자 면허 및 경력증명 확인 □ 착공 전 필수 승인 서류(안전계획 등) 첨부 완료 □ 발주처 착공신고서 조립 완료 및 접수 [집행단계 리스크 체크사항 (LLBS 연계)] □ 용지 보상 내역에 분묘 이장비(유연/무연)가 별도로 책정되어 있는가? □ 연약지반 구간의 보상 지연 시 이를 만회할 공법(PC, 프리로딩 생략 등)이 있는가? □ 유용토를 성토할 구간의 보상 완료 시점이 굴착 시점과 일치하는가? □ 크러셔장 운영에 따른 소음/진동 시뮬레이션을 수행하고 인허가 리스크를 검토했는가? | I9: 행정 | J9: ● 관련분야 설계기준서 준수 | K9: ● 선로 기하학 오차(종단구배 급변부 캔트 미반영 등)로 궤도 시공 불가 및 기본계획 변경 리스크를 검토하였는가? | L9: ● 협력사 자문 내용 없음 또는 해당사항 없음
A10: 1000 | B10: 1000-3 | C10: 타공사(SRT, GTX-A 등) 구간 협의 및 간섭 검토 | D10: 1000-3-1 | E10: 타공사 간섭구간 기술 영향 평가 및 도면 검토 | F10: ● 지하안전관리에 관한 특별법(지하안전평가 기준 및 인접 굴착 영향선 검토) | G10: [작업 절차] 1. 사전 준비 단계: - 설계 도서 및 시방 기준을 분석하여 타공사 간섭구간 기술 영향 평가 및 도면 검토 작업을 위한 현장 실측 및 경계 측량을 수행함. 2. 본 시공 단계: - SRT/GTX-A 교차 구간 상세 구조물 도면 입수 작업을 표준 시공 절차에 준하여 시행하며, 실시간 수평도 및 치수 공차를 관리함. 3. 검사 및 마감 단계: - 이격거리 및 응력 간섭 3D 시뮬레이션 결과 검토 시험 및 품질 검사를 실측하고 기준값 만족 여부를 기록함. 간섭 구조물 차수 및 방호 대책 설계 도면 확인 작업을 거쳐 노면 정리 및 안전 조치를 완료함. [주의사항 (하자이력 연계)] GTX-A 굴착 공사 영향으로 트램 교차로 노반 침하 및 가시설 이상 거동 발생 | H10: □ 상호 이격거리 구조 안전성 계산서 검토 완료 □ 계측기 설치 계획서 간섭 구간 반영 확인 □ 간섭 최소화 구조 형식 반영 확인 [집행단계 리스크 체크사항 (LLBS 연계)] □ 연약지반 구간의 보상 지연 시 이를 만회할 공법(PC, 프리로딩 생략 등)이 있는가? □ 부지 내 기존 도로가 보상 문제로 폐쇄될 경우 대체 진입로 계획이 있는가? □ 개발제한구역, 상수원보호구역 등 특수 규제 지역 포함 여부 및 예상 인허가 소요 기간이 공정표(CP)에 반영되었는가? □ 철도/지하철 인접 공사 시 유관기관 협의비 및 안전성 검토 용역비가 책정되어 있는가? | I10: 행정 | J10: ● 관련분야 설계기준서 준수 | K10: ● 해당 공종 리스크 분석 수립 준수 | L10: ● 협력사 자문 내용 없음 또는 해당사항 없음
A11: 1000 | B11: 1000-3 | C11: 타공사(SRT, GTX-A 등) 구간 협의 및 간섭 검토 | D11: 1000-3-2 | E11: 간섭구간 공동 협의회 개최 및 협의록 작성 | F11: ● 발주처 인접 공사 안전 관리 가이드라인 및 공구 간 인터페이스 조정 표준 | G11: [작업 절차] 1. 사전 준비 단계: - 설계 도서 및 시방 기준을 분석하여 간섭구간 공동 협의회 개최 및 협의록 작성 작업을 위한 현장 실측 및 경계 측량을 수행함. 2. 본 시공 단계: - 주기적 협의체 구성 및 굴착 공정 스케줄 교환 작업을 표준 시공 절차에 준하여 시행하며, 실시간 수평도 및 치수 공차를 관리함. 3. 검사 및 마감 단계: - 비상시 자동 전파 시스템 및 공구장 핫라인 개설 시험 및 품질 검사를 실측하고 기준값 만족 여부를 기록함. 상호 서명 완료된 공식 간섭 협의록 발주처 보고 작업을 거쳐 노면 정리 및 안전 조치를 완료함. [주의사항 (하자이력 연계)] 구두 협의로 시공했다가 가시설 파손 시 공구 간 책임 공방 및 공사 중단(1개월) | H11: □ 양 공구 대리인 서명된 협의록 보관 여부 □ 핫라인 구축 및 비상 대응 시나리오 마련 여부 □ 합의 사항 설계/시공 도서 반영 여부 [집행단계 리스크 체크사항 (LLBS 연계)] □ 연약지반 구간의 보상 지연 시 이를 만회할 공법(PC, 프리로딩 생략 등)이 있는가? □ 부지 내 기존 도로가 보상 문제로 폐쇄될 경우 대체 진입로 계획이 있는가? □ 개발제한구역, 상수원보호구역 등 특수 규제 지역 포함 여부 및 예상 인허가 소요 기간이 공정표(CP)에 반영되었는가? □ 철도/지하철 인접 공사 시 유관기관 협의비 및 안전성 검토 용역비가 책정되어 있는가? | I11: 행정 | J11: ● 관련분야 설계기준서 준수 | K11: ● 해당 공종 리스크 분석 수립 준수 | L11: ● 협력사 자문 내용 없음 또는 해당사항 없음
A12: 2000 임시설비 및 가설공사 (Temporary & Utility Works)
A13: 2000 | B13: 2000-1 | C13: 가설사무소 설치 및 안전·환경 관리 준비 | D13: 2000-1-1 | E13: 가설현장사무소 부지 확보 및 인허가 신고 | F13: ● 건축법 제20조(가설건축물), 지자체 가설건축물 축조 신고 지침 요건 | G13: [작업 절차] 1. 사전 준비 단계: - 설계 도서 및 시방 기준을 분석하여 가설현장사무소 부지 확보 및 인허가 신고 작업을 위한 현장 실측 및 경계 측량을 수행함. 2. 본 시공 단계: - 임차부지 소유권 확인 및 가설 물건 배치 설계도 작성 작업을 표준 시공 절차에 준하여 시행하며, 실시간 수평도 및 치수 공차를 관리함. 3. 검사 및 마감 단계: - 관할 지자체 가설건축물 축조 신고서 접수 시험 및 품질 검사를 실측하고 기준값 만족 여부를 기록함. 소방서 소방시설 사전 협의 및 신고필증 획득 작업을 거쳐 노면 정리 및 안전 조치를 완료함. [주의사항 (하자이력 연계)] 부지 미승인 상태의 무단 가설물 축조로 지자체 철거 명령 및 이행강제금 부과 | H13: □ 축조 신고필증 획득 및 현장 비치 여부 □ 경계 측량 확인 및 설계도면 일치 여부 □ 소방기구(소화기 등) 적정 수량 배치 완료 [집행단계 리스크 체크사항 (LLBS 연계)] □ 구조물과 흙막이 벽체 사이 여유폭(Working Space) 내에 배수로 설치 공간이 확보되었는가? □ 굴착 바닥면의 피압수 용출 가능성(Boiling)을 검토하고 Well Point 등 지하수위 저하 공법을 반영했는가? □ 흙막이 가시설과 본 구조물 사이에 거푸집 설치 및 작업자 이동 공간(최소 1m 이상)이 확보되었는가? □ 교량 시공용 대형 크레인(200ton 이상)의 아웃트리거 전개 폭을 고려하여 가교 폭이나 작업대(Staging)가 반영되었는가? | I13: 토목 | J13: ● 관련분야 설계기준서 준수 | K13: ● 가설건축물 설치 승인 지연으로 현장 사무소 개설 연기 및 현장 관리 공백 발생 리스크를 검토하였는가? | L13: ● 협력사 자문 내용 없음 또는 해당사항 없음
A14: 2000 | B14: 2000-2 | C14: 가설도로·가시설 및 공사 진입로 설치 | D14: 2000-2-1 | E14: 가설도로 개설 및 진입 노면 다짐 시공 | F14: ● KCS 11 20 20 (가설공사 도로 및 터파기 다짐 표준시방서) ● 가설도로 기초 지반 최소 허용 지내력 150 kN/m² 이상 확보 | G14: [작업 절차] 1. 사전 준비 단계: - 설계 도서 및 시방 기준을 분석하여 가설도로 개설 및 진입 노면 다짐 시공 작업을 위한 현장 실측 및 경계 측량을 수행함. 2. 본 시공 단계: - 진입로 롤러 다짐(두께 300mm 단위 분할 다짐) 작업을 표준 시공 절차에 준하여 시행하며, 실시간 수평도 및 치수 공차를 관리함. 3. 검사 및 마감 단계: - 평판재하시험(PBT) 실시, 지내력 150 kN/m2 확보 확인 시험 및 품질 검사를 실측하고 기준값 만족 여부를 기록함. 쇄석 골재 포설 및 표면 배수 구배(2%) 형성 작업을 거쳐 노면 정리 및 안전 조치를 완료함. [주의사항 (하자이력 연계)] 다짐 불량 가설도로 상에서 25톤 덤프트럭 전도 사고 발생 | H14: □ 평판재하시험 지내력 기준(150 kN/m2) 통과 여부 □ 노면 배수 구배 및 측구 집수정 설치 여부 □ 대형 장비 회전 반경 확보 여부 [집행단계 리스크 체크사항 (LLBS 연계)] □ 개착 구조물 기초 바닥에 지하수 배제를 위한 맹암거 및 유공관이 반영되었는가? □ 공사 중 집중호우(Frequency 10~20년 빈도)에 대비한 배수 펌프 용량과 예비 펌프가 산정되었는가? □ 항타기 등 대형 장비의 진입로 폭과 회전 반경이 현장 여건(농로, 마을길)과 부합하는가? □ 교량 시공용 대형 크레인(200ton 이상)의 아웃트리거 전개 폭을 고려하여 가교 폭이나 작업대(Staging)가 반영되었는가? | I14: 토목 | J14: ● 관련분야 설계기준서 준수 | K14: ● 가설도로 다짐 부족으로 중장비(레미콘, 크레인) 이동 시 지반 함몰 및 장비 전도 리스크를 검토하였는가? | L14: ● [공사구간 분할] 레일 뒤틀림 방지를 위해 1km 기준 분할 시공을 권장하며, 상하선별 별도 시공하되 노선 하나 기준으로 전폭 시공 적용 ● [자재적치] 협소 구간은 추가 적치 부지를 확보하지 않고, 기시공/미시공 구간에 레일을 임시 적치하여 대응
A15: 2000 | B15: 2000-3 | C15: 유틸리티/전력 가설 및 임시 배관·배선 설치 | D15: 2000-3-1 | E15: 유틸리티 임시 전력 설비 설치 및 접지 공사 | F15: ● 전기설비기술기준(산업부) 및 가설공사 표준시방서(전기) ● 가설 전력 분전반 접지 저항 100Ω 이하 정밀 시공 | G15: [작업 절차] 1. 사전 준비 단계: - 설계 도서 및 시방 기준을 분석하여 유틸리티 임시 전력 설비 설치 및 접지 공사 작업을 위한 현장 실측 및 경계 측량을 수행함. 2. 본 시공 단계: - 한전 임시 수전 신청 및 전신주 변압기 설치 입회 작업을 표준 시공 절차에 준하여 시행하며, 실시간 수평도 및 치수 공차를 관리함. 3. 검사 및 마감 단계: - 현장 분전반 접지 공사(접지 저항 100Ω 이하 측정) 시험 및 품질 검사를 실측하고 기준값 만족 여부를 기록함. 외함 차단기(ELB, 감도전류 30mA 이하) 테스트 작업을 거쳐 노면 정리 및 안전 조치를 완료함. [주의사항 (하자이력 연계)] 여름철 우천 시 가설 분전반 접지 불량으로 인한 작업자 감전 사고 발생 | H15: □ 접지저항값 측정 및 기준(100Ω 이하) 만족 여부 □ 누전차단기 정격 감도 확인 및 일일 점검 완료 □ 고압 노출선 방호 케이싱 씌우기 여부 [집행단계 리스크 체크사항 (LLBS 연계)] □ 개착 구조물 기초 바닥에 지하수 배제를 위한 맹암거 및 유공관이 반영되었는가? □ 공사 중 집중호우(Frequency 10~20년 빈도)에 대비한 배수 펌프 용량과 예비 펌프가 산정되었는가? □ 교량 시공용 대형 크레인(200ton 이상)의 아웃트리거 전개 폭을 고려하여 가교 폭이나 작업대(Staging)가 반영되었는가? □ 항타기 등 대형 장비의 진입로 폭과 회전 반경이 현장 여건(농로, 마을길)과 부합하는가? | I15: 토목/전기 | J15: ● 관련분야 설계기준서 준수 | K15: ● 가설 전기 설비 과과부하 누전으로 현장 화재 발생 및 임시 차단기 오동작 리스크를 검토하였는가? | L15: ● 협력사 자문 내용 없음 또는 해당사항 없음
A16: 2000 | B16: 2000-4 | C16: 교통전환 계획 수립 및 공사 중 교통 관리 | D16: 2000-4-1 | E16: 우회 교통 차선 도색 및 안전 통제 조치 | F16: ● KCS 44 60 05 (노면표시) / KCS 21 20 05 (현장가설시설물) ● 임시 차선 휘도: 설치시 백색 240, 황색 150 mcd/(m²·lx) 이상 (5℃ 이하 시공 금지, KS L 2521 2호 유리알 1L당 800g 살포) ● 임시 차선테이프: 건조 백색 250 / 습윤 백색 500 mcd/(m²·lx), 미끄럼저항 45 BPN 이상 ● 가설 펜스(울타리): 높이 1.8m 이상 (민감 지역 주거·상가 50m 이내 3.0m 이상), 지주 간격 1.8m 이내 고정 ● 접근방지책: 높이 1.2m 이상 강관(φ48.6mm, 두께 2.4mm), 지주 간격 2.0m 이내 횡선대 3열 이상 설치 ● 시선유도봉: 주황색 몸체 인증품, 주행 방향 앵커볼트 2개 대향 배치 고정 ● 시선유도표지: 높이 900mm 설치, 설치 간격(직선 50m, R≤50m 급곡선 4~5m), 진행 방향 90°(직각) 설치 ● 갈매기표지: 두께 3mm 이하 알루미늄판, 높이 1.2m 거치, R≤50m 급곡선 설치 간격 8m ● 교통안전표지: 알루미늄판(A5052P 등) 두께 3mm 이상, 지주 아연도금 550g/m² 이상(HDZ 55), KS A 3507 초고휘도 반사지 부착 (부착 시 실내 18~24℃, 습도 65% 이하 유지), 차량 진행 방향 직각(90°) 설치(시인성 고려 10° 이내 안쪽 조정) | G16: [작업 절차] 1. 사전 준비 단계: - 설계 도서 및 시방 기준을 분석하여 우회 교통 차선 도색 및 안전 통제 조치 작업을 위한 현장 실측 및 경계 측량을 수행함. 2. 본 시공 단계: - 경찰서 승인 평면도 기반 주·야간 교통 통제 표지 설치 작업을 표준 시공 절차에 준하여 시행하며, 실시간 수평도 및 치수 공차를 관리함. 3. 검사 및 마감 단계: - 고휘도 반사 페인트 차선 도색 및 시선유도봉(델리네이터) 장착 시험 및 품질 검사를 실측하고 기준값 만족 여부를 기록함. 야간 싸이키 등, LED 유도 표지판 전원 가동 작업을 거쳐 노면 정리 및 안전 조치를 완료함. [주의사항 (하자이력 연계)] 굴착 전환부 야간 경고등 미설치로 민간 차량 가시설 추돌 사고 발생 ● 협력업체 자문 [레일운반] 18m/20m 장대레일 반입 시 가로수 저촉 우려가 있으며, 도심지 주간 운반 시 후송차량 및 전담 신호수 배치 필수 [차로점용] 노반공사 완료부 상면에서 장비 이동 및 작업은 문제없으나 배수관 보강이 수반되어야 하며, 협소구간은 100m 이내 압송 타설 권장 | H16: □ 통제 구간 내 차선 도색 및 반사 시트 설치 여부 □ 야간 신호수 조광 유도봉 소지 여부 □ 보행자 안전 통로 확보 및 펜스 마감 상태 [집행단계 리스크 체크사항 (LLBS 연계)] □ 굴착 바닥면의 피압수 용출 가능성(Boiling)을 검토하고 Well Point 등 지하수위 저하 공법을 반영했는가? □ 개착 구조물 기초 바닥에 지하수 배제를 위한 맹암거 및 유공관이 반영되었는가? □ 구조물 터파기 사면(Open Cut)의 상단 라인이 공사 부지 경계선 내에 들어오는가? □ 흙막이 가시설과 본 구조물 사이에 거푸집 설치 및 작업자 이동 공간(최소 1m 이상)이 확보되었는가? | I16: 토목/교통 | J16: ● [교통관리] 도로공사구간 차선 휘도: 설치시 백색 240, 황색 150 mcd/(m²·lx) 이상 (5℃ 이하 시공 금지, KS L 2521 2호 유리알 1L당 800g 살포) ● [교통관리] 임시 차선테이프: 건조 백색 250 / 습윤 백색 500 mcd/(m²·lx), 미끄럼저항 45 BPN 이상 ● [교통관리] 가설 휀스: 높이 1.8m 이상 (민감 지역 주거·상가 50m 이내 3.0m 이상), 지주 간격 1.8m 이내 ● [교통관리] 접근방지책: 높이 1.2m 이상 강관(φ48.6mm, 두께 2.4mm), 지주 간격 2.0m 이내, 횡선대 3열 이상 설치 ● [교통관리] 안전표지: 알루미늄판 두께 3mm 이상, 아연도금 550g/m² 이상(HDZ 55), KS A 3507 초고휘도 반사지 부착, 진행방향 직각(90°) 설치(10° 이내 안쪽 조정) | K16: ● 굴착 전환부 야간 경고등 미설치로 민간 차량 가시설 추돌 사고 발생 리스크를 검토하였는가? | L16: ● [레일운반] 18m/20m 장대레일 반입 시 가로수 저촉 우려가 있으며, 도심지 주간 운반 시 후송차량 및 전담 신호수 배치 필수 ● [차로점용] 노반공사 완료부 상면에서 장비 이동 및 작업은 문제없으나 배수관 보강이 수반되어야 하며, 협소구간은 100m 이내 압송 타설 권장
A17: 3000 교차로 공사 (Intersection Works)
A18: 3000 | B18: 3000-1 | C18: 교차로 구간 지장물 조사 및 인허가 협의 | D18: 3000-1-1 | E18: 교차로 지하매설물 대장 수집 및 사전계획수립 | F18: ● 국토지리정보원 지하정보 통합지도 구축 및 활용 지침 규정 | G18: [작업 절차] 1. 사전 준비 단계: - 설계 도서 및 시방 기준을 분석하여 교차로 지하매설물 대장 수집 및 사전계획수립 작업을 위한 현장 실측 및 경계 측량을 수행함. 2. 본 시공 단계: - 지자체 상하수도, 한국가스공사, 전력/통신사 도면 수집 작업을 표준 시공 절차에 준하여 시행하며, 실시간 수평도 및 치수 공차를 관리함. 3. 검사 및 마감 단계: - GIS 데이터 기반 교차로 중심 횡단면도 중첩 작성 시험 및 품질 검사를 실측하고 기준값 만족 여부를 기록함. 이설/보강 대책이 필요한 중대 지장물 목록 확정 작업을 거쳐 노면 정리 및 안전 조치를 완료함. [주의사항 (하자이력 연계)] 지하시설물 정보 불일치로 굴착 중 상수도 주관 파손, 상가 단수 민원 폭주 ● 협력업체 자문(정주건설/트리플건설) [시공순서] 일반구간 선시공 후 교차로 시공이 시공성 면에서 유리하나, 교차로 선시공 시 차량 통행에 의한 레일 파손 우려 대응 필요 (일반 및 교차로 작업조 통합 운영 권장) ● [교차로PST] 신속한 교통 개방을 위해 프리캐스트(PST) 패널 공법을 적용하되, 아스콘 접속부 처리가 지연되면 개방 효과가 미미하므로 교차로 길이 및 현장 차선 수별 세부 시공계획 필수 | H18: □ 관리기관별 지장물 대장 최신 여부 확인 □ 고압가스, 특별고압 송전선로 간섭 여부 표시 □ 도면 중첩 분석 보고서 작성 완료 [집행단계 리스크 체크사항 (LLBS 연계)] □ 기초 터파기 구간의 지반 조건(연약지반)을 고려할 때 사면 경사를 유지할 부지가 충분한가? □ 도심지 협소 구간 작업 시 대형 장비 진입 불가에 따른 소형 장비 할증이 반영되었는가? □ 자재 발주 전 도면상 명기된 배수 관련 부속 자재가 내역에 있는지 전수 조사했는가? □ 접속부 시공 전 배수판/동판 설치 상세를 작업자에게 교육했는가? | I18: 토목/행정 | J18: ● 관련분야 설계기준서 준수 | K18: ● 지장물 위치 측량 데이터 누락으로 굴착 중 타 기관 지중 설비 오타격 파손 리스크를 검토하였는가? | L18: ● 협력사 자문 내용 없음 또는 해당사항 없음
A19: 3000 | B19: 3000-1 | C19: 교차로 구간 지장물 조사 및 인허가 협의 | D19: 3000-1-2 | E19: 현장 지하매설물 탐지(GPR) 및 인력 시험 굴착 | F19: ● KCS 11 10 10 (지장물 탐사 및 이설 공사 표준시방서) ● 백호우 장비 사용 전 필수 인력 굴착(폭 1.0m, 깊이 2.0m) 선행 | G19: [상세 작업 절차 - 정밀 관리] 1. 사전 설계도 분석 및 매핑: - 지하시설물 정보통신 대장 및 기존 GIS 데이터를 중첩하여 탐사 영역(교차로 개소별)을 3D 격자망으로 사전 분할함. 2. GPR 장비 셋업 및 검교정: - 250MHz/600MHz 이중 주파수 GPR 안테나 장비를 현장 노면에 셋업하고, 지반 유전율 및 수분 상태에 따른 반사 신호 검교정을 수행함. 3. 정밀 GPR 스캐닝 실시: - 노면 격자 라인(최소 0.5m 간격)을 따라 스캔을 실시하여 종횡단 단면의 반사 신호(Hyperbola)를 실시간 획득함. 4. 공동 및 이상 대역 탐지 분석: - 획득된 원시 데이터를 소프트웨어를 통해 필터링하여 지중 공동 및 금속/비금속 매설관(상수도, 가스관, 케이블 등)의 예상 심도(오차 ±10cm)를 추정함. 5. 현장 인력 시험 굴착 및 확인: - 중장비 굴착 전, 예상 지장물 심도 상부 1.0m 지점까지는 백호우로 굴착하고, 이후 유관기관 입회 하에 인력 굴착(폭 1.0m, 깊이 2.0m 이상)을 통해 지장물의 정확한 관종, 외경, 재질을 육안 확인하고 GIS 측량을 시행하여 위치를 확정함. [주의사항 (하자이력 연계)] 장비 굴착 중 도면에 없던 한전 고압 케이블 포크레인 버킷 접촉 사고 | H19: □ GPR 검출 자료와 설계도면 불일치 구간 확인 □ 백호우 장비 사용 전 인력 굴착 선행 여부 □ 노출 매설물 종류 및 재질 태그 기록 보관 [집행단계 리스크 체크사항 (LLBS 연계)] □ 기초 터파기 구간의 지반 조건(연약지반)을 고려할 때 사면 경사를 유지할 부지가 충분한가? □ 구조물 터파기 사면(Open Cut)의 상단 라인이 공사 부지 경계선 내에 들어오는가? □ 자재 발주 전 도면상 명기된 배수 관련 부속 자재가 내역에 있는지 전수 조사했는가? □ 접속부 시공 전 배수판/동판 설치 상세를 작업자에게 교육했는가? | I19: 토목 | J19: ● 관련분야 설계기준서 준수 | K19: ● 지하 매설 특수 지장물(고압 한전 가스관) 정밀 탐사 지연으로 후속 토공 착수 무기한 연기 리스크를 검토하였는가? | L19: ● 협력사 자문 내용 없음 또는 해당사항 없음
A20: 3000 | B20: 3000-1 | C20: 교차로 구간 지장물 조사 및 인허가 협의 | D20: 3000-1-3 | E20: 지장물 관리기관 합동 회의 및 이설 협의서 날인 | F20: ● 도로법 시행령 제43조(점용료 및 지장물 이설 비용 정산 기준) | G20: [작업 절차] 1. 사전 준비 단계: - 설계 도서 및 시방 기준을 분석하여 지장물 관리기관 합동 회의 및 이설 협의서 날인 작업을 위한 현장 실측 및 경계 측량을 수행함. 2. 본 시공 단계: - 관할 지자체 및 가스/전력 관리기관 담당자 현장 공동 실사 주관 작업을 표준 시공 절차에 준하여 시행하며, 실시간 수평도 및 치수 공차를 관리함. 3. 검사 및 마감 단계: - 이설 공법 및 임시 우회 선로 방안 협의록 조율 시험 및 품질 검사를 실측하고 기준값 만족 여부를 기록함. 분담금 정산 비율이 명시된 이설 합의 승인서 날인 작업을 거쳐 노면 정리 및 안전 조치를 완료함. [주의사항 (하자이력 연계)] 이설 비용 분담 협의 미결 상태로 장시간 방치되어 전체 공기 3개월 지연 | H20: □ 관리기관 공동 서명 날인서 확보 완료 □ 이설 비용 청구 및 실행 예산 승인 여부 □ 이설 우회 루트 지반 지지력 확인 완료 [집행단계 리스크 체크사항 (LLBS 연계)] □ 기초 터파기 구간의 지반 조건(연약지반)을 고려할 때 사면 경사를 유지할 부지가 충분한가? □ 도심지 협소 구간 작업 시 대형 장비 진입 불가에 따른 소형 장비 할증이 반영되었는가? □ 도로/철도 횡단 구간의 낙하물 방지 시설이 '그물망'이 아닌 '방호 선반(강판/합판)'으로 설계되었는가? □ 특수 교각(Y형, V형) 시공 시 상부 하중을 지지할 가설 벤트가 내역에 있는가? | I20: 토목/행정 | J20: ● 관련분야 설계기준서 준수 | K20: ● 지장물 이설 공사비 정산 지연으로 해당 유관 부처 협의 지연 및 행정 조치 보완 리스크를 검토하였는가? | L20: ● 협력사 자문 내용 없음 또는 해당사항 없음
A21: 3000 | B21: 3000-2 | C21: 교차로 지장물 이설 및 방호·보강 공사 | D21: 3000-2-1 | E21: 교차로 지장물 임시/영구 이설 시공 | F21: ● KCS 11 10 15 (상수도 배관 시공 표준시방서) ● 임시 이설 상수도 기밀 수압시험(설계 규정압력의 1.5배, 1시간 유지) | G21: [상세 작업 절차 - 정밀 관리] 1. 우회 이설 계획 수립 및 밸브 차단: - 이설 노선에 대한 임시 우회 배관 자재(용접강관, PE관 등) 및 차수 밸브 위치를 점검하고, 단수/차단 일정에 대해 지자체 및 유관기관 사전 공고를 완료함. 2. 이설 대상관 노출 및 방호: - 백호우 굴착 후 노출된 기존 상수도/가스관에 충격 방지용 EPDM 고무 패드를 피복하고 안전 벤트 가시설을 건립하여 구조적 안정성을 유지함. 3. 임시 바이패스 관로 포설 및 조인트 접합: - 규격 배관을 현장 정밀 재단하여 설계 경로로 포설하고, 융착 접합 및 플랜지 볼트 체결(토크 렌치 정밀 제어)을 수행하여 기밀성을 확보함. 4. 수압 시험 및 플러싱 소독: - 신설 우회 관로 내부를 플러싱하여 이물질을 제거하고, 규정 수압(설계 압력의 1.5배, 최소 1.0 MPa)을 가해 1시간 동안 누수 및 압력 강하 여부를 정밀 확인하고 성적서를 작성함. 5. 관로 전환 및 되메우기: - 야간 차단 시간 내에 기존 관로에서 우회 관로로 유체를 전환(Tie-in) 접합하고, 되메우기(모래 두께 300mm 보호층 및 양질토 분할 다짐)를 완료함. [주의사항 (하자이력 연계)] 임시 이설한 상수도관 연결부 수압 불량으로 누수 발생, 도로 지반 함몰 | H21: □ 단수 안내문 발송 및 비상 급수 대책 수립 확인 □ 수압시험 합격 기준(압력 강하 0.02MPa 이하) 확인 □ 접합부 용접 및 프랜지 조임 검측 상태 [집행단계 리스크 체크사항 (LLBS 연계)] □ 교량 시공용 대형 크레인(200ton 이상)의 아웃트리거 전개 폭을 고려하여 가교 폭이나 작업대(Staging)가 반영되었는가? □ 구조물 터파기 사면(Open Cut)의 상단 라인이 공사 부지 경계선 내에 들어오는가? □ 하부 도로/구조물이 상부 시공 하중(크레인+거더)을 견딜 수 있는가? □ 벤트 위치가 하부 교통 흐름이나 구조물과 간섭되지 않는가? | I21: 토목/기계 | J21: ● 관련분야 설계기준서 준수 | K21: ● 임시 이설한 상수도관 연결부 수압 불량으로 누수 발생, 도로 지반 함몰 리스크를 검토하였는가? | L21: ● 협력사 자문 내용 없음 또는 해당사항 없음
A22: 3000 | B22: 3000-2 | C22: 교차로 지장물 이설 및 방호·보강 공사 | D22: 3000-2-2 | E22: 이설 불가 지장물 방호공(H-Beam 매달기) 시공 | F22: ● 건설공사용 가설구조물 설계기준(KDS 21 00 00) 구조 안전율 준수 | G22: [상세 작업 절차 - 정밀 관리] 1. 지장물 노출 및 계측기 부착: - 이설 불가 매설 가스관/통신관 구간을 인력 굴착으로 완전히 노출시키고, 관 표면에 변형률 게이지(Strain Gauge) 및 처짐 측정용 틸트센서를 부착함. 2. 방호 H-Beam 파일 천공 및 근입: - 지장물 외곽 양측에 규격 H-Beam(300x300mm) 수직 파일을 오거로 천공 및 근입하고, 그라우팅 주입으로 지지력을 확보함. 3. 매달기 크로스 거더 설치: - 수직 H-Beam 상부에 횡방향 H-Beam 크로스 거더를 정밀 볼트 조임 및 용접 접합하여 강결 구조를 형성함. 4. 행거 와이어 조립 및 장력 도입: - 특수 강재 행거 플레이트와 고장력 턴버클 와이어를 크로스 거더와 지장물 받침대(Saddle) 사이에 조립하고, 설계 하중 분배를 고려하여 와이어 턴버클 장력을 고르게 도입(토크 렌치 제어)함. 5. 거푸집 가설 및 시공 중 상시 모니터링: - 가시설 흙막이판 설치 시 방호 구간 하부에 낙석 방지 판넬을 추가 설치하고, 토공 굴착 및 본체 시공 중 지장물의 미세 침하(허용치 ±2mm 이내) 여부를 실시간 계측기로 모니터링함. [주의사항 (하자이력 연계)] 매달기 방호공의 와이어 장력 이완으로 가스관 침하 및 이음부 가스 누출 | H22: □ H-Beam 매달기 와이어 조임 및 턴버클 체결 강도 □ 매설관 하부 처짐 방지용 패드 밀착 상태 □ 변위 측정 센서 초기 리셋 및 일일 기록 여부 [집행단계 리스크 체크사항 (LLBS 연계)] □ 구조물 터파기 사면(Open Cut)의 상단 라인이 공사 부지 경계선 내에 들어오는가? □ 기초 터파기 구간의 지반 조건(연약지반)을 고려할 때 사면 경사를 유지할 부지가 충분한가? □ 동바리 높이가 10m를 초과하는 구간에 대해 시스템 동바리가 적용되었는가? □ 좌굴 안정성 검토가 수행되었는가? | I22: 토목 | J22: ● 관련분야 설계기준서 준수 | K22: ● 매달기 방호공의 와이어 장력 이완으로 가스관 침하 및 이음부 가스 누출 리스크를 검토하였는가? | L22: ● 협력사 자문 내용 없음 또는 해당사항 없음
A23: 3000 | B23: 3000-3 | C23: 교차로 토공 굴착 및 가시설 설치 | D23: 3000-3-1 | E23: 교차로 아스팔트 포장 깨기 및 단계별 굴착 | F23: ● KCS 11 20 15 (토공사 굴착 표준시방서) ● 굴착 사면 경사면 구배 확보(사질토 1:1.0, 암반 1:0.5) | G23: [작업 절차] 1. 사전 준비 단계: - 설계 도서 및 시방 기준을 분석하여 교차로 아스팔트 포장 깨기 및 단계별 굴착 작업을 위한 현장 실측 및 경계 측량을 수행함. 2. 본 시공 단계: - 도로 커터를 이용하여 차선별 외곽 라인 정밀 컷팅(깊이 150mm) 작업을 표준 시공 절차에 준하여 시행하며, 실시간 수평도 및 치수 공차를 관리함. 3. 검사 및 마감 단계: - 백호우 브레이커 작업 시 비산방지망 설치 시험 및 품질 검사를 실측하고 기준값 만족 여부를 기록함. 굴착 단계별 법면 구배 유지(사질토 1:1.0, 암반 1:0.5) 작업을 거쳐 노면 정리 및 안전 조치를 완료함. [주의사항 (하자이력 연계)] 굴착 단면 경사 방치로 우천 시 법면 붕괴 및 주변 통제 펜스 탈락 | H23: □ 도로 정밀 컷팅 라인 일치 및 인접 포장 파손 유무 □ 살수기 가동 및 비산 먼지 제어 상태 □ 굴착면 기울기 및 굴착 깊이 설계값 일치 여부 [집행단계 리스크 체크사항 (LLBS 연계)] □ 가시설 굴착 심도가 지하수위 아래에 위치하는가? □ 토류판 적용 시 차수 그라우팅 비용이 반영되었는가? □ 개착 구조물 기초 바닥에 지하수 배제를 위한 맹암거 및 유공관이 반영되었는가? □ 항타기 등 대형 장비의 진입로 폭과 회전 반경이 현장 여건(농로, 마을길)과 부합하는가? | I23: 토목 | J23: ● [토질기초] 깎기 비탈면 표준 경사: 풍화암 1:1.0~1:1.2, 연암(절리직각) 1:0.5~1:0.7, 경암(절리직각) 1:0.3~1:0.5 ● [토질기초] 깎기 비탈면 기준 안전율: 건기 Fs > 1.5, 우기 Fs > 1.2 (지하수위 1/2 포화 시) ● [토질기초] 가설 흙막이 안전율: 근입깊이 1.2, 보일링 1.5, 히빙 1.5, 앵커 인발(단기) 1.5 이상 | K23: ● 굴착 단면 경사 방치로 우천 시 법면 붕괴 및 주변 통제 펜스 탈락 리스크를 검토하였는가? (교차로 궤도 [10] [12] 연계) ● 지그 고정 불량으로 플랜지웨이 폭이 47mm를 초과해 휠체어·자전거 전도 사고가 발생할 리스크를 검토하였는가? | L23: ● [시공순서] 일반구간 선시공 후 교차로 시공이 시공성 면에서 유리하나, 교차로 선시공 시 차량 통행에 의한 레일 파손 우려 대응 필요 (일반 및 교차로 작업조 통합 운영 권장)
A24: 3000 | B24: 3000-3 | C24: 교차로 토공 굴착 및 가시설 설치 | D24: 3000-3-2 | E24: 교차로 단계별 교통 전환 방호벽 설치 및 노출 지장물 방호 | F24: ● KCS 21 20 05 (가설안전시설물) / KCS 11 10 10 (지장물 이설공사) ● 교통 차단 PE 방호벽 물채움 고정 및 노출 매설관 턴버클 매달기 수직 처짐 통제 | G24: [작업 절차] 1. 사전 준비 단계: - 설계 도서 및 시방 기준을 분석하여 교차로 단계별 교통 전환 방호벽 설치 및 노출 지장물 방호 작업을 위한 현장 실측 및 경계 측량을 수행함. 2. 본 시공 단계: - 교차로 단계별 점용 차선 경계부에 PE 방호벽(물채움 충진 필수) 및 안전 펜스를 정밀 건주할 것 작업을 표준 시공 절차에 준하여 시행하며, 실시간 수평도 및 치수 공차를 관리함. 3. 검사 및 마감 단계: - 야간 시인성 확보를 위해 PE 방호벽 상부 델리네이터 및 경고 발광 다이오드(LED) 조밀 거치 시험 및 품질 검사를 실측하고 기준값 만족 여부를 기록함. 굴착 중 노출된 상수도/한전관 등 연약 매설물 처짐 방지용 H-Beam 지탱 보강 또는 턴버클 매달기 방호 처치 작업을 거쳐 노면 정리 및 안전 조치를 완료함. [주의사항 (하자이력 연계)] 임시 차선 차단 PE 방호벽 전도에 따른 교차로 추돌 사고 발생 및 노출 매설관(가스/상수도) 지탱 부실로 인한 관 처짐 미세 균열 발생 | H24: □ PE 방호벽 물채움 및 연결 핀 결속 상태 □ 야간 경고등 정상 작동 및 시인성 확보 여부 □ 노출 지장물 처짐 방지 지탱대 거치 상태 □ 임시 지철판 단차 미끄럼 방지 고무 패드 설치 여부 [집행단계 리스크 체크사항 (LLBS 연계)] □ 가시설 굴착 심도가 지하수위 아래에 위치하는가? □ 토류판 적용 시 차수 그라우팅 비용이 반영되었는가? □ 개착 구조물 기초 바닥에 지하수 배제를 위한 맹암거 및 유공관이 반영되었는가? □ 항타기 등 대형 장비의 진입로 폭과 회전 반경이 현장 여건(농로, 마을길)과 부합하는가? | I24: 토목 | J24: ● [토질기초] 가시설 흙막이벽 허용 수평변위: 강성 0.002H, 보통 0.0025H, 연성 0.003H (H: 굴착심도) ● [토질기초] 인접 도로 허용 침하량: 25mm 이하 | K24: ● 임시 차선 차단 PE 방호벽 전도에 따른 교차로 추돌 사고 발생 및 노출 매설관(가스/상수도) 지탱 부실로 인한 관 처짐 미세 균열 발생 | L24: ● [교차로PST] 신속한 교통 개방을 위해 프리캐스트(PST) 패널 공법을 적용하되, 아스콘 접속부 처리가 지연되면 개방 효과가 미미하므로 교차로 길이 및 현장 차선 수별 세부 시공계획 필수 ● [박스구간] 개착박스 내 협소 공간 시공 시 별도 특수 장비 없이 일반 장비와 가이드롤러를 조합하여 시공 가능
A25: 3000 | B25: 3000-4 | C25: 교차로 노반·RC-PC 구조물 설치 및 마감 공사 | D25: 3000-4-1 | E25: 기초 지반 정밀 정리 및 지내력 평판재하시험(PBT) | F25: ● KDS 11 50 15 (얕은기초 설계기준) ● 교차로 노반 하부 기초 허용 지내력(최소 200 kN/m²) 도달 시험 | G25: [상세 작업 절차 - 정밀 관리] 1. 시험 위치 선정 및 노면 정지: - 설계도상 노반 기초 평판재하시험(PBT) 위치(정거장 기초, 교량 교대 등 최소 3개소)를 마킹하고, 시험 구역 지반을 흙판 등으로 평탄하게 정리(요철 2mm 이하)함. 2. 시험판 및 재하시설 세팅: - 직경 300mm 원형 강제 재하판을 지반에 수평 안착시키고, 반력 하중용 중장비(20톤 백호우 또는 덤프트럭)의 하중 중심에 잭(Jack)을 배치함. 3. 다이얼 게이지 및 측정 장치 세팅: - 지반 침하량 측정을 위한 마이크로 다이얼 게이지(측정 정밀도 0.01mm) 3개를 재하판 주위에 삼각 형태로 대칭 배치하고 기준 빔에 고정함. 4. 단계별 하중 재하 및 침하량 실측: - 설계 최대 재하 하중(150 kN/m2 확보 목적)을 5~8단계로 나누어 누적 재하함. 각 단계별 하중을 15분 이상 유지하며 지반 변형률 및 침하 속도가 안정될 때까지 다이얼 게이지 값을 실측 기록함. 5. 지내력 평가 및 노반 변형계수(Ev1, Ev2) 도출: - 압력-침하량 곡선을 분석하여 극한 지지력을 도출하고, 변형계수비(Ev2/Ev1)가 시방 기준(2.0 이하)을 충족하는지 검증하여 합격 판정 후 시험 성적서를 작성 및 서명함. [주의사항 (하자이력 연계)] 교차로 노반 하부 지반 지내력 부족으로 트램 시공 후 부등 침하 발생(선형 변형) | H25: □ 바닥면 배수 처리 및 느슨한 흙 제거 상태 □ 평판재하시험(PBT) 성적서 결과 값(200 kN/m2 이상) □ 침하량-하중 곡선 상 항복점 유무 확인 [집행단계 리스크 체크사항 (LLBS 연계)] □ 항타기 등 대형 장비의 진입로 폭과 회전 반경이 현장 여건(농로, 마을길)과 부합하는가? □ 기초 터파기 구간의 지반 조건(연약지반)을 고려할 때 사면 경사를 유지할 부지가 충분한가? □ 배수펌프장 등 필수 운영 시설의 가동 기간이 전체 공사 기간과 연동되어 있는가? □ 도심지 공사 시 교통 처리 계획에 따른 가시설 존치 기간이 적정하게 산정되었는가? | I25: 토목/노반 | J25: ● [토질기초] 직접기초 허용 지내력 연직지지력 저항계수 0.45 (극한한계상태), 1.0 (사용/극단한계상태) ● [토질기초] 지반의 분류: 전단파속도 Vs 기준 S1(암반) ~ S5(깊고 연약한 지반) 구분 적용 | K25: ● 교차로 노반 하부 지반 지내력 부족으로 트램 시공 후 부등 침하 발생(선형 변형) 리스크를 검토하였는가? | L25: ● 협력사 자문 내용 없음 또는 해당사항 없음
A26: 3000 | B26: 3000-4 | C26: 교차로 노반·RC-PC 구조물 설치 및 마감 공사 | D26: 3000-4-2 | E26: 프리캐스트(PC) 노반 구조물 크레인 정밀 거치 | F26: ● KCS 14 20 53 (프리캐스트 콘크리트 공사 표준시방서) ● PC 블록 접합 조인트 채움 무수축 몰탈 규정 강도(최소 30 MPa) 확보 | G26: [상세 작업 절차 - 정밀 관리] 1. 노반 기초면 실측 및 청소: - 프리캐스트(PC) 노반 구조물이 안착될 하부 콘크리트 기초면의 중심선 및 높이를 광파기로 정밀 실측하고, 레이턴스(불순물) 및 먼지를 와이어 브러시로 완전히 청소함. 2. 인양 크레인 세팅 및 줄걸이 점검: - 투입될 이동식 크레인(200톤급 이상)의 아웃트리거 밑판 보강 지반 다짐을 완료하고, 슬링 와이어(4점식 샤클 연결)의 마모 상태를 육안 점검함. 3. PC 블록 인양 및 가거치: - PC 노반 블록(중량 약 15톤)을 서서히 수평 인양하여 안착 위치 상부 30cm 지점까지 하강시킨 후, 정밀 가이드 지그를 사용해 가거치함. 4. 3D 정밀 얼라인먼트 조정: - 광파기 및 정밀 레벨기를 활용하여 PC 블록 간 접합 조인트 단차(허용오차 ±1mm 이내) 및 중심선 틀림을 미세 유압 잭으로 상하좌우 정밀 조정함. 5. 무수축 몰탈 충진 및 습윤 양생: - 접합부에 조인트 폼재를 기밀 가설하고, 고강도 무수축 몰탈(설계 강도 40 MPa 이상)을 공극 없이 가압 충진함. 충진 완료 후 충격 및 진동을 차단하고 최소 3일간 습윤 포를 덮어 양생을 시행함. [주의사항 (하자이력 연계)] PC 노반 블록 간 조인트 단차 및 접합 무수축 몰탈 충진 부족으로 차량 진동 시 블록 이탈 | H26: □ PC 블록 수평 오차(±3mm 이내) 확인 □ 접합 조인트 틈새 테이핑 및 몰탈 누출 유무 □ 몰탈 공시체 강도(최소 30 MPa) 시험 합격 여부 [집행단계 리스크 체크사항 (LLBS 연계)] □ 교량 시공용 대형 크레인(200ton 이상)의 아웃트리거 전개 폭을 고려하여 가교 폭이나 작업대(Staging)가 반영되었는가? □ 항타기 등 대형 장비의 진입로 폭과 회전 반경이 현장 여건(농로, 마을길)과 부합하는가? □ 도심지 공사 시 교통 처리 계획에 따른 가시설 존치 기간이 적정하게 산정되었는가? □ 특수교량(FCM 등)의 주요 구조부 설계 적정성을 착공 전 검증했는가? | I26: 토목/노반 | J26: ● [구조분야] 고정하중: 철근콘크리트 24.5 kN/m3, 아스팔트 포장재 22.6 kN/m3 적용 ● [구조분야] 트램 활하중: 5량 기준 총중량 632 kN (축중 63.2 kN/축) 적용 | K26: ● PC 노반 블록 간 조인트 단차 및 접합 무수축 몰탈 충진 부족으로 차량 진동 시 블록 이탈 리스크를 검토하였는가? | L26: ● 협력사 자문 내용 없음 또는 해당사항 없음
A27: 3000 | B27: 3000-5 | C27: 곡선부 선형설계 및 확폭 공사 | D27: 3000-5-1 | E27: 트램 곡선 구간 확폭 측량 및 캔트/슬랙 계산 | F27: ● 경기도 노면전차 건설 규정 제6조(최소 곡선반경 R25m 이상, 캔트/슬랙 미적용 표준) | G27: [상세 작업 절차 - 정밀 관리] 1. 노선 기하학 데이터 수집: - 트램 궤도 선형 설계 도면에서 곡선 반경(R), 완화곡선 길이(L), 설계 속도(V=30~45km/h) 및 윤배 간격 데이터를 수집함. 2. 캔트(Cant) 설계값 계산: - 공식 [C = 11.8 * V^2 / R]을 바탕으로 균형 캔트값을 계산하고, 승객 승차감 향상과 차륜 이상 마모 방지를 위한 외궤 높임 캔트(설계치 예: 40mm)를 결정함. 3. 슬랙(Slack) 곡선 확폭량 계산: - 고정 축거를 고려하여 곡선 반경에 따른 궤간 확폭량(슬랙량: 0~15mm)을 계산하고, 외측 궤간 레일의 확폭 곡선을 정의함. 4. 현장 3D 토탈스테이션 정밀 측량: - 현장에 3D 토탈스테이션을 설치하여 설계 좌표(X, Y, Z) 기반 곡선 시종점부(BTC, ECC, ETC) 및 주요 10m 격자 포인트를 측량 및 레일 마킹함. 5. 설계 보정 및 차량 주행 간섭 시뮬레이션: - 계산된 캔트/슬랙 값을 토대로 인근 정거장 플랫폼 및 연석 시설물과의 건축한계(Clearance 최소 100mm 확보) 침범 여부를 시뮬레이션하고 설계 최종 승인을 득함. [주의사항 (하자이력 연계)] 캔트 부족으로 주행 트램 원심력 이탈 감지 및 비상 제동 동작(승차감 극도로 저하) | H27: □ 선형 계산서 상 캔트값 설계 일치 여부 □ 곡선부 외측 레일 높이(캔트량) 오차 범위 확인 □ 측량 결과의 설계값 오차(±1mm 이내) 확인 [집행단계 리스크 체크사항 (LLBS 연계)] □ 특수교량(FCM 등)의 주요 구조부 설계 적정성을 착공 전 검증했는가? □ 도로/철도 횡단 구간의 낙하물 방지 시설이 '그물망'이 아닌 '방호 선반(강판/합판)'으로 설계되었는가? □ 하부 도로/구조물이 상부 시공 하중(크레인+거더)을 견딜 수 있는가? □ 벤트 위치가 하부 교통 흐름이나 구조물과 간섭되지 않는가? | I27: 토목 | J27: ● 관련분야 설계기준서 준수 | K27: ● 캔트 부족으로 주행 트램 원심력 이탈 감지 및 비상 제동 동작(승차감 극도로 저하) 리스크를 검토하였는가? | L27: ● 협력사 자문 내용 없음 또는 해당사항 없음
A28: 3000 | B28: 3000-5 | C28: 곡선부 선형설계 및 확폭 공사 | D28: 3000-5-2 | E28: 확폭 구간 도로 굴착 및 지반 안정 시공 | F28: ● KCS 11 20 20 (도로 노상 및 노반 다짐) ● 확폭 경계 지반 시멘트 안정처리(CBR 10% 이상, 다짐도 98% 확보) | G28: [작업 절차] 1. 사전 준비 단계: - 설계 도서 및 시방 기준을 분석하여 확폭 구간 도로 굴착 및 지반 안정 시공 작업을 위한 현장 실측 및 경계 측량을 수행함. 2. 본 시공 단계: - 기존 차로 경계면 벤치컷팅(계단식 깎기) 실시 작업을 표준 시공 절차에 준하여 시행하며, 실시간 수평도 및 치수 공차를 관리함. 3. 검사 및 마감 단계: - 시멘트 안정 처리 공법을 통한 노상 강도(CBR 10% 이상) 보강 시험 및 품질 검사를 실측하고 기준값 만족 여부를 기록함. 콤팩터를 이용한 경계 모서리 정밀 다짐 작업을 거쳐 노면 정리 및 안전 조치를 완료함. [주의사항 (하자이력 연계)] 확폭 접합부 다짐 불량으로 트램 탈선방지 가드레일 설치 구간 지반 균열 발생 | H28: □ 계단식 깎기 적용으로 신구 접합부 일체화 여부 □ 시멘트 혼합 균일도 및 다짐도 검측(98% 이상) □ 지하 배수 유도용 맹암거 설치 상태 [집행단계 리스크 체크사항 (LLBS 연계)] □ 자재 발주 전 도면상 명기된 배수 관련 부속 자재가 내역에 있는지 전수 조사했는가? □ 접속부 시공 전 배수판/동판 설치 상세를 작업자에게 교육했는가? □ 가설 구조물 철거 시 발생할 폐기물 물량을 예측하여 예산에 반영했는가? □ 준공 정산 시 누락되기 쉬운 철거 비용을 미리 확보했는가? | I28: 토목 | J28: ● 관련분야 설계기준서 준수 | K28: ● 확폭 접합부 다짐 불량으로 트램 탈선방지 가드레일 설치 구간 지반 균열 발생 리스크를 검토하였는가? | L28: ● 협력사 자문 내용 없음 또는 해당사항 없음
A29: 3000 | B29: 3000-6 | C29: 교차로 신호·표지판 설치 및 도로 마감 공사 | D29: 3000-6-1 | E29: 교통신호기 지주 건주 및 제어반 결선 | F29: ● 경찰청 표준규격 교통신호제어기 규정 준수(LSU, Flash-EXT, PPC 등) | G29: [작업 절차] 1. 사전 준비 단계: - 설계 도서 및 시방 기준을 분석하여 교통신호기 지주 건주 및 제어반 결선 작업을 위한 현장 실측 및 경계 측량을 수행함. 2. 본 시공 단계: - 신호 지주 기초 앵커 매립 및 콘크리트 강도 확인 작업을 표준 시공 절차에 준하여 시행하며, 실시간 수평도 및 치수 공차를 관리함. 3. 검사 및 마감 단계: - 통신·전원 케이블 입선 및 단자대 압착 터미널 시공 시험 및 품질 검사를 실측하고 기준값 만족 여부를 기록함. 트램 제어 인터페이스 카드 제어기 내 장착 작업을 거쳐 노면 정리 및 안전 조치를 완료함. [주의사항 (하자이력 연계)] 수동 결선 오류로 트램 접근 시 교차로 신호 황색 등화 미표시, 일반차량 충돌 | H29: □ 지주 수직도 및 기초 콘크리트 지내력 확인 □ 케이블 단자 압착 불량 및 절연 피복 손상 유무 □ 경찰서 교통신호 통제기 프로토콜 연동 통신 확인 [집행단계 리스크 체크사항 (LLBS 연계)] □ 도로/철도 횡단 구간의 낙하물 방지 시설이 '그물망'이 아닌 '방호 선반(강판/합판)'으로 설계되었는가? □ 하부 도로/구조물이 상부 시공 하중(크레인+거더)을 견딜 수 있는가? □ 벤트 위치가 하부 교통 흐름이나 구조물과 간섭되지 않는가? □ 기존 차선 수 유지가 가능한 단계별 가시설(Staging) 계획인가? | I29: 토목/노반 | J29: ● 관련분야 설계기준서 준수 | K29: ● 수동 결선 오류로 트램 접근 시 교차로 신호 황색 등화 미표시, 일반차량 충돌 리스크를 검토하였는가? | L29: ● 협력사 자문 내용 없음 또는 해당사항 없음
... A31: 3000 | B31: 3000-6 | C31: 교차로 신호·표지판 설치 및 도로 마감 공사 | D31: 3000-6-3 | E31: 트램 우선신호 검지기(Loop Coil 등) 매설 시험 | F31: ● ITS 사업 시방서(루프검지기 부설공) ● 코일 매설 슬롯 컷팅(폭 10mm, 깊이 50mm), 루프선 절연저항 10MΩ 이상 | G31: [작업 절차] 1. 사전 준비 단계: - 설계 도서 및 시방 기준을 분석하여 트램 우선신호 검지기(Loop Coil 등) 매설 시험 작업을 위한 현장 실측 및 경계 측량을 수행함. 2. 본 시공 단계: - 아스팔트 포장면 정밀 슬롯 컷팅(폭 10mm, 깊이 50mm) 작업을 표준 시공 절차에 준하여 시행하며, 실시간 수평도 및 치수 공차를 관리함. 3. 검사 및 마감 단계: - 루프선(4회 이상 권선) 삽입 후 절연저항(10MΩ 이상) 측정 시험 및 품질 검사를 실측하고 기준값 만족 여부를 기록함. 에폭시 코킹재 주입 마감 및 트램 차량 통과 실시간 검지 테스트 작업을 거쳐 노면 정리 및 안전 조치를 완료함. [주의사항 (하자이력 연계)] 루프 코일 몰탈 충진부 박리로 아스팔트 균열 및 단선 발생, 트램 감지 불능 | H31: □ 코일 슬롯 컷팅 깊이 및 모서리 모따기 처리 여부 □ 코킹재 충진 상태 및 포장 노면과의 단차 유무 □ 통과 차량 감지 신호 검지기반 수신 확인 [집행단계 리스크 체크사항 (LLBS 연계)] □ 특수교량(FCM 등)의 주요 구조부 설계 적정성을 착공 전 검증했는가? □ 도로/철도 횡단 구간의 낙하물 방지 시설이 '그물망'이 아닌 '방호 선반(강판/합판)'으로 설계되었는가? □ 하부 도로/구조물이 상부 시공 하중(크레인+거더)을 견딜 수 있는가? □ 벤트 위치가 하부 교통 흐름이나 구조물과 간섭되지 않는가? | I31: 토목/노반 | J31: ● 관련분야 설계기준서 준수 | K31: ● 에폭시 충진재 내부 공극 발생으로 노면수 침투, 동절기 동결 팽창으로 루프 검지선 단선 리스크를 검토하였는가? | L31: ● 협력사 자문 내용 없음 또는 해당사항 없음
A32: 5000 본선 궤도공사 (Mainline Trackworks)
A33: 5000 | B33: 5000-1 | C33: 궤도 구간 지장물 조사 및 인허가 협의 | D33: 5000-1-1 | E33: 궤도 선형 하부 지하 지장물 GPR 정밀 탐지 | F33: ● 지하안전관리에 관한 특별법(지하매설물 정밀 안전성 평가 지침) | G33: [작업 절차] 1. 사전 준비 단계: - 설계 도서 및 시방 기준을 분석하여 궤도 선형 하부 지하 지장물 GPR 정밀 탐지 작업을 위한 현장 실측 및 경계 측량을 수행함. 2. 본 시공 단계: - 궤도 중심선 좌우 2.5m 폭 범위 GPR 스캔 주행 작업을 표준 시공 절차에 준하여 시행하며, 실시간 수평도 및 치수 공차를 관리함. 3. 검사 및 마감 단계: - 지하 레이더 이미지상 이상 반사체 깊이 측정 시험 및 품질 검사를 실측하고 기준값 만족 여부를 기록함. 1m 간격 격자망 기반 매설물 탐지 맵 도면화 작업을 거쳐 노면 정리 및 안전 조치를 완료함. [주의사항 (하자이력 연계)] 본선 궤도 굴착 중 폐쇄된 것으로 오인한 구 상선 전력관 접촉 사고 | H33: □ GPR 탐사 주행 속도 규정(5km/h 이하) 준수 여부 □ 매설물 위치 표시 스프레이 마킹 상태 □ 맨홀 내부 실사 및 관리대장 상의 이격 거리 검증 [집행단계 리스크 체크사항 (LLBS 연계)] □ 기초 터파기 구간의 지반 조건(연약지반)을 고려할 때 사면 경사를 유지할 부지가 충분한가? □ 도심지 협소 구간 작업 시 대형 장비 진입 불가에 따른 소형 장비 할증이 반영되었는가? □ 자재 발주 전 도면상 명기된 배수 관련 부속 자재가 내역에 있는지 전수 조사했는가? □ 접속부 시공 전 배수판/동판 설치 상세를 작업자에게 교육했는가? | I33: 토목/행정 | J33: ● 관련분야 설계기준서 준수 | K33: ● 지중 레이더(GPR) 탐사 생략으로 도로 하부 동공 미발견, 굴착 중 도로 함몰 사고 리스크를 검토하였는가? | L33: ● 협력사 자문 내용 없음 또는 해당사항 없음
A34: 5000 | B34: 5000-2 | C34: 궤도 구간 지장물 이설 공사 | D34: 5000-2-1 | E34: 궤도 선형 간섭 상수도/전력관 우회 이설 | F34: ● KCS 11 10 10 (지장물 이설공사 일반기준) ● 되메우기 재료 층별 포설 및 다짐도 95% 이상 검측 | G34: [작업 절차] 1. 사전 준비 단계: - 설계 도서 및 시방 기준을 분석하여 궤도 선형 간섭 상수도/전력관 우회 이설 작업을 위한 현장 실측 및 경계 측량을 수행함. 2. 본 시공 단계: - 이설 신설 관로 터파기 및 경사도 레벨 측정 작업을 표준 시공 절차에 준하여 시행하며, 실시간 수평도 및 치수 공차를 관리함. 3. 검사 및 마감 단계: - 기계식 접합부 토크 체결 및 용접부 비파괴 검사(RT/UT) 시험 및 품질 검사를 실측하고 기준값 만족 여부를 기록함. 관로 보호용 경고 테이프 매설(관 상부 30cm 지점) 작업을 거쳐 노면 정리 및 안전 조치를 완료함. [주의사항 (하자이력 연계)] 이설 배수관 접합부 플랜지 볼트 조임 부족으로 매설 후 미세 누수 지반 완화 | H34: □ 관로 경사도(배수 자연유하 구배) 설계 만족 여부 □ 기밀시험 또는 누수시험 보고서 승인 여부 □ 이설 관로 되메우기 다짐도(95% 이상) 검측 [집행단계 리스크 체크사항 (LLBS 연계)] □ 도심지 협소 구간 작업 시 대형 장비 진입 불가에 따른 소형 장비 할증이 반영되었는가? □ 교량 시공용 대형 크레인(200ton 이상)의 아웃트리거 전개 폭을 고려하여 가교 폭이나 작업대(Staging)가 반영되었는가? □ 하부 도로/구조물이 상부 시공 하중(크레인+거더)을 견딜 수 있는가? □ 벤트 위치가 하부 교통 흐름이나 구조물과 간섭되지 않는가? | I34: 토목/기계 | J34: ● 관련분야 설계기준서 준수 | K34: ● 지장물 우회 이설 후 되메우기 다짐 부족으로 준공 후 도로 침하 및 크랙 발생 리스크를 검토하였는가? | L34: ● 협력사 자문 내용 없음 또는 해당사항 없음
A35: 5000 | B35: 5000-3 | C35: 궤도 구간 이설 불가 지장물 방호·보강 공사 | D35: 5000-3-1 | E35: 이설 불가 지장물용 철근콘크리트 보호 슬래브 시공 | F35: ● KCS 14 20 10 (콘크리트 일반시방서) ● 보호용 철근 콘크리트 슬래브 설계 강도(24 MPa 이상) 확보 | G35: [작업 절차] 1. 사전 준비 단계: - 설계 도서 및 시방 기준을 분석하여 이설 불가 지장물용 철근콘크리트 보호 슬래브 시공 작업을 위한 현장 실측 및 경계 측량을 수행함. 2. 본 시공 단계: - 지장물 직상부 완충재(스티로폼 100mm) 포설 작업을 표준 시공 절차에 준하여 시행하며, 실시간 수평도 및 치수 공차를 관리함. 3. 검사 및 마감 단계: - 이중 철근 배근(D16@150) 및 피복 두께(80mm) 스페이서 거치 시험 및 품질 검사를 실측하고 기준값 만족 여부를 기록함. 고강도 콘크리트(24MPa 이상) 타설 및 습윤 양생 작업을 거쳐 노면 정리 및 안전 조치를 완료함. [주의사항 (하자이력 연계)] 보호 슬래브 기초 지지력 부족으로 하중 집중 시 가스관에 하중 전가되어 밸브 파손 | H35: □ 완충재 밀착 상태 및 철근 배근 간격 일치 여부 □ 콘크리트 피복 두께 및 거푸집 견고성 확인 □ 콘크리트 타설 시 진동 다짐(바이브레이터) 밀도 [집행단계 리스크 체크사항 (LLBS 연계)] □ 기초 터파기 구간의 지반 조건(연약지반)을 고려할 때 사면 경사를 유지할 부지가 충분한가? □ 도심지 협소 구간 작업 시 대형 장비 진입 불가에 따른 소형 장비 할증이 반영되었는가? □ 흙막이 앵커가 인접 사유지를 침범하는지 지적도와 대조하고, 침범 시 보상비 또는 제거식 앵커 비용을 반영했는가? □ 시종점 및 작업구 위치 하부의 지장물(송전선, 가스관) 매설 현황을 지장물도와 대조했는가? | I35: 토목 | J35: ● 관련분야 설계기준서 준수 | K35: ● 보호 콘크리트 슬래브 두께 미달 및 철근 배근 불량으로 트램 상부 통과 하중 작용 시 파손 리스크를 검토하였는가? | L35: ● 협력사 자문 내용 없음 또는 해당사항 없음
A36: 5000 | B36: 5000-4 | C36: 본선 궤도 구간 토공 굴착 및 노상 정리 | D36: 5000-4-1 | E36: 궤도 하부 구조물 정밀 굴착 및 레벨 고르기 | F36: ● KCS 11 20 15 (토공사 굴착 표준시방서) ● 백호우 정밀 굴착 높이 설계 계획고 오차 ±10mm 이내 관리 | G36: [작업 절차] 1. 사전 준비 단계: - 설계 도서 및 시방 기준을 분석하여 궤도 하부 구조물 정밀 굴착 및 레벨 고르기 작업을 위한 현장 실측 및 경계 측량을 수행함. 2. 본 시공 단계: - GPS 장착 백호우 레벨 유도 굴착 작업을 표준 시공 절차에 준하여 시행하며, 실시간 수평도 및 치수 공차를 관리함. 3. 검사 및 마감 단계: - 과굴착부 무수축 콘크리트(또는 소일시멘트) 보정 시험 및 품질 검사를 실측하고 기준값 만족 여부를 기록함. 인력 요철 다듬기 및 콤팩터 노면 다짐 작업을 거쳐 노면 정리 및 안전 조치를 완료함. [주의사항 (하자이력 연계)] 과굴착 구간 양질의 토사 되메우기 생략으로 하중 작용 시 불균일 침하 | H36: □ 설계 계획고 대비 굴착 심도 오차(±10mm 이내) □ 과굴착부 양질의 토사 또는 콘크리트 채움 여부 □ 바닥 평탄도 및 배수 유도 종단 경사 확인 [집행단계 리스크 체크사항 (LLBS 연계)] □ 자재 발주 전 도면상 명기된 배수 관련 부속 자재가 내역에 있는지 전수 조사했는가? □ 접속부 시공 전 배수판/동판 설치 상세를 작업자에게 교육했는가? □ 가설 구조물 철거 시 발생할 폐기물 물량을 예측하여 예산에 반영했는가? □ 준공 정산 시 누락되기 쉬운 철거 비용을 미리 확보했는가? | I36: 토목 | J36: ● 관련분야 설계기준서 준수 | K36: ● 종단 경사 오차로 계획고보다 낮게 굴착하여 궤도 기초 콘크리트 물량 과다 유입 및 단차 리스크를 검토하였는가? | L36: ● 협력사 자문 내용 없음 또는 해당사항 없음
A37: 5000 | B37: 5000-5 | C37: 본선 노반(H=200mm) 다짐 | D37: 5000-5-1 | E37: 노반 층다짐 및 진동 롤러 전압 시공 | F37: ● KCS 11 20 20 (도로 다짐 및 다짐도 검사) ● 10톤 진동 롤러 층다짐 두께 200mm 단위 포설 및 다짐도 98% 이상 확보 | G37: [상세 작업 절차 - 정밀 관리] 1. 노상 기초 지반 검사 및 청소: - 노반 다짐 대상지의 잡석 및 유기물을 제거하고, 지반 침하 우려가 있는 연약 지반 구간은 모래 치환 또는 석회 혼합 공법을 선행하여 정리함. 2. 다짐 토사 포설 및 함수비 조절: - 양질의 토사를 모터 그레이더를 사용하여 포설하되, 1회 다짐 후 두께가 200mm 이내(포설 두께 약 250mm)가 되도록 두께 게이지로 관리함. 현장 함수비 측정을 통해 최적 함수비(OMC ±2% 범위)를 유지하기 위해 살수 또는 건조 작업을 시행함. 3. 10톤 진동 롤러 중첩 다짐: - 10톤 이상급 탠덤 진동 롤러를 투입하여 중심선에서 외곽 방향으로 전압함. 롤러 주행 속도를 3~4 km/h로 제한하고, 차륜 중첩 폭(최소 50cm 이상)을 유지하며 왕복 6회 이상 전압을 실시함. 4. 현장 들밀도 및 다짐도 실측: - 다짐 완료 노면에서 모래치환법(KS F 2311) 들밀도 시험을 실시하여 현장 건조밀도를 측정하고, 다짐도 기준치(98% 이상) 만족 여부를 판별함. 5. 횡단 구배(2%) 정리 및 우수 유입 방지: - 노반 횡단 구배(2%)를 확보하여 표면 배수를 유도하고, 다짐면 상부에 가설 비닐시트를 포설하여 우천 시 다짐층 연화 및 유실을 헷지함. [주의사항 (하자이력 연계)] 함수비 조절 실패로 진동 다짐 시 스펀징(지반 꿀렁임) 현상 방치, 지내력 저하 | H37: □ 층다짐 두께(200mm) 준수 및 최적함수비 유지 상태 □ 진동 롤러 왕복 횟수 및 겹침 폭(50cm 이상) 준수 □ 들밀도시험 성적서 상 다짐도(98% 이상) 만족 [집행단계 리스크 체크사항 (LLBS 연계)] □ 특수교량(FCM 등)의 주요 구조부 설계 적정성을 착공 전 검증했는가? □ 관급자재 수급 불안정 시 사급 전환 가능성 및 비용 차이를 검토했는가? □ 케이블/행어 로프의 와류진동(Vortex Shedding) 검토가 수행되었는가? □ 제진 장치(Damper) 설치가 내역에 포함되거나 유보금으로 잡혀있는가? | I37: 토목/노반 | J37: ● 관련분야 설계기준서 준수 | K37: ● 다짐 장비 운용 횟수 부족으로 지반 변형률 기준 미달, 주행 시 선로 침하 리스크를 검토하였는가? | L37: ● 협력사 자문 내용 없음 또는 해당사항 없음
A38: 5000 | B38: 5000-5 | C38: 본선 노반(H=200mm) 다짐 | D38: 5000-5-2 | E38: 토공 노반 품질 검증 및 인수 (토목➔궤도 인계) | F38: ● KDS 11 50 15 (얕은기초 설계기준) ● Ev2 ≥ 80 MPa, Ev2/Ev1 비율 2.3 이하 만족 | G38: [작업 절차] 1. 사전 준비 단계: - 설계 도서 및 시방 기준을 분석하여 토공 노반 품질 검증 및 인수 (토목➔궤도 인계) 작업을 위한 현장 실측 및 경계 측량을 수행함. 2. 본 시공 단계: - 강화노반(쇄석 200mm) 다짐 상태에서 평판재하시험(PBT)을 수행하여 지지력 및 노반변형계수(Ev2) 적합성 검증 작업을 표준 시공 절차에 준하여 시행하며, 실시간 수평도 및 치수 공차를 관리함. 3. 검사 및 마감 단계: - 노반면 하부 횡단배수로 동결심도 이하 매설 확인 및 상면 돌출 수직 배수관 높이 사전 마킹 시험 및 품질 검사를 실측하고 기준값 만족 여부를 기록함. 토목 측으로부터 노반 인수 전 3D 토탈스테이션 정밀 측량을 통한 종횡단 기울기 및 중심선형 확인 (전시/후시각 00°-00'-08" 이내) 작업을 거쳐 노면 정리 및 안전 조치를 완료함. [주의사항 (하자이력 연계)] 종평면 종단 구배 한계값 미충족 도면을 거르지 못하여 궤도 재설계 발생 | H38: □ 평판재하시험 Ev2 계수 및 Ev2/Ev1 비 설계값 만족 여부 □ 수직 배수 파이프 상면 돌출 높이 및 마킹 일치 상태 □ 종횡단 구배 및 중심선형 오차 허용 범위 이내 도달 여부 [집행단계 리스크 체크사항 (LLBS 연계)] □ 절토 구간의 암반 등급(토사/리핑/발파) 분류 기준이 지반 조사 데이터에 근거했는가? □ 산악지/계곡부의 경우 전석(Boulder)층 출현 가능성을 고려하여 할증을 반영했는가? □ 철도보호지구 등 특수 구간 공사 시 유관기관이 요구하는 안전점검 비용이 별도로 계상되었는가? | I38: 토목/노반 | J38: ● [토질기초] 콘크리트 궤도 하부 허용 잔류침하량: 30.0mm 이하 (성토체 및 궤도구조 25mm, 열차하중 침하 5mm 합산) ● [토질기초] 흙쌓기 속도 기준: 점토층 두터운 이탄질 3.0cm/day, 보통 점토질 5.0cm/day, 얇은 점토층 10.0cm/day 이하 | K38: ● 함수비 조율 실패로 강화 노반 다짐도 불량, 궤도 콘크리트 슬래브 균열 전이 리스크를 검토하였는가? | L38: ● 협력사 자문 내용 없음 또는 해당사항 없음
A39: 5000 | B39: 5000-6 | C39: 본선 궤도/노반 매설물 및 기초층 설치 | D39: 5000-6-1 | E39: 도상안정층(HSB) 시공 및 유도줄눈 설치 | F39: ● KCS 14 20 10 (콘크리트 일반시방서) ● fck=18MPa HSB 콘크리트 두께 100mm 확보, 유도줄눈 매 5m 간격 설치 | G39: [작업 절차] 1. 사전 준비 단계: - 설계 도서 및 시방 기준을 분석하여 도상안정층(HSB) 시공 및 유도줄눈 설치 작업을 위한 현장 실측 및 경계 측량을 수행함. 2. 본 시공 단계: - 강화노반 청소 후 버림 콘크리트를 타설하며, 상부 도상 콘크리트 접합력 증대를 위해 기계식 솔 또는 레이크를 통한 거칠기 시공(Roughness) 실시 작업을 표준 시공 절차에 준하여 시행하며, 실시간 수평도 및 치수 공차를 관리함. 3. 검사 및 마감 단계: - 두께 100mm 내외의 도상안정층(HSB) 콘크리트 타설 및 균일 수평 마감 시험 및 품질 검사를 실측하고 기준값 만족 여부를 기록함. 건조수축 균열 방지를 위해 타설 완료 후 매 5m 간격으로 깊이 30mm 이상의 균열유도줄눈을 컷팅 설치 작업을 거쳐 노면 정리 및 안전 조치를 완료함. [주의사항 (하자이력 연계)] 무근 HSB 층에 균열 유도줄눈 설치 누락 시 불규칙 수축 균열이 상부 TCL층으로 전이 발생 | H39: □ 버림 콘크리트 상면 표면 거칠기 가공 상태 □ HSB 두께(100mm) 및 콘크리트 설계 강도 만족 여부 □ 균열유도줄눈 간격(5m) 및 컷팅 깊이 적정 여부 [집행단계 리스크 체크사항 (LLBS 연계)] □ 교량 시공용 대형 크레인(200ton 이상)의 아웃트리거 전개 폭을 고려하여 가교 폭이나 작업대(Staging)가 반영되었는가? □ 흙막이 가시설과 본 구조물 사이에 거푸집 설치 및 작업자 이동 공간(최소 1m 이상)이 확보되었는가? □ 특수 교각(Y형, V형) 시공 시 상부 하중을 지지할 가설 벤트가 내역에 있는가? □ 벤트 기초의 지지력 검토가 수행되었는가? | I39: 토목 | J39: ● 관련분야 설계기준서 준수 | K39: ● 무근 콘크리트 타설 시 수평도 오차로 궤도 블록 거치 시 하부 충전재 두께 불균일 리스크를 검토하였는가? | L39: ● [HSB유도줄눈] 보조도상 콘크리트(HSB) 층 매립 시 건조 수축 균열이 상부 도상 콘크리트로 전이되는 것을 막기 위해 매 5m 간격 균열유도줄눈을 반드시 반영할 것
A40: 5000 | B40: 5000-7 | C40: 홈레일(Grooved Rail) 부설 및 검수 | D40: 5000-7-1 | E40: 반-PC 슬래브 배열 설치 및 스핀들 1차 정렬 | F40: ● KCS 14 20 53 (프리캐스트 콘크리트) ● 반-PC 슬래브 판넬 규격 오차 관리 및 거치 레벨 ±5mm 이내 | G40: [상세 작업 절차 - 정밀 관리] 1. HSB 기초 콘크리트면 정밀 측량: - 하부 도상 안정층(HSB) 콘크리트면의 중심선 및 높이를 광파기로 측정하여 궤도 중심선 가이드 라인을 노면에 스프레이 마킹함. 2. 반-PC 슬래브 크레인 배열 안착: - 공장에서 사전 제작된 반-PC 슬래브 블록(중량 약 5톤)을 현장으로 반입하여 검수하고, 25톤 크레인을 사용하여 마킹된 중심선 가이드를 따라 10mm 오차 이내로 순차 배열 안착시킴. 3. 조인트 고무 댐퍼 및 연결재 삽입: - PC 슬래브 블록 간 접합 조인트에 신축 거동 흡수용 탄성 고무 댐퍼를 삽입하고, 강결용 철근 다웰바를 슬래브 홀에 밀입함. 4. 레일 거치 및 스핀들 장치 세팅: - 배열된 슬래브 상부 요철부에 그루브 레일을 거치하고, 정밀 조정용 스핀들(Spindle) 지그 장치를 레일 양측 및 하부에 체결함. 5. 수평 및 궤간 1차 러프 정렬: - 스핀들 볼트를 조정하여 레일의 높이를 대략적으로 맞추고, 궤간 측정 게이지(Gauge)를 활용하여 궤간 오차를 ±5mm 이내로 1차 정렬하여 임시 고정함. [주의사항 (하자이력 연계)] 슬래브 인양 시 와이어 각도 불량으로 모서리 파손 및 야적 시 수평 지반 관리 부실로 인한 판넬 뒤틀림 변형 발생 | H40: □ 반-PC 슬래브 거치 중심선 및 종단 레벨 오차 범위 확인 □ 스핀들 조정 장치 나사산 손상 유무 및 작동 상태 □ 슬래브 조인트부 틈새 규격 및 배열 수평도 상태 [집행단계 리스크 체크사항 (LLBS 연계)] □ 교량 시공용 대형 크레인(200ton 이상)의 아웃트리거 전개 폭을 고려하여 가교 폭이나 작업대(Staging)가 반영되었는가? □ 항타기 등 대형 장비의 진입로 폭과 회전 반경이 현장 여건(농로, 마을길)과 부합하는가? □ Steel Box 내부 제습 설비 가동 전 부식 방지를 위한 임시 도장(Shop Primer)이 반영되었는가? □ 강교 인양용 러그(Lug) 상세가 실제 투입될 크레인 및 와이어 각도와 호환되는가? | I40: 토목 | J40: ● 관련분야 설계기준서 준수 | K40: ● 그루브레일 밴딩 곡률 반경 오차로 현장 조립 시 선형 뒤틀림 및 궤간 확장 불가 리스크를 검토하였는가? (궤도 곡선 밴딩 [4] 연계) | L40: ● [슬래브적치] 프리캐스트 반-PC 슬래브의 현장 반입 및 적치 시 균일한 수평 지지대를 배치하여 슬래브 자체의 비틀림 변형 및 모서리 깨짐을 사전 방지할 것
A41: 5000 | B41: 5000-7 | C41: 홈레일(Grooved Rail) 부설 및 검수 | D41: 5000-7-2 | E41: TCL 거푸집 가설 및 슬래브 정밀 선형 조정 | F41: ● KCS 21 10 00 (거푸집공사 표준시방서) ● 슬래브 수평/고저 및 중심선형 정밀 오차 ±2mm 이내 | G41: [상세 작업 절차 - 정밀 관리] 1. 거푸집 강제 패널 설치 및 고정: - 도상 콘크리트(TCL) 타설을 위한 양측 강제 거푸집 패널을 가설하되, 콘크리트 타설 시 측압에 견디도록 지지대(Stay) 및 앵커 핀을 0.5m 간격으로 견고히 바닥 HSB에 앵커 고정함. 2. 정밀 측량 타겟(Prism) 세팅: - 레일 상면에 전용 미니 프리즘 타겟을 부착하고, 0.5mm 정밀도를 가진 자동 추적 3D 토탈스테이션(GEDO 시스템 등)을 기지점 배후 측량으로 세팅함. 3. 3D 정밀 얼라인먼트 조정: - 실시간 토탈스테이션 계측 데이터와 철도 선형 모델 데이터를 비교하며 스핀들 조정 볼트 및 유압 정밀 자키를 미세 조작함. 4. 허용오차 정밀 검증: - 궤간(±1.5mm 이내), 수평(±1.5mm 이내), 줄틀림 및 면틀림 오차가 허용 한계값 내에 도달할 때까지 조정 작업을 반복 시행하고 락너트로 완전 고정함. 5. 변형 방지 지그(Tie-Bar) 체결: - 콘크리트 타설 중 레일이 측압에 의해 밀리는 현상을 방지하기 위해 궤간 유지용 가설 타이바(Tie-Bar) 지그를 1.0m 간격으로 추가 조임 체결하고 거푸집 틈새 실링 작업을 시행함. [주의사항 (하자이력 연계)] 정밀 측량 오차 누적으로 곡선 반경 미세 뒤틀림이 발생하여 차량 안착 시 단차 오차(±3mm 초과) 재시공 발생 | H41: □ 측면 거푸집 수직도 및 타설 측압 대비 수평 버팀목 보강 상태 □ 정밀 측량 결과 궤도 수평/고저 및 중심선형 오차 허용값 충족 여부 □ 스핀들 락너트 체결 및 고정 상태 [집행단계 리스크 체크사항 (LLBS 연계)] □ 가시설 굴착 심도가 지하수위 아래에 위치하는가? □ 토류판 적용 시 차수 그라우팅 비용이 반영되었는가? □ 특수 교각(Y형, 아치형) 시공 시 작업자 발판 및 거푸집 지지를 위한 가설 벤트가 반영되었는가? □ 흙막이 가시설과 본 구조물 사이에 거푸집 설치 및 작업자 이동 공간(최소 1m 이상)이 확보되었는가? | I41: 토목 | J41: ● [선로설계] 궤간 및 캔트: 표준 궤간 1,435mm 확보, 캔트는 적용 안함(무캔트 표준 적용) ● [구조분야] 차량횡하중: 축중의 20%를 레일면 높이에서 교축 직각 방향으로 고려 ● [구조분야] 원심하중: 레일상면 1.5m 높이에 곡선 바깥쪽 수평 작용 (충격계수 미고려) ● [구조분야] 시동/제동하중: 레일 윗면에 레일방향(교축방향) 수평 작용 (높이 1.5m, 시동 0.27+0.95xL/Lv x T, 제동 0.27+1.00xL/Lv x T) | K41: ● 정밀 측량 생략 및 지지 불량으로 궤간·수평·줄틀림 오차가 허용치(±3mm)를 초과해, 콘크리트 경화 후 도상을 전면 재시공할 리스크를 검토하였는가? (궤도 단면계획 [49]) | L41: ● [레일밴딩] 현장 야적장에서 직접 밴딩 시 그루브레일 복부 가압 과정의 비틀림 제어 숙련도 확보가 핵심이며, 밴딩 끝단 로스(약 700mm)에 대비한 3~5% 할증 설계 검토 ● [선형조정] 슬래브 내장 스핀들 조정 시 3D 측량 정밀도 확보를 위해 주간 온도 변화에 따른 팽창 수축 보정치를 감안하여 조정할 것
A42: 5000 | B42: 5000-7 | C42: 홈레일(Grooved Rail) 부설 및 검수 | D42: 5000-7-3 | E42: 도상 콘크리트(TCL)층 정밀 타설 및 습윤 양생 | F42: ● KCS 14 20 10 (콘크리트 일반시방서) ● fck=30MPa 강도 궤도도상용 콘크리트, 타설 후 최소 7일간 습윤 양생 | G42: [상세 작업 절차 - 정밀 관리] 1. 콘크리트 배합 설계 검수 및 슬럼프 측정: - 현장 반입 레미콘 배합 스펙(설계 강도 30 MPa 이상, 슬럼프 120±20mm, 공기량 4.5±1.5%)을 출하 전표로 검수하고, 레미콘 트럭별로 현장 슬럼프 및 공기량 시험을 실시하여 기록함. 2. 슈트 타설 및 바이브레이터 다짐: - 레일을 고정한 스핀들 지그 장치가 흔들리지 않도록 콘크리트를 양측에서 대칭으로 서서히 주입함. 고주파 봉상 진동기(바이브레이터)를 삽입하되, 철근 및 레일 고정 볼트에 직접 접촉하지 않도록 30cm 간격으로 수직 삽입 다짐(수포 제거)함. 3. 표면 마감 및 배수 횡단경사 형성: - 콘크리트 표면을 밀밀하게 그레이팅 흙손으로 마감하고, 노면수 고임 방지를 위한 외측 방향의 횡단 배수 경사(2%)를 정밀 형성함. 4. 균열 제어 수축 줄눈(Control Joint) 커팅: - 콘크리트 타설 후 초기 경화 시점(타설 완료 후 12~24시간 이내)에 설계된 5.0m 간격으로 커팅기로 균열 유도 줄눈(폭 5mm, 깊이 50mm)을 정밀 커팅함. 5. 습윤 양생포 가설 및 살수 관리: - 콘크리트 응결 완료 즉시 표면에 양생 시트(부직포)를 밀착 포설하고, 양생 온도를 15~25도로 유지하며 최소 7일간 살수하여 습윤 양생(건조 수축 균열 방지) 상태를 유지함. [주의사항 (하자이력 연계)] 고습도/저온 시 수밀성 파손 및 타설 초기 보양막 훼손 시 급격한 건조수축 균열(10개소 이상 미세 균열) 하자 발생 | H42: □ 타설 전 바닥면 이물질 청소 상태 및 습윤 상태 확인 □ TCL 콘크리트 슬럼프 및 설계 강도(30MPa) 공시체 시험 결과 □ 살수 장치 가동 상태 및 표면 습윤 양생막 유지 상태 | I42: 토목 | J42: ● 관련분야 설계기준서 준수 | K42: ● 현장 용접 온도 관리 및 연마 불량으로 열처리레일 경도 저하 및 미세 균열이 남아 레일 절손(파단) 사고가 발생할 리스크를 검토하였는가? (급곡선부 마감관리 [56]) | L42: ● [수축균열] 궤도 콘크리트(TCL) 타설 시 건조수축 균열 예방 대책을 수립할 것 (위례 현장 fck=30MPa 적용 시 10개소 이상 미세 균열 하자 조치 사례 참고)
...

Sheet 지반조사
A1: L2 코드 | B1: L3 코드 | C1: L3 대공종명 | D1: L4 코드 | E1: 일정 (D-Day) | F1: 작업단위 (Level 4 Task/Activity) | G1: 주관 | H1: 협업부서 | I1: 목적 | J1: 방법 | K1: 산출물(결과) | L1: 표준서 (Standard) 요약 | M1: 표준서 파일 (HTML) | N1: 수행지침 (Guideline) 요약 | O1: 수행지침 파일 (HTML) | P1: 체크리스트 (Checklist) 요약 | Q1: 체크리스트 파일 (HTML)
A2: 9000 | B2: 9000-0 | C2: 사전준비_지반조사 | D2: 9000-0-1 | E2: 사전영업 | F2: 발주처 계획 입수(비공식) | G2: 토목사업팀 | H2: 지반조사업체, 외부지질전문가 3인이상 | I2: 발주처 기본계획 사전 검토 | J2: • 조사설계 용역 기본계획 도서 확보 여부 확인 • 핵심이슈 (미시추 사유, 지층/암반등급 조정여부 등) 확보 여부 확인 • 사업지 연접 지질/지반조사 자료 확보 여부 확인 | K2: 발주처 기본계획 보고서 | L2: 발주처 기본계획 사전 검토 | 발주처 기본계획 보고서 | M2: 👉 [더블클릭] 표준서 열기 📄 | N2: • 조사설계 용역 기본계획 도서 확보 여부 확인 • 핵심이슈 (미시추 사유, 지층/암반등급 조정여부 등) 확보 여부 확인 • 사업지 연접 지질/지반조사 자료 확보 여부 확인 | O2: 👉 [더블클릭] 수행지침 열기 📄 | P2: 1) 발주처 계획 입수(비공식) 적정성을 확인하였는가? 2) 발주처 기본계획 보고서 산출물을 확보하였는가? | Q2: 👉 [더블클릭] 체크리스트 열기 📄
A3: 9000 | B3: 9000-0 | C3: 사전준비_지반조사 | D3: 9000-0-2 | E3: 사전영업 | F3: 관심프로젝트 선정 | G3: 토목사업팀 | H3: 포스코스마트엔지니어링팀 | I3: 입수된 발주정보 평가를 통한 관심 Project 선정 | J3: • 해당 프로젝트별 발주처/경쟁동향 / 사업성평가 수행 • 기술형입찰 입찰참여 Guide Line으로 해당 프로젝트 평가 | K3: 관심사업 List | L3: 입수된 발주정보 평가를 통한 관심 Project 선정 | 관심사업 List | M3: 👉 [더블클릭] 표준서 열기 📄 | N3: • 해당 프로젝트별 발주처/경쟁동향 / 사업성평가 수행 • 기술형입찰 입찰참여 Guide Line으로 해당 프로젝트 평가 | O3: 👉 [더블클릭] 수행지침 열기 📄 | P3: 1) 관심프로젝트 선정 적정성을 확인하였는가? 2) 관심사업 List 산출물을 확보하였는가? | Q3: 👉 [더블클릭] 체크리스트 열기 📄
A4: 9000 | B4: 9000-0 | C4: 사전준비_지반조사 | D4: 9000-0-3 | E4: 사전영업 | F4: 발주처 지반조사 모니터링 | G4: 포스코스마트엔지니어링팀 | H4: 토목사업팀 | I4: 발주처 지반조사 수립업체 파악 | J4: • 발주처 지반조사업체 확인 후 당사 Pool List와 비교 • 발주처 지반조사 업체 확인팀 Contact Point 확보 | K4: 발주처 기본계획 수행 List + Contact Point List | L4: 발주처 지반조사 수립업체 파악 | 발주처 기본계획 수행 List + Contact Point List | M4: 👉 [더블클릭] 표준서 열기 📄 | N4: • 발주처 지반조사업체 확인 후 당사 Pool List와 비교 • 발주처 지반조사 업체 확인팀 Contact Point 확보 | O4: 👉 [더블클릭] 수행지침 열기 📄 | P4: 1) 발주처 지반조사 모니터링 적정성을 확인하였는가? 2) 발주처 기본계획 수행 List + Contact Point List 산출물을 확보하였는가? | Q4: 👉 [더블클릭] 체크리스트 열기 📄
A5: 9000 | B5: 9000-0 | C5: 사전준비_지반조사 | D5: 9000-0-4 | E5: 매년 1분기 | F5: 외부 지질전문가 Pool 관리 | G5: 포스코스마트엔지니어링팀 | H5: - | I5: 지반조사 품질향상을 위한 제3자 검증 수행 지반조사 전문가 Pool 관리 | J5: • Academic 전문가와 현장 전문가를 포함한 Pool 구성 • 전문가 Pool의 학력/기술사 등 경력사항(조사 15년) 확인 | K5: 외부지질전문가 Pool List | L5: 지반조사 품질향상을 위한 제3자 검증 수행 지반조사 전문가 Pool 관리 | 외부지질전문가 Pool List | M5: 👉 [더블클릭] 표준서 열기 📄 | N5: • Academic 전문가와 현장 전문가를 포함한 Pool 구성 • 전문가 Pool의 학력/기술사 등 경력사항(조사 15년) 확인 | O5: 👉 [더블클릭] 수행지침 열기 📄 | P5: 1) 외부 지질전문가 Pool 관리 적정성을 확인하였는가? 2) 외부지질전문가 Pool List 산출물을 확보하였는가? | Q5: 👉 [더블클릭] 체크리스트 열기 📄
A6: 9000 | B6: 9000-0 | C6: 사전준비_지반조사 | D6: 9000-0-5 | E6: 매년 1분기 | F6: 지반조사 Pool 관리 | G6: 외주구매팀 | H6: 포스코스마트엔지니어링팀 | I6: 발주처 계획 대응 및 개략 지반조사 결과 사전 예측을 위한 업체 관리 | J6: • 공공기관별 입찰공고 모니터링 통한 지반조사업체 입찰참여 유치(입찰 공사 여부 확인) • 업체 Pool List 갱신 여부 확인 • 지반조사업체 역량 및 기술수준 평가표 평가 여부 확인 (Pool 갱신 및 신규업체 등록) • 조사업체 강점, 장비보유 확인 • 조사업체 Network 확보 여부 확인 | K6: 조사업체 POOL/필요시 Update | L6: 발주처 계획 대응 및 개략 지반조사 결과 사전 예측을 위한 업체 관리 | 조사업체 POOL/필요시 Update | M6: 👉 [더블클릭] 표준서 열기 📄 | N6: • 공공기관별 입찰공고 모니터링 통한 지반조사업체 입찰참여 유치(입찰 공사 여부 확인) • 업체 Pool List 갱신 여부 확인 • 지반조사업체 역량 및 기술수준 평가표 평가 여부 확인 (Pool 갱신 및 신규업체... | O6: 👉 [더블클릭] 수행지침 열기 📄 | P6: 1) 지반조사 Pool 관리 적정성을 확인하였는가? 2) 조사업체 POOL/필요시 Update 산출물을 확보하였는가? | Q6: 👉 [더블클릭] 체크리스트 열기 📄
A7: 9000 | B7: 9000-0 | C7: 사전준비_지반조사 | D7: 9000-0-6 | E7: D-210 ~ D-180 | F7: 기본계획 지반조사 자료 및 R/O 정보 입수 | G7: 지반조사 협력업체 | H7: 설계 협력업체 | I7: 발주처 기본계획 및 지반조사 결과 사전 획득 | J7: • 기본계획 지반조사결과 및 실시설계 Contact을 통한 자료입수 | K7: 발주처 기본계획 보고서 및 지반조사 보고서(비공식) | L7: 발주처 기본계획 및 지반조사 결과 사전 획득 | 발주처 기본계획 보고서 및 지반조사 보고서(비공식) | M7: 👉 [더블클릭] 표준서 열기 📄 | N7: • 기본계획 지반조사결과 및 실시설계 Contact을 통한 자료입수 | O7: 👉 [더블클릭] 수행지침 열기 📄 | P7: 1) 기본계획 지반조사 자료 및 R/O 정보 입수 적정성을 확인하였는가? 2) 발주처 기본계획 보고서 및 지반조사 보고서(비공식) 산출물을 확보하였는가? | Q7: 👉 [더블클릭] 체크리스트 열기 📄
A8: 9000 | B8: 9000-0 | C8: 사전준비_지반조사 | D8: 9000-0-7 | E8: D-180 ~ D-165 | F8: 기본계획 지반조사 R/O 검토 (설계, 공정, 기획) | G8: 포스코스마트엔지니어링팀(설계), 토목수행팀(공정), 토목사업지원팀(기획) | H8: 토목견적팀 | I8: 발주처 기본계획 지반조사 문제점 검토 | J8: • 시추조사 위치, 수량 적정성 검토 • 지질이상 구간 상세 조사 여부 및 적정성 검토 확인 • 미시추 구간 지반 특성 적정성 검토확인 (측점 검토, 위치 및 물량검토) • 인근 사업 지반조사자료 비교 통해 당사 지반특성 분석 결과 Cross-check 확인 | K8: 기본계획 지반조사 검토서(설계, 공정, 기획) | L8: 발주처 기본계획 지반조사 문제점 검토 | 기본계획 지반조사 검토서(설계, 공정, 기획) | M8: 👉 [더블클릭] 표준서 열기 📄 | N8: • 시추조사 위치, 수량 적정성 검토 • 지질이상 구간 상세 조사 여부 및 적정성 검토 확인 • 미시추 구간 지반 특성 적정성 검토확인 (측점 검토, 위치 및 물량검토) • 인근 사업 지반조사자료 비교 통해 당사 지... | O8: 👉 [더블클릭] 수행지침 열기 📄 | P8: 1) 기본계획 지반조사 R/O 검토 (설계, 공정, 기획) 적정성을 확인하였는가? 2) 기본계획 지반조사 검토서(설계, 공정, 기획) 산출물을 확보하였는가? | Q8: 👉 [더블클릭] 체크리스트 열기 📄
A9: 9000 | B9: 9000-0 | C9: 사전준비_지반조사 | D9: 9000-0-8 | E9: D-165 ~ D-150 | F9: 기본계획 지반조사 R/O 종합검토 (원가) | G9: 토목견적팀 | H9: 포스코스마트엔지니어링팀(설계), 토목수행팀(공정), 토목사업지원팀(기획) | I9: 발주처 지반조사 문제점 R/O 분석 | J9: • 발주처 기본계획 지반조사 R/O별 Cost effect 분석 | K9: 기본계획 지반조사 개략 검토서 | L9: 발주처 지반조사 문제점 R/O 분석 | 기본계획 지반조사 개략 검토서 | M9: 👉 [더블클릭] 표준서 열기 📄 | N9: • 발주처 기본계획 지반조사 R/O별 Cost effect 분석 | O9: 👉 [더블클릭] 수행지침 열기 📄 | P9: 1) 기본계획 지반조사 R/O 종합검토 (원가) 적정성을 확인하였는가? 2) 기본계획 지반조사 개략 검토서 산출물을 확보하였는가? | Q9: 👉 [더블클릭] 체크리스트 열기 📄
A10: 9000 | B10: 9000-0 | C10: 사전준비_지반조사 | D10: 9000-0-9 | E10: D-150 ~ D-135 | F10: 지반조사 업체 선정 | G10: 일반구매팀 | H10: 포스코스마트엔지니어링팀 | I10: 지반조사업체 Pool 내 최적의 업체 선정 | J10: • 지반조사업체 Pool/실적 검토 및 공종별 적합성 정합 및 견적 본부 연계 검토 | K10: 지반조사 입찰 참여 Pool | L10: 지반조사업체 Pool 내 최적의 업체 선정 | 지반조사 입찰 참여 Pool | M10: 👉 [더블클릭] 표준서 열기 📄 | N10: • 지반조사업체 Pool/실적 검토 및 공종별 적합성 정합 및 견적 본부 연계 검토 | O10: 👉 [더블클릭] 수행지침 열기 📄 | P10: 1) 지반조사 업체 선정 적정성을 확인하였는가? 2) 지반조사 입찰 참여 Pool 산출물을 확보하였는가? | Q10: 👉 [더블클릭] 체크리스트 열기 📄
A11: 9000 | B11: 9000-0 | C11: 사전준비_지반조사 | D11: 9000-0-10 | E11: D-135 ~ D-120 | F11: 지반조사 업체 계약 | G11: 일반구매팀 | H11: 포스코스마트엔지니어링팀 | I11: 지반조사업체 용역 계약 | J11: • 일반구매시스템을 이용한 용역계약 | K11: 지반조사 용역 계약서 | L11: 지반조사업체 용역 계약 | 지반조사 용역 계약서 | M11: 👉 [더블클릭] 표준서 열기 📄 | N11: • 일반구매시스템을 이용한 용역계약 | O11: 👉 [더블클릭] 수행지침 열기 📄 | P11: 1) 지반조사 업체 계약 적정성을 확인하였는가? 2) 지반조사 용역 계약서 산출물을 확보하였는가? | Q11: 👉 [더블클릭] 체크리스트 열기 📄
A12: 9000 | B12: 9000-0 | C12: 사전준비_지반조사 | D12: 9000-0-11 | E12: D-135 ~ D-115 | F12: 지반조사 항목, 수량 및 위치검토 | G12: 포스코스마트엔지니어링팀 | H12: 지반조사업체 | I12: 프로젝트 정합에 부합하는 지반조사 항목 사전조사 수행, 위치 선정 | J12: • 현장답사 수행 • 공종별 실시설계에 준하여 수량 및 위치 검토 | K12: 지반조사 계획서 | L12: 프로젝트 정합에 부합하는 지반조사 항목 사전조사 수행, 위치 선정 | 지반조사 계획서 | M12: 👉 [더블클릭] 표준서 열기 📄 | N12: • 현장답사 수행 • 공종별 실시설계에 준하여 수량 및 위치 검토 | O12: 👉 [더블클릭] 수행지침 열기 📄 | P12: 1) 지반조사 항목, 수량 및 위치검토 적정성을 확인하였는가? 2) 지반조사 계획서 산출물을 확보하였는가? | Q12: 👉 [더블클릭] 체크리스트 열기 📄
... A37: 9000 | B37: 9000-0 | C37: 사전준비_지반조사 | D37: 9000-0-36 | E37: - ~ - | F37: 매뉴얼 Update | G37: 혁신실장 | H37: 현장 공무팀 | I37: 지반조사 매뉴얼 Update | J37: • 매뉴얼 Update 및 개정사항 사내공지 | K37: 지반조사 매뉴얼 | L37: 지반조사 매뉴얼 Update | 지반조사 매뉴얼 | M37: 👉 [더블클릭] 표준서 열기 📄 | N37: • 매뉴얼 Update 및 개정사항 사내공지 | O37: 👉 [더블클릭] 수행지침 열기 📄 | P37: 1) 매뉴얼 Update 적정성을 확인하였는가? 2) 지반조사 매뉴얼 산출물을 확보하였는가? | Q37: 👉 [더블클릭] 체크리스트 열기 📄

Sheet 지반조사(원본서식)
A1: ■ 매뉴얼_공통_사전준비_지반조사(기술형)
A2: No. | B2: Process | C2: 시점(When) | E2: 목적(Why) | F2: Activity 방법(How) | G2: 주관부서(Who) | H2: 협업부서 | I2: 산출물(What) | J2: 수행지침 | K2: 표준서
C3: Start | D3: Finish
A4: 공통_사전준비_지반조사(기술형)
B5: 발주처 계획 입수(비공식) | C5: 사전영업 | E5: 발주처 기본계획 사전 검토 | F5: • 조사설계 용역 기본계획 도서 확보 여부 확인 • 핵심이슈 (미시추 사유, 지층/암반등급 조정여부 등) 확보 여부 확인 • 사업지 연접 지질/지반조사 자료 확보 여부 확인 | G5: 토목사업팀 | H5: 지반조사업체, 외부지질전문가 3인이상 | I5: 발주처 기본계획 보고서
B6: 관심프로젝트 선정 | C6: 사전영업 | E6: 입수된 발주정보 평가를 통한 관심 Project 선정 | F6: • 해당 프로젝트별 발주처/경쟁동향 / 사업성평가 수행 • 기술형입찰 입찰참여 Guide Line으로 해당 프로젝트 평가 | G6: 토목사업팀 | H6: 포스코스마트엔지니어링팀 | I6: 관심사업 List
A7: 1 | B7: 발주처 지반조사 모니터링 | C7: 사전영업 | E7: 발주처 지반조사 수립업체 파악 | F7: • 발주처 지반조사업체 확인 후 당사 Pool List와 비교 • 발주처 지반조사 업체 확인팀 Contact Point 확보 | G7: 포스코스마트엔지니어링팀 | H7: 토목사업팀 | I7: 발주처 기본계획 수행 List + Contact Point List
A8: 2 | B8: 외부 지질전문가 Pool 관리 | C8: 매년 1분기 | E8: 지반조사 품질향상을 위한 제3자 검증 수행 지반조사 전문가 Pool 관리 | F8: • Academic 전문가와 현장 전문가를 포함한 Pool 구성 • 전문가 Pool의 학력/기술사 등 경력사항(조사 15년) 확인 | G8: 포스코스마트엔지니어링팀 | H8: - | I8: 외부지질전문가 Pool List
A9: 3 | B9: 지반조사 Pool 관리 | C9: 매년 1분기 | E9: 발주처 계획 대응 및 개략 지반조사 결과 사전 예측을 위한 업체 관리 | F9: • 공공기관별 입찰공고 모니터링 통한 지반조사업체 입찰참여 유치(입찰 공사 여부 확인) • 업체 Pool List 갱신 여부 확인 • 지반조사업체 역량 및 기술수준 평가표 평가 여부 확인 (Pool 갱신 및 신규업체 등록) • 조사업체 강점, 장비보유 확인 • 조사업체 Network 확보 여부 확인 | G9: 외주구매팀 | H9: 포스코스마트엔지니어링팀 | I9: 조사업체 POOL/필요시 Update
B10: 기본계획 지반조사 자료 및 R/O 정보 입수 | C10: D-210 | D10: D-180 | E10: 발주처 기본계획 및 지반조사 결과 사전 획득 | F10: • 기본계획 지반조사결과 및 실시설계 Contact을 통한 자료입수 | G10: 지반조사 협력업체 | H10: 설계 협력업체 | I10: 발주처 기본계획 보고서 및 지반조사 보고서(비공식)
B11: 기본계획 지반조사 R/O 검토 (설계, 공정, 기획) | C11: D-180 | D11: D-165 | E11: 발주처 기본계획 지반조사 문제점 검토 | F11: • 시추조사 위치, 수량 적정성 검토 • 지질이상 구간 상세 조사 여부 및 적정성 검토 확인 • 미시추 구간 지반 특성 적정성 검토확인 (측점 검토, 위치 및 물량검토) • 인근 사업 지반조사자료 비교 통해 당사 지반특성 분석 결과 Cross-check 확인 | G11: 포스코스마트엔지니어링팀(설계), 토목수행팀(공정), 토목사업지원팀(기획) | H11: 토목견적팀 | I11: 기본계획 지반조사 검토서(설계, 공정, 기획)
A12: 4 | B12: 기본계획 지반조사 R/O 종합검토 (원가) | C12: D-165 | D12: D-150 | E12: 발주처 지반조사 문제점 R/O 분석 | F12: • 발주처 기본계획 지반조사 R/O별 Cost effect 분석 | G12: 토목견적팀 | H12: 포스코스마트엔지니어링팀(설계), 토목수행팀(공정), 토목사업지원팀(기획) | I12: 기본계획 지반조사 개략 검토서
A13: 5 | B13: 지반조사 업체 선정 | C13: D-150 | D13: D-135 | E13: 지반조사업체 Pool 내 최적의 업체 선정 | F13: • 지반조사업체 Pool/실적 검토 및 공종별 적합성 정합 및 견적 본부 연계 검토 | G13: 일반구매팀 | H13: 포스코스마트엔지니어링팀 | I13: 지반조사 입찰 참여 Pool
B14: 지반조사 업체 계약 | C14: D-135 | D14: D-120 | E14: 지반조사업체 용역 계약 | F14: • 일반구매시스템을 이용한 용역계약 | G14: 일반구매팀 | H14: 포스코스마트엔지니어링팀 | I14: 지반조사 용역 계약서
A15: 6 | B15: 지반조사 항목, 수량 및 위치검토 | C15: D-135 | D15: D-115 | E15: 프로젝트 정합에 부합하는 지반조사 항목 사전조사 수행, 위치 선정 | F15: • 현장답사 수행 • 공종별 실시설계에 준하여 수량 및 위치 검토 | G15: 포스코스마트엔지니어링팀 | H15: 지반조사업체 | I15: 지반조사 계획서
A16: 7 | B16: 지반조사계획 적정성 심사의뢰 | C16: D-115 | D16: D-105 | E16: 지반조사 항목, 수량 및 위치 적정성 검토 | F16: • 지반조사 계획서 검토 및 검토 | G16: 외부지질전문가 3인 이상 | H16: 포스코스마트엔지니어링팀 | I16: 지반조사계획 의견서
B17: 지반조사 인허가 | C17: D-135 | D17: D-100 | E17: 지반조사 수행을 위한 인허가 승인 | F17: • 산지일시사용 신고(사업계획서, 지형도, 산지일시사용예정실측도, 복구계획서, 복지봉투) • 굴착행위 신고(굴착행위신고서, 위치 또는 평면도, 원상복구계획서, 토지사용 승낙서) • 하천점용 허가(위치도, 이해관계인 동의서, 수리계산서, 하천점용등, 사업자등록증) | G17: 지반조사업체 | H17: 포스코스마트엔지니어링팀 | I17: 인허가 서류
B18: 지반조사 항목, 수량 및 위치 보완 | C18: D-105 | D18: D-100 | E18: 외부지질전문가 의견을 반영한 지반조사 계획 확정 | F18: • 외부지질전문가 지반조사 의견 검토 • 입찰설계 지반조사 계획 보완 | G18: 포스코스마트엔지니어링팀 | H18: 외부지질전문가 3인 이상, 지반조사업체 | I18: 지반조사 용역 계약서
A19: 8 | B19: 지반조사 수행 | C19: D-100 | D19: D-50 | E19: 과업구간 지반여건 상세 파악 | F19: • 물리탐사 수행(전기 비저항, 탄성파탐사 등) • 시추조사 및 현장 시험 수행(공내재하시험, 실내전단시험 등) • 실내시험 수행(요동시험, 입도시험 등) | G19: 지반조사업체 | H19: 포스코스마트엔지니어링팀 | I19: 지반조사 보고서, 시추 Core 및 샘플
A20: 9 | B20: 지반조사 수렴 결과 분석 | C20: D-50 | D20: D-40 | E20: 지반조사 결과 오류 및 지반정수의 적합성 검토 | F20: • 입찰설계 지반조사 보고서 검토 • 시추조사 위치 및 심도의 적정성 검토 • 실내시험 결과 등급 적정성 검토 • 실시설계시 추가지반조사 필요구간 검토 | G20: 외부지질전문가 3인 이상 | H20: 포스코스마트엔지니어링팀, 지반조사업체 | I20: 지반조사 결과 분석 의견서
B21: 입찰설계 지반조사 R/O 검토 (설계, 원가, 공정, 기타) | C21: D-40 | D21: D-30 | E21: 입찰설계 지반조사 결과에 따른 직분야 R/O 및 Cost impact 반영 사항 검토 | F21: • 입찰설계 지반조사 결과 분석을 통한 원가 및 공정 영향 검토 • 미시추 구간 평가 및 공정 Risk 반영 사항 검토 • 지반조건을 고려한 발파공법성 여부 검토 | G21: 토목견적팀(원가), 토목수행팀(공정), 토목사업지원팀(기획) | H21: 포스코스마트엔지니어링팀 | I21: 입찰설계 지반조사 검토서(설계, 원가, 공정, 기타)
A22: 10 | B22: 지반조사 결과 R/O 종합검토 | C22: D-40 | D22: D-30 | E22: 원가 및 공정 검토 결과에 따른 입찰설계 R/O 최종 확정 | F22: • 입찰설계 지반조사 R/O별 Cost effect 분석 • 유사사업 L/L 분석, R/P 검토를 통한 실시설계시 고려사항 검토 | G22: 포스코스마트엔지니어링팀 | H22: 토목견적팀(원가), 토목수행팀(공정), 토목사업지원팀(기획) | I22: 입찰설계 R/O 검토서
B23: REM 수립 | C23: D-30 | D23: D-20 | E23: REM 차트 작성(회사의 Core Risk, T/C 공정검토 결과, 경쟁사 동향, 발주 경향) 및 보고 | F23: • Risk Profiling/Merge 방안 검토 • 공정 착공성 검토 및 T/C 검토 • 설계차별화 및 Idea Frame 검토 | G23: 포스코스마트엔지니어링팀 | H23: 토목견적팀, 토목사업지원팀 | I23: REM 회의록
A24: 11 | B24: 추가지반조사 계획 수립 | C24: D-30 | D24: D-15 | E24: R/O 분석 결과에 기반한 추가지반조사 항목 도출 | F24: • 지반조사 수렴 결과 분석보고서 검토 • 지반조사 결과 R/O 종합검토 결과 검토 | G24: 포스코스마트엔지니어링팀 | H24: 토목견적팀(원가), 토목수행팀(공정), 토목사업지원팀(기획) | I24: 추가지반조사 List
B25: 3D GPR탐사 장비 사양(차량형) 검토 | C25: D-15 | D25: D-7 | E25: 적정 추가지반조사 규명을 위한 장비 사양 검토 | F25: • 3D GPR탐사 장비 사양(차량형) - 3D Radar(노르웨이)_200~3000Hz, 2.0m~3.0m : 하상도 높음 - MIRA(스웨덴)_400~1300Hz, 1.0m~2.0m : 정밀한 입체 형상 - StreamC(이탈리아)_200~600Hz, 1.5m~3.0m : 다양한 심도, 공동 탐지 - VGPR(호주)_100~4000Hz, 2.0m~3.0m : 고속주행 데이터 획득 - Road 3D(한국)_200~3000Hz, 2.0m~3.0m : 하상도 높음, 유용특화 | G25: 현장 공무팀 | H25: 현장 공사팀 | I25: -
B26: ECRM 수립 | C26: D-15 | D26: D-7 | E26: 입찰설계 지반조사 결과에 따른 직분야 R/O 및 Cost impact 반영 사항 검토 | F26: • 입찰설계 지반조사 결과 분석을 통한 원가 및 공정 영향 검토 • 미시추 구간 평가 및 공정 Risk 반영 사항 검토 • 지반조건을 고려한 발파공법성 여부 검토 | G26: 토목견적팀(원가) | H26: 포스코스마트엔지니어링팀, 토목수행팀, 토목사업지원팀 | I26: 입찰설계 지반조사 검토서(설계, 원가, 공정, 기타)
B27: 최종 Cost 검토 / 입찰 | C27: D-7 | D27: D-0 | E27: 입찰 | F27: • 최종 R/O를 반영한 투찰내역서 작성 | G27: 토목견적팀 | H27: - | I27: 투찰내역서
A28: 12 | B28: 입찰설계 현장 인수인계 | C28: D+0 | D28: D+30 | E28: 지반조사 포함 전체 R/O 승계자료 인수인계 및 추가지반조사 계획 공유 | F28: • 최종 R/O 결과 및 입찰도서 인출 | G28: 현장소장 | H28: 토목수행팀 | I28: 인수인계서
A29: 13 | B29: 추가지반조사 수행 | C29: D+30 | D29: D+100 | E29: 미시추구간 지반조사 수행을 통한 지반 Risk Hedge | F29: • 추가 지반조사 계획 및 시점 확인 - 탄성파탐사/전기비저항탐사 등 물리탐사 추가조사 (현장 및 위치 확인) - 추가시추조사 수행(물리탐사, 시추조사) - 토질 및 암석 실내시험 수행 및 결과분석 확인 - 공종별 핵심시설(교량, 접속도로, 토공, #200m 통과점, 터널 발파/심벽진입) 확인 | G29: 지반조사업체 | H29: 현장 공사팀/공무팀, 포스코스마트엔지니어링팀, 토목수행팀 | I29: 추가 지반조사 보고서 | J29: ○ | K29: ○
A30: 14 | B30: 추가지반조사 결과 분석 | C30: D+100 | D30: D+110 | E30: 추가지반조사 결과에 기반한 최종 R/O 확정 | F30: • 외부전문가 검토 통한 지반특성 최종 Cross-check 확인 • 입찰설계 지반조사 대비 지반특성 변경구간 제원도 확인 | G30: 외부지질전문가 3인 이상 | H30: 현장 공사팀/공무팀, 포스코스마트엔지니어링팀, 토목수행팀 | I30: 추가 지반조사결과 종합보고서 | J30: ○ | K30: ○
B31: 실시설계 지반조사 R/O 검토 (설계, 원가, 공정, 기타) | C31: D+110 | D31: D+120 | E31: 실시설계 지반조사 결과에 따른 직분야 R/O 및 Cost impact 반영 사항 검토 | F31: • 실시설계 추가지반조사 결과 분석을 통한 원가 및 공정 영향 검토 • 미시추 구간 평가 및 공정 Risk 반영 사항 검토 • 지반조건을 고려한 발파공법성 검토 | G31: 포스코스마트엔지니어링팀 | H31: 현장 공사팀/품질팀/공무팀, 토목견적팀(원가), 토목수행팀(공정), 토목사업지원팀(기획) | I31: 실시설계 지반조사 검토서(설계, 원가, 공정, 기타)
A32: 15 | B32: 실시설계 추가지반조사 결과 검토 | C32: D+110 | D32: D+120 | E32: 추가지반조사 결과에 기반한 최종 R/O 확정 | F32: • 추가지반조사 결과 검토 | G32: 포스코스마트엔지니어링팀 | H32: 현장 공사팀/품질팀/공무팀, 토목견적팀(원가), 토목수행팀(공정), 토목사업지원팀(기획) | I32: 실시설계 최종 R/O
A33: 16 | B33: 최종 R/O 이행방안 수립 | C33: D+120 | D33: D+150 | E33: 최종 지반조사 결과에 따른 R/O 이행방안 수립 | F33: • Core Risk 및 Hedge 방안 수립 • Opportunity에 따른 본공 상가 추가 개선 방안 수립 | G33: 현장소장 | H33: 토목수행팀 | I33: 최종 R/O 이행계획서
A34: 17 | B34: 외부지질전문가 업무평가 | C34: - | D34: - | E34: 참여인력 전문성 평가 및 특이사항 기록 | F34: • 외부지질 전문가 업무평가서 작성 | G34: 포스코스마트엔지니어링팀 | H34: 현장 공사팀/공무팀 | I34: 외부지질 전문가 업무평가서
A35: 18 | B35: 조사업체 PM 업무평가 | C35: - | D35: - | E35: 조사업체 PM 전문성 평가 및 특이사항 기록 | F35: • 지반조사 PM 업무평가서 작성 | G35: 포스코스마트엔지니어링팀 | H35: 현장 공사팀/공무팀 | I35: PM업무평가서
A36: 19 | B36: 지반조사업체 업무평가 | C36: - | D36: - | E36: 조사업체 업무평가 및 특이사항 기록 | F36: • 협력업체 업무평가서 | G36: 현장소장 | H36: 현장 공사팀/공무팀 | I36: 협력업체 업무평가서
B37: 설계변경 LL 리포트 작성 | C37: - | D37: - | E37: 설계변경 사항 기록 | F37: • 설계변경 사유 기록관리 • 예상 R/O대비 설계변경 사항 비교 검토 | G37: 현장소장 | H37: 현장 공무팀 | I37: LL리포트
B38: 설계변경 LL 리포트 관리 | C38: - | D38: - | E38: 전체 현장 설계변경 사항 기록 | F38: • 현장별 설계변경 LL 리포트 취합 관리 | G38: 토목수행팀 | H38: 현장소장 | I38: LL리포트 List
B39: 지반조사업체 정산계약 | C39: - | D39: - | E39: 지반조사업체 정산 | F39: • 조사도 수량 Check 후 구매시스템 변경계약 수행 • 변경계약 후 정산금 집행 | G39: 일반구매팀 | H39: 현장 공무팀 | I39: 정산계약서
A40: 20 | B40: 매뉴얼 Update | C40: - | D40: - | E40: 지반조사 매뉴얼 Update | F40: • 매뉴얼 Update 및 개정사항 사내공지 | G40: 혁신실장 | H40: 현장 공무팀 | I40: 지반조사 매뉴얼

Sheet 사전토공사
A1: L2 코드 | B1: L3 코드 | C1: L3 대공종명 | D1: L4 코드 | E1: 일정 (D-Day) | F1: 작업단위 (Level 4 Task/Activity) | G1: 주관 | H1: 목적 | I1: 방법 | J1: 산출물(결과) | K1: 표준서 (Standard) 요약 | L1: 표준서 파일 (HTML) | M1: 수행지침 (Guideline) 요약 | N1: 수행지침 파일 (HTML) | O1: 체크리스트 (Checklist) 요약 | P1: 체크리스트 파일 (HTML) | Q1: 비고 | R1: 첨부서류 연계 상세 설계기준 | S1: 집행단계 리스크 체크리스트 | T1: 협력사 시공/공사관리 자문
