Workbook

Sheet 종합통계대시보드
A1: 동탄도시철도(트램) 건설공사 집행단계 엔지니어링 매뉴얼 종합 통계 대시보드
A2: ■ 11개 공종 전체 시트 동적 수식 연동 | 실시간 액티비티 및 표준서·수행지침·체크리스트 집계 대시보드 | Ver 8.0
B4: 총 관리 공종 수 | D4: 총 액티비티 (WBS) | E4: 표준서 (Standard) | F4: 수행지침 (Guideline) | G4: 체크리스트 (Checklist) | H4: 매뉴얼 총계 (Total)
B5: =COUNTA(B10:B20)&"개 공종" | D5: =D21&"개 작업" | E5: =E21&" / "&D21 | F5: =F21&" / "&D21 | G5: =G21&" / "&D21 | H5: =H21&"권"
B6: 토목·궤도·시스템 전분야 | D6: 100% WBS 코드 부여 | E6: =TEXT(E21/D21,"0.0%")&" 디지털 연계" | F6: =TEXT(F21/D21,"0.0%")&" 2D도식 탑재" | G6: =TEXT(G21/D21,"0.0%")&" 12대질문형 완비" | H6: 전 공종 3대 도서 완결
A8: 1. 11대 공종별 마스터 현황 및 실시간 수식 연동 대장
A9: 순번 | B9: 공종명 (Discipline) | C9: L3 코드 | D9: 액티비티 수 | E9: 표준서 | F9: 수행지침 | G9: 체크리스트 | H9: 매뉴얼 합계 | I9: 전체 비중 | J9: 시트 바로가기
A10: 1 | B10: 지반조사 | C10: 9000-1 | D10: =COUNTA(지반조사!G2:G100) | E10: =COUNTIF(지반조사!N2:N100, "*HYPERLINK*") | F10: =COUNTIF(지반조사!P2:P100, "*HYPERLINK*") | G10: =COUNTIF(지반조사!R2:R100, "*HYPERLINK*") | H10: =SUM(E10:G10) | I10: =D10/$D$21 | J10: =HYPERLINK("#'지반조사'!A1", "👉 [지반조사] 시트 이동 ➔")
A11: 2 | B11: 사전토공사 | C11: 9000-2 | D11: =COUNTA(사전토공사!G2:G100) | E11: =COUNTIF(사전토공사!N2:N100, "*HYPERLINK*") | F11: =COUNTIF(사전토공사!P2:P100, "*HYPERLINK*") | G11: =COUNTIF(사전토공사!R2:R100, "*HYPERLINK*") | H11: =SUM(E11:G11) | I11: =D11/$D$21 | J11: =HYPERLINK("#'사전토공사'!A1", "👉 [사전토공사] 시트 이동 ➔")
A12: 3 | B12: 지장물이설 | C12: 9000-3 | D12: =COUNTA(지장물이설!G2:G100) | E12: =COUNTIF(지장물이설!N2:N100, "*HYPERLINK*") | F12: =COUNTIF(지장물이설!P2:P100, "*HYPERLINK*") | G12: =COUNTIF(지장물이설!R2:R100, "*HYPERLINK*") | H12: =SUM(E12:G12) | I12: =D12/$D$21 | J12: =HYPERLINK("#'지장물이설'!A1", "👉 [지장물이설] 시트 이동 ➔")
A13: 4 | B13: 상부강화노반 | C13: 9000-4 | D13: =COUNTA(상부강화노반!G2:G100) | E13: =COUNTIF(상부강화노반!N2:N100, "*HYPERLINK*") | F13: =COUNTIF(상부강화노반!P2:P100, "*HYPERLINK*") | G13: =COUNTIF(상부강화노반!R2:R100, "*HYPERLINK*") | H13: =SUM(E13:G13) | I13: =D13/$D$21 | J13: =HYPERLINK("#'상부강화노반'!A1", "👉 [상부강화노반] 시트 이동 ➔")
A14: 5 | B14: 콘크리트도상 | C14: 9000-5 | D14: =COUNTA(콘크리트도상!G2:G100) | E14: =COUNTIF(콘크리트도상!N2:N100, "*HYPERLINK*") | F14: =COUNTIF(콘크리트도상!P2:P100, "*HYPERLINK*") | G14: =COUNTIF(콘크리트도상!R2:R100, "*HYPERLINK*") | H14: =SUM(E14:G14) | I14: =D14/$D$21 | J14: =HYPERLINK("#'콘크리트도상'!A1", "👉 [콘크리트도상] 시트 이동 ➔")
A15: 6 | B15: 건축 | C15: 9000-6 | D15: =COUNTA(건축!G2:G100) | E15: =COUNTIF(건축!N2:N100, "*HYPERLINK*") | F15: =COUNTIF(건축!P2:P100, "*HYPERLINK*") | G15: =COUNTIF(건축!R2:R100, "*HYPERLINK*") | H15: =SUM(E15:G15) | I15: =D15/$D$21 | J15: =HYPERLINK("#'건축'!A1", "👉 [건축] 시트 이동 ➔")
A16: 7 | B16: 신호분야 | C16: 9000-7 | D16: =COUNTA(신호!G2:G100) | E16: =COUNTIF(신호!N2:N100, "*HYPERLINK*") | F16: =COUNTIF(신호!P2:P100, "*HYPERLINK*") | G16: =COUNTIF(신호!R2:R100, "*HYPERLINK*") | H16: =SUM(E16:G16) | I16: =D16/$D$21 | J16: =HYPERLINK("#'신호'!A1", "👉 [신호] 시트 이동 ➔")
A17: 8 | B17: 전기분야 | C17: 9000-8 | D17: =COUNTA(전기!G2:G100) | E17: =COUNTIF(전기!N2:N100, "*HYPERLINK*") | F17: =COUNTIF(전기!P2:P100, "*HYPERLINK*") | G17: =COUNTIF(전기!R2:R100, "*HYPERLINK*") | H17: =SUM(E17:G17) | I17: =D17/$D$21 | J17: =HYPERLINK("#'전기'!A1", "👉 [전기] 시트 이동 ➔")
A18: 9 | B18: 통신분야 | C18: 9000-9 | D18: =COUNTA(통신!G2:G100) | E18: =COUNTIF(통신!N2:N100, "*HYPERLINK*") | F18: =COUNTIF(통신!P2:P100, "*HYPERLINK*") | G18: =COUNTIF(통신!R2:R100, "*HYPERLINK*") | H18: =SUM(E18:G18) | I18: =D18/$D$21 | J18: =HYPERLINK("#'통신'!A1", "👉 [통신] 시트 이동 ➔")
A19: 10 | B19: 기계설비·소방설비 | C19: 9000-10 | D19: =COUNTA(기계!G2:G100) | E19: =COUNTIF(기계!N2:N100, "*HYPERLINK*") | F19: =COUNTIF(기계!P2:P100, "*HYPERLINK*") | G19: =COUNTIF(기계!R2:R100, "*HYPERLINK*") | H19: =SUM(E19:G19) | I19: =D19/$D$21 | J19: =HYPERLINK("#'기계'!A1", "👉 [기계] 시트 이동 ➔")
A20: 11 | B20: 철도종합시험운행 | C20: 9000-11 | D20: =COUNTA(철도종합시운전!G2:G100) | E20: =COUNTIF(철도종합시운전!N2:N100, "*HYPERLINK*") | F20: =COUNTIF(철도종합시운전!P2:P100, "*HYPERLINK*") | G20: =COUNTIF(철도종합시운전!R2:R100, "*HYPERLINK*") | H20: =SUM(E20:G20) | I20: =D20/$D$21 | J20: =HYPERLINK("#'철도종합시운전'!A1", "👉 [철도종합시운전] 시트 이동 ➔")
A21: 합계 | B21: 11개 공종 전체 | C21: - | D21: =SUM(D10:D20) | E21: =SUM(E10:E20) | F21: =SUM(F10:F20) | G21: =SUM(G10:G20) | H21: =SUM(H10:H20) | I21: =SUM(I10:I20) | J21: 총 1,092개 매뉴얼 도서
A23: 2. D-Day 일정 추진 단계별(Timeline) 업무 분포 및 관리 목표 (수식 연동)
A24: 단계 구분 | B24: 기간 (D-Day) | C24: 주요 엔지니어링 관리 목표 | D24: 작업 수 | E24: 비중 (%)
A25: Stage 1 : 착수 전 사전준비 및 인허가 | B25: D-300 ~ D-0 | C25: 설계적정성 검토, 인허가 취득, 인터페이스 Big Room 회의, 자재공급원 승인 | D25: 169 | E25: =D25/$D$21
A26: Stage 2 : 현장 본시공 및 구조물 구축 | B26: D+1 ~ D+100 | C26: 토공/지장물이설, 상부강화노반 다짐, 콘크리트도상/궤광 조립, 건축 골조/마감 | D26: 107 | E26: =D26/$D$21
A27: Stage 3 : 시스템 설치 및 단위 기능시험 | B27: D+101 ~ D+180 | C27: 전기 수배전반 수전, LTE-R 무선 AP 설치, 기계 소방배관 수압시험, 신호 랙 조립 | D27: 8 | E27: =D27/$D$21
A28: Stage 4 : 종합시운전 및 영업 개통 | B28: D+181 ~ D+240 | C28: 속도별 시설물검증시험, 30일 영업 다이아 시운전, 운영사 인수인계 및 개통 | D28: 80 | E28: =D28/$D$21
A30: 3. 4대 주관 부문별 업무 분장(R&R) 및 조직 협업 매트릭스 (수식 연동)
A31: 주관 부문 | B31: 포함 공종 범위 | C31: 작업 수 (수식) | D31: 비중 (%) | E31: 핵심 담당 조직
A32: 토목 / 궤도 / 지반 부문 | B32: 지반조사, 사전토공사, 지장물이설, 상부강화노반, 콘크리트도상 | C32: =SUM(D10:D14) | D32: =C32/$D$21 | E32: 현장 공사팀 / 토목사업팀
A33: 건축 / 기계설비 / 소방 부문 | B33: 역사/정거장 건축, 기계설비, 소방방재설비 | C33: =D15+D19 | D33: =C33/$D$21 | E33: 건축공사팀 / 기계설비팀
A34: 시스템 (전기 / 신호 / 통신) 부문 | B34: 수배전/전차선 전기설비, T-ATP/ATO 신호, LTE-R 통신 | C34: =SUM(D16:D18) | D34: =C34/$D$21 | E34: 시스템사업팀 / 전기신호팀
A35: 개통운영 / 종합시운전 / 안전품질 부문 | B35: 사전점검, 속도별 시설물검증, 영업시운전, TS 안전관리체계, 인수인계 | C35: =D20 | D35: =C35/$D$21 | E35: 개통운영팀 / 안전품질팀

Sheet 지반조사
A1: L2 코드 | B1: L3 코드 | C1: L3 대공종명 | D1: L4 코드 | E1: 선행 | F1: 후행 | G1: 작업단위 (Level 4 Task/Activity) | H1: 일정 (D-Day) | I1: 주관 | J1: 목적 | K1: 방법 | L1: 산출물(결과) | M1: 표준서 (Standard) 요약 | N1: 표준서 파일 (HTML) | O1: 수행지침 (Guideline) 요약 | P1: 수행지침 파일 (HTML) | Q1: 체크리스트 (Checklist) 요약 | R1: 체크리스트 파일 (HTML) | S1: 비고
A2: 9000 | B2: 9000-1 | C2: 지반조사 | D2: 9000-1-1 | E2: - | F2: 9000-1-2 | G2: 발주처 계획 입수(비공식) | H2: D-90 (D-120~D-90) | I2: 토목사업팀 (협업: 지반조사업체, 외부지질전문가 3인이상) | J2: 발주처 기본계획 사전 검토 | K2: • 조사설계 용역 기본계획 도서 확보 여부 확인 • 핵심이슈 (미시추 사유, 지층/암반등급 조정여부 등) 확보 여부 확인 • 사업지 연접 지질/지반조사 자료 확보 여부 확인 | L2: 발주처 기본계획 보고서 | M2: 발주처 기본계획 사전 검토 | 발주처 기본계획 보고서 | N2: =HYPERLINK(LEFT(CELL("filename",A1),FIND("[",CELL("filename",A1))-1)&"1.지반조사/01_발주처 계획 입수(비공식)/표준서/발주처 계획 입수(비공식)_표준서.html", "표준서 열기") | O2: • 조사설계 용역 기본계획 도서 확보 여부 확인 • 핵심이슈 (미시추 사유, 지층/암반등급 조정여부 등) 확보 여부 확인 • 사업지 연접 지질/지반조사 자료 확보 여부 확인 | P2: =HYPERLINK(LEFT(CELL("filename",A1),FIND("[",CELL("filename",A1))-1)&"1.지반조사/01_발주처 계획 입수(비공식)/수행지침/발주처 계획 입수(비공식)_수행지침.html", "수행지침서 열기") | Q2: 1) 발주처 계획 입수(비공식) 적정성을 확인하였는가? 2) 발주처 기본계획 보고서 산출물을 확보하였는가? | R2: =HYPERLINK(LEFT(CELL("filename",A1),FIND("[",CELL("filename",A1))-1)&"1.지반조사/01_발주처 계획 입수(비공식)/체크리스트/발주처 계획 입수(비공식)_체크리스트.html", "체크리스트 열기")
A3: 9000 | B3: 9000-1 | C3: 지반조사 | D3: 9000-1-2 | E3: 9000-1-1 | F3: 9000-1-3, 9000-1-4, 9000-1-5 | G3: 관심프로젝트 선정 | H3: D-60 (D-80~D-60) | I3: 토목사업팀 (협업: 포스코 스마트엔지니어링팀) | J3: 입수된 발주정보 평가를 통한 관심 Project 선정 | K3: • 해당 프로젝트별 발주처/경쟁동향 / 사업성평가 수행 • 기술형입찰 입찰참여 Guide Line으로 해당 프로젝트 평가 | L3: 관심사업 List | M3: 입수된 발주정보 평가를 통한 관심 Project 선정 | 관심사업 List | N3: =HYPERLINK(LEFT(CELL("filename",A1),FIND("[",CELL("filename",A1))-1)&"1.지반조사/02_관심프로젝트 선정/표준서/관심프로젝트 선정_표준서.html", "표준서 열기") | O3: • 해당 프로젝트별 발주처/경쟁동향 / 사업성평가 수행 • 기술형입찰 입찰참여 Guide Line으로 해당 프로젝트 평가 | P3: =HYPERLINK(LEFT(CELL("filename",A1),FIND("[",CELL("filename",A1))-1)&"1.지반조사/02_관심프로젝트 선정/수행지침/관심프로젝트 선정_수행지침.html", "수행지침서 열기") | Q3: 1) 관심프로젝트 선정 적정성을 확인하였는가? 2) 관심사업 List 산출물을 확보하였는가? | R3: =HYPERLINK(LEFT(CELL("filename",A1),FIND("[",CELL("filename",A1))-1)&"1.지반조사/02_관심프로젝트 선정/체크리스트/관심프로젝트 선정_체크리스트.html", "체크리스트 열기")
A4: 9000 | B4: 9000-1 | C4: 지반조사 | D4: 9000-1-3 | E4: 9000-1-2 | F4: 9000-1-7 | G4: 발주처 지반조사 모니터링 | H4: D-60 (D-70~D-60) | I4: 포스코스마트엔지니어링팀 (협업: 토목사업팀) | J4: 발주처 지반조사 수립업체 파악 | K4: • 발주처 지반조사업체 확인 후 당사 Pool List와 비교 • 발주처 지반조사 업체 확인팀 Contact Point 확보 | L4: 발주처 기본계획 수행 List + Contact Point List | M4: 발주처 지반조사 수립업체 파악 | 발주처 기본계획 수행 List + Contact Point List | N4: =HYPERLINK(LEFT(CELL("filename",A1),FIND("[",CELL("filename",A1))-1)&"1.지반조사/03_발주처 지반조사 모니터링/표준서/발주처 지반조사 모니터링_표준서.html", "표준서 열기") | O4: • 발주처 지반조사업체 확인 후 당사 Pool List와 비교 • 발주처 지반조사 업체 확인팀 Contact Point 확보 | P4: =HYPERLINK(LEFT(CELL("filename",A1),FIND("[",CELL("filename",A1))-1)&"1.지반조사/03_발주처 지반조사 모니터링/수행지침/발주처 지반조사 모니터링_수행지침.html", "수행지침서 열기") | Q4: 1) 발주처 지반조사 모니터링 적정성을 확인하였는가? 2) 발주처 기본계획 수행 List + Contact Point List 산출물을 확보하였는가? | R4: =HYPERLINK(LEFT(CELL("filename",A1),FIND("[",CELL("filename",A1))-1)&"1.지반조사/03_발주처 지반조사 모니터링/체크리스트/발주처 지반조사 모니터링_체크리스트.html", "체크리스트 열기")
A5: 9000 | B5: 9000-1 | C5: 지반조사 | D5: 9000-1-4 | E5: 9000-1-2 | F5: 9000-1-6 | G5: 외부 지질전문가 Pool 관리 | H5: D-50 (D-60~D-50) | I5: 포스코스마트엔지니어링팀 (협업: -) | J5: 지반조사 품질향상을 위한 제3자 검증 수행 지반조사 전문가 Pool 관리 | K5: • Academic 전문가와 현장 전문가를 포함한 Pool 구성 • 전문가 Pool의 학력/기술사 등 경력사항(조사 15년) 확인 | L5: 외부지질전문가 Pool List | M5: 지반조사 품질향상을 위한 제3자 검증 수행 지반조사 전문가 Pool 관리 | 외부지질전문가 Pool List | N5: =HYPERLINK(LEFT(CELL("filename",A1),FIND("[",CELL("filename",A1))-1)&"1.지반조사/04_외부 지질전문가 Pool 관리/표준서/외부 지질전문가 Pool 관리_표준서.html", "표준서 열기") | O5: • Academic 전문가와 현장 전문가를 포함한 Pool 구성 • 전문가 Pool의 학력/기술사 등 경력사항(조사 15년) 확인 | P5: =HYPERLINK(LEFT(CELL("filename",A1),FIND("[",CELL("filename",A1))-1)&"1.지반조사/04_외부 지질전문가 Pool 관리/수행지침/외부 지질전문가 Pool 관리_수행지침.html", "수행지침서 열기") | Q5: 1) 외부 지질전문가 Pool 관리 적정성을 확인하였는가? 2) 외부지질전문가 Pool List 산출물을 확보하였는가? | R5: =HYPERLINK(LEFT(CELL("filename",A1),FIND("[",CELL("filename",A1))-1)&"1.지반조사/04_외부 지질전문가 Pool 관리/체크리스트/외부 지질전문가 Pool 관리_체크리스트.html", "체크리스트 열기")
A6: 9000 | B6: 9000-1 | C6: 지반조사 | D6: 9000-1-5 | E6: 9000-1-2 | F6: 9000-1-6 | G6: 지반조사 Pool 관리 | H6: D-80 (D-120~D-80) | I6: 외주구매팀 (협업: 포스코스마트엔지니어링팀) | J6: 발주처 계획 대응 및 개략 지반조사 결과 사전 예측을 위한 업체 관리 | K6: • 공공기관별 입찰공고 모니터링 통한 지반조사업체 입찰참여 유치(입찰 공사 여부 확인) • 업체 Pool List 갱신 여부 확인 • 지반조사업체 역량 및 기술수준 평가표 평가 여부 확인 (Pool 갱신 및 신규업체 등록) • 조사업체 강점, 장비보유 확인 • 조사업체 Network 확보 여부 확인 | L6: 조사업체 POOL/필요시 Update | M6: 발주처 계획 대응 및 개략 지반조사 결과 사전 예측을 위한 업체 관리 | 조사업체 POOL/필요시 Update | N6: =HYPERLINK(LEFT(CELL("filename",A1),FIND("[",CELL("filename",A1))-1)&"1.지반조사/05_지반조사 Pool 관리/표준서/지반조사 Pool 관리_표준서.html", "표준서 열기") | O6: • 공공기관별 입찰공고 모니터링 통한 지반조사업체 입찰참여 유치(입찰 공사 여부 확인) • 업체 Pool List 갱신 여부 확인 • 지반조사업체 역량 및 기술수준 평가표 평가 여부 확인 (Pool 갱신 및 신규업체... | P6: =HYPERLINK(LEFT(CELL("filename",A1),FIND("[",CELL("filename",A1))-1)&"1.지반조사/05_지반조사 Pool 관리/수행지침/지반조사 Pool 관리_수행지침.html", "수행지침서 열기") | Q6: 1) 지반조사 Pool 관리 적정성을 확인하였는가? 2) 조사업체 POOL/필요시 Update 산출물을 확보하였는가? | R6: =HYPERLINK(LEFT(CELL("filename",A1),FIND("[",CELL("filename",A1))-1)&"1.지반조사/05_지반조사 Pool 관리/체크리스트/지반조사 Pool 관리_체크리스트.html", "체크리스트 열기")
A7: 9000 | B7: 9000-1 | C7: 지반조사 | D7: 9000-1-6 | E7: 9000-1-4, 9000-1-5 | F7: 9000-1-10 | G7: 기본계획 지반조사 자료 및 R/O 정보 입수 | H7: D-40 | I7: 지반조사 협력업체 (협업: 설계 협력업체) | J7: 발주처 기본계획 및 지반조사 결과 사전 획득 | K7: • 기본계획 지반조사결과 및 실시설계 Contact을 통한 자료입수 | L7: 발주처 기본계획 보고서 및 지반조사 보고서(비공식) | M7: 발주처 기본계획 및 지반조사 결과 사전 획득 | 발주처 기본계획 보고서 및 지반조사 보고서(비공식) | N7: =HYPERLINK(LEFT(CELL("filename",A1),FIND("[",CELL("filename",A1))-1)&"1.지반조사/06_기본계획 지반조사 자료 및 R_O 정보 입수/표준서/기본계획 지반조사 자료 및 R_O 정보 입수_표준서.html", "표준서 열기") | O7: • 기본계획 지반조사결과 및 실시설계 Contact을 통한 자료입수 | P7: =HYPERLINK(LEFT(CELL("filename",A1),FIND("[",CELL("filename",A1))-1)&"1.지반조사/06_기본계획 지반조사 자료 및 R_O 정보 입수/수행지침/기본계획 지반조사 자료 및 R_O 정보 입수_수행지침.html", "수행지침서 열기") | Q7: 1) 기본계획 지반조사 자료 및 R/O 정보 입수 적정성을 확인하였는가? 2) 발주처 기본계획 보고서 및 지반조사 보고서(비공식) 산출물을 확보하였는가? | R7: =HYPERLINK(LEFT(CELL("filename",A1),FIND("[",CELL("filename",A1))-1)&"1.지반조사/06_기본계획 지반조사 자료 및 R_O 정보 입수/체크리스트/기본계획 지반조사 자료 및 R_O 정보 입수_체크리스트.html", "체크리스트 열기")
A8: 9000 | B8: 9000-1 | C8: 지반조사 | D8: 9000-1-7 | E8: 9000-1-3 | F8: 9000-1-8, 9000-1-9 | G8: 기본계획 지반조사 R/O 검토 (설계, 공정, 기획) | H8: D-65 (D-65~D-55) | I8: 포스코스마트엔지니어링팀(설계), 토목수행팀(공정), 토목사업지원팀(기획) (협업: 토목견적팀) | J8: 발주처 기본계획 지반조사 문제점 검토 | K8: • 시추조사 위치, 수량 적정성 검토 • 지질이상 구간 상세 조사 여부 및 적정성 검토 확인 • 미시추 구간 지반 특성 적정성 검토확인 (측점 검토, 위치 및 물량검토) • 인근 사업 지반조사자료 비교 통해 당사 지반특성 분석 결과 Cross-check 확인 | L8: 기본계획 지반조사 검토서(설계, 공정, 기획) | M8: 발주처 기본계획 지반조사 문제점 검토 | 기본계획 지반조사 검토서(설계, 공정, 기획) | N8: =HYPERLINK(LEFT(CELL("filename",A1),FIND("[",CELL("filename",A1))-1)&"1.지반조사/07_기본계획 지반조사 R_O 검토 (설계, 공정, 기획)/표준서/기본계획 지반조사 R_O 검토 (설계, 공정, 기획)_표준서.html", "표준서 열기") | O8: • 시추조사 위치, 수량 적정성 검토 • 지질이상 구간 상세 조사 여부 및 적정성 검토 확인 • 미시추 구간 지반 특성 적정성 검토확인 (측점 검토, 위치 및 물량검토) • 인근 사업 지반조사자료 비교 통해 당사 지... | P8: =HYPERLINK(LEFT(CELL("filename",A1),FIND("[",CELL("filename",A1))-1)&"1.지반조사/07_기본계획 지반조사 R_O 검토 (설계, 공정, 기획)/수행지침/기본계획 지반조사 R_O 검토 (설계, 공정, 기획)_수행지침.html", "수행지침서 열기") | Q8: 1) 기본계획 지반조사 R/O 검토 (설계, 공정, 기획) 적정성을 확인하였는가? 2) 기본계획 지반조사 검토서(설계, 공정, 기획) 산출물을 확보하였는가? | R8: =HYPERLINK(LEFT(CELL("filename",A1),FIND("[",CELL("filename",A1))-1)&"1.지반조사/07_기본계획 지반조사 R_O 검토 (설계, 공정, 기획)/체크리스트/기본계획 지반조사 R_O 검토 (설계, 공정, 기획)_체크리스트.html", "체크리스트 열기")
A9: 9000 | B9: 9000-1 | C9: 지반조사 | D9: 9000-1-8 | E9: 9000-1-7 | F9: 9000-1-10 | G9: 기본계획 지반조사 R/O 종합검토 (원가) | H9: D-40 (D-60~D-40) | I9: 토목견적팀 (협업: 포스코스마트엔지니어링팀(설계), 토목수행팀(공정), 토목사업지원팀(기획)) | J9: 발주처 지반조사 문제점 R/O 분석 | K9: • 발주처 기본계획 지반조사 R/O별 Cost effect 분석 | L9: 기본계획 지반조사 개략 검토서 | M9: 발주처 지반조사 문제점 R/O 분석 | 기본계획 지반조사 개략 검토서 | N9: =HYPERLINK(LEFT(CELL("filename",A1),FIND("[",CELL("filename",A1))-1)&"1.지반조사/08_기본계획 지반조사 R_O 종합검토 (원가)/표준서/기본계획 지반조사 R_O 종합검토 (원가)_표준서.html", "표준서 열기") | O9: • 발주처 기본계획 지반조사 R/O별 Cost effect 분석 | P9: =HYPERLINK(LEFT(CELL("filename",A1),FIND("[",CELL("filename",A1))-1)&"1.지반조사/08_기본계획 지반조사 R_O 종합검토 (원가)/수행지침/기본계획 지반조사 R_O 종합검토 (원가)_수행지침.html", "수행지침서 열기") | Q9: 1) 기본계획 지반조사 R/O 종합검토 (원가) 적정성을 확인하였는가? 2) 기본계획 지반조사 개략 검토서 산출물을 확보하였는가? | R9: =HYPERLINK(LEFT(CELL("filename",A1),FIND("[",CELL("filename",A1))-1)&"1.지반조사/08_기본계획 지반조사 R_O 종합검토 (원가)/체크리스트/기본계획 지반조사 R_O 종합검토 (원가)_체크리스트.html", "체크리스트 열기")
A10: 9000 | B10: 9000-1 | C10: 지반조사 | D10: 9000-1-9 | E10: 9000-1-7 | F10: 9000-1-10 | G10: 지반조사 업체 선정 | H10: D-30 | I10: 일반구매팀 (협업: 포스코스마트엔지니어링팀) | J10: 지반조사업체 Pool 내 최적의 업체 선정 | K10: • 지반조사업체 Pool/실적 검토 및 공종별 적합성 정합 및 견적 본부 연계 검토 | L10: 지반조사 입찰 참여 Pool | M10: 지반조사업체 Pool 내 최적의 업체 선정 | 지반조사 입찰 참여 Pool | N10: =HYPERLINK(LEFT(CELL("filename",A1),FIND("[",CELL("filename",A1))-1)&"1.지반조사/09_지반조사 업체 선정/표준서/지반조사 업체 선정_표준서.html", "표준서 열기") | O10: • 지반조사업체 Pool/실적 검토 및 공종별 적합성 정합 및 견적 본부 연계 검토 | P10: =HYPERLINK(LEFT(CELL("filename",A1),FIND("[",CELL("filename",A1))-1)&"1.지반조사/09_지반조사 업체 선정/수행지침/지반조사 업체 선정_수행지침.html", "수행지침서 열기") | Q10: 1) 지반조사 업체 선정 적정성을 확인하였는가? 2) 지반조사 입찰 참여 Pool 산출물을 확보하였는가? | R10: =HYPERLINK(LEFT(CELL("filename",A1),FIND("[",CELL("filename",A1))-1)&"1.지반조사/09_지반조사 업체 선정/체크리스트/지반조사 업체 선정_체크리스트.html", "체크리스트 열기")
A11: 9000 | B11: 9000-1 | C11: 지반조사 | D11: 9000-1-10 | E11: 9000-1-6, 9000-1-8, 9000-1-9 | F11: 9000-1-11 | G11: 지반조사 업체 계약 | H11: D-30 | I11: 일반구매팀 (협업: 포스코스마트엔지니어링팀) | J11: 지반조사업체 용역 계약 | K11: • 일반구매시스템을 이용한 용역계약 | L11: 지반조사 용역 계약서 | M11: 지반조사업체 용역 계약 | 지반조사 용역 계약서 | N11: =HYPERLINK(LEFT(CELL("filename",A1),FIND("[",CELL("filename",A1))-1)&"1.지반조사/10_지반조사 업체 계약/표준서/지반조사 업체 계약_표준서.html", "표준서 열기") | O11: • 일반구매시스템을 이용한 용역계약 | P11: =HYPERLINK(LEFT(CELL("filename",A1),FIND("[",CELL("filename",A1))-1)&"1.지반조사/10_지반조사 업체 계약/수행지침/지반조사 업체 계약_수행지침.html", "수행지침서 열기") | Q11: 1) 지반조사 업체 계약 적정성을 확인하였는가? 2) 지반조사 용역 계약서 산출물을 확보하였는가? | R11: =HYPERLINK(LEFT(CELL("filename",A1),FIND("[",CELL("filename",A1))-1)&"1.지반조사/10_지반조사 업체 계약/체크리스트/지반조사 업체 계약_체크리스트.html", "체크리스트 열기")
A12: 9000 | B12: 9000-1 | C12: 지반조사 | D12: 9000-1-11 | E12: 9000-1-10 | F12: 9000-1-12, 9000-1-13 | G12: 지반조사 항목, 수량 및 위치검토 | H12: D-30 | I12: 포스코스마트엔지니어링팀 (협업: 지반조사업체) | J12: 프로젝트 정합에 부합하는 지반조사 항목 사전조사 수행, 위치 선정 | K12: • 현장답사 수행 • 공종별 실시설계에 준하여 수량 및 위치 검토 | L12: 지반조사 계획서 | M12: 프로젝트 정합에 부합하는 지반조사 항목 사전조사 수행, 위치 선정 | 지반조사 계획서 | N12: =HYPERLINK(LEFT(CELL("filename",A1),FIND("[",CELL("filename",A1))-1)&"1.지반조사/11_지반조사 항목, 수량 및 위치검토/표준서/지반조사 항목, 수량 및 위치검토_표준서.html", "표준서 열기") | O12: • 현장답사 수행 • 공종별 실시설계에 준하여 수량 및 위치 검토 | P12: =HYPERLINK(LEFT(CELL("filename",A1),FIND("[",CELL("filename",A1))-1)&"1.지반조사/11_지반조사 항목, 수량 및 위치검토/수행지침/지반조사 항목, 수량 및 위치검토_수행지침.html", "수행지침서 열기") | Q12: 1) 지반조사 항목, 수량 및 위치검토 적정성을 확인하였는가? 2) 지반조사 계획서 산출물을 확보하였는가? | R12: =HYPERLINK(LEFT(CELL("filename",A1),FIND("[",CELL("filename",A1))-1)&"1.지반조사/11_지반조사 항목, 수량 및 위치검토/체크리스트/지반조사 항목, 수량 및 위치검토_체크리스트.html", "체크리스트 열기")
A13: 9000 | B13: 9000-1 | C13: 지반조사 | D13: 9000-1-12 | E13: 9000-1-11 | F13: 9000-1-16 | G13: 지반조사계획 적정성 심사의뢰 | H13: D-30 | I13: 외부지질전문가 3인 이상 (협업: 포스코스마트엔지니어링팀) | J13: 지반조사 항목, 수량 및 위치 적정성 검토 | K13: • 지반조사 계획서 검토 및 검토 | L13: 지반조사계획 의견서 | M13: 지반조사 항목, 수량 및 위치 적정성 검토 | 지반조사계획 의견서 | N13: =HYPERLINK(LEFT(CELL("filename",A1),FIND("[",CELL("filename",A1))-1)&"1.지반조사/12_지반조사계획 적정성 심사의뢰/표준서/지반조사계획 적정성 심사의뢰_표준서.html", "표준서 열기") | O13: • 지반조사 계획서 검토 및 검토 | P13: =HYPERLINK(LEFT(CELL("filename",A1),FIND("[",CELL("filename",A1))-1)&"1.지반조사/12_지반조사계획 적정성 심사의뢰/수행지침/지반조사계획 적정성 심사의뢰_수행지침.html", "수행지침서 열기") | Q13: 1) 지반조사계획 적정성 심사의뢰 적정성을 확인하였는가? 2) 지반조사계획 의견서 산출물을 확보하였는가? | R13: =HYPERLINK(LEFT(CELL("filename",A1),FIND("[",CELL("filename",A1))-1)&"1.지반조사/12_지반조사계획 적정성 심사의뢰/체크리스트/지반조사계획 적정성 심사의뢰_체크리스트.html", "체크리스트 열기")
A14: 9000 | B14: 9000-1 | C14: 지반조사 | D14: 9000-1-13 | E14: 9000-1-11 | F14: 9000-1-14, 9000-1-15 | G14: 지반조사 인허가 | H14: D-30 | I14: 지반조사업체 (협업: 포스코스마트엔지니어링팀) | J14: 지반조사 수행을 위한 인허가 승인 | K14: • 산지일시사용 신고(사업계획서, 지형도, 산지일시사용예정실측도, 복구계획서, 복지봉투) • 굴착행위 신고(굴착행위신고서, 위치 또는 평면도, 원상복구계획서, 토지사용 승낙서) • 하천점용 허가(위치도, 이해관계인 동의서, 수리계산서, 하천점용등, 사업자등록증) | L14: 인허가 서류 | M14: 지반조사 수행을 위한 인허가 승인 | 인허가 서류 | N14: =HYPERLINK(LEFT(CELL("filename",A1),FIND("[",CELL("filename",A1))-1)&"1.지반조사/13_지반조사 인허가/표준서/지반조사 인허가_표준서.html", "표준서 열기") | O14: • 산지일시사용 신고(사업계획서, 지형도, 산지일시사용예정실측도, 복구계획서, 복지봉투) • 굴착행위 신고(굴착행위신고서, 위치 또는 평면도, 원상복구계획서, 토지사용 승낙서) • 하천점용 허가(위치도, 이해관계인 ... | P14: =HYPERLINK(LEFT(CELL("filename",A1),FIND("[",CELL("filename",A1))-1)&"1.지반조사/13_지반조사 인허가/수행지침/지반조사 인허가_수행지침.html", "수행지침서 열기") | Q14: 1) 지반조사 인허가 적정성을 확인하였는가? 2) 인허가 서류 산출물을 확보하였는가? | R14: =HYPERLINK(LEFT(CELL("filename",A1),FIND("[",CELL("filename",A1))-1)&"1.지반조사/13_지반조사 인허가/체크리스트/지반조사 인허가_체크리스트.html", "체크리스트 열기")
A15: 9000 | B15: 9000-1 | C15: 지반조사 | D15: 9000-1-14 | E15: 9000-1-13 | F15: 9000-1-16 | G15: 지반조사 항목, 수량 및 위치 보완 | H15: D-30 | I15: 포스코스마트엔지니어링팀 (협업: 외부지질전문가 3인 이상, 지반조사업체) | J15: 외부지질전문가 의견을 반영한 지반조사 계획 확정 | K15: • 외부지질전문가 지반조사 의견 검토 • 입찰설계 지반조사 계획 보완 | L15: 지반조사 용역 계약서 | M15: 외부지질전문가 의견을 반영한 지반조사 계획 확정 | 지반조사 용역 계약서 | N15: =HYPERLINK(LEFT(CELL("filename",A1),FIND("[",CELL("filename",A1))-1)&"1.지반조사/14_지반조사 항목, 수량 및 위치 보완/표준서/지반조사 항목, 수량 및 위치 보완_표준서.html", "표준서 열기") | O15: • 외부지질전문가 지반조사 의견 검토 • 입찰설계 지반조사 계획 보완 | P15: =HYPERLINK(LEFT(CELL("filename",A1),FIND("[",CELL("filename",A1))-1)&"1.지반조사/14_지반조사 항목, 수량 및 위치 보완/수행지침/지반조사 항목, 수량 및 위치 보완_수행지침.html", "수행지침서 열기") | Q15: 1) 지반조사 항목, 수량 및 위치 보완 적정성을 확인하였는가? 2) 지반조사 용역 계약서 산출물을 확보하였는가? | R15: =HYPERLINK(LEFT(CELL("filename",A1),FIND("[",CELL("filename",A1))-1)&"1.지반조사/14_지반조사 항목, 수량 및 위치 보완/체크리스트/지반조사 항목, 수량 및 위치 보완_체크리스트.html", "체크리스트 열기")
A16: 9000 | B16: 9000-1 | C16: 지반조사 | D16: 9000-1-15 | E16: 9000-1-13 | F16: 9000-1-16 | G16: 지반조사 수행 | H16: D-30 | I16: 지반조사업체 (협업: 포스코스마트엔지니어링팀) | J16: 과업구간 지반여건 상세 파악 | K16: • 물리탐사 수행(전기 비저항, 탄성파탐사 등) • 시추조사 및 현장 시험 수행(공내재하시험, 실내전단시험 등) • 실내시험 수행(요동시험, 입도시험 등) | L16: 지반조사 보고서, 시추 Core 및 샘플 | M16: 과업구간 지반여건 상세 파악 | 지반조사 보고서, 시추 Core 및 샘플 | N16: =HYPERLINK(LEFT(CELL("filename",A1),FIND("[",CELL("filename",A1))-1)&"1.지반조사/15_지반조사 수행/표준서/지반조사 수행_표준서.html", "표준서 열기") | O16: • 물리탐사 수행(전기 비저항, 탄성파탐사 등) • 시추조사 및 현장 시험 수행(공내재하시험, 실내전단시험 등) • 실내시험 수행(요동시험, 입도시험 등) | P16: =HYPERLINK(LEFT(CELL("filename",A1),FIND("[",CELL("filename",A1))-1)&"1.지반조사/15_지반조사 수행/수행지침/지반조사 수행_수행지침.html", "수행지침서 열기") | Q16: 1) 지반조사 수행 적정성을 확인하였는가? 2) 지반조사 보고서, 시추 Core 및 샘플 산출물을 확보하였는가? | R16: =HYPERLINK(LEFT(CELL("filename",A1),FIND("[",CELL("filename",A1))-1)&"1.지반조사/15_지반조사 수행/체크리스트/지반조사 수행_체크리스트.html", "체크리스트 열기")
A17: 9000 | B17: 9000-1 | C17: 지반조사 | D17: 9000-1-16 | E17: 9000-1-12, 9000-1-14, 9000-1-15 | F17: 9000-1-17, 9000-1-22, 9000-1-24 | G17: 지반조사 수렴 결과 분석 | H17: D-30 | I17: 외부지질전문가 3인 이상 (협업: 포스코스마트엔지니어링팀, 지반조사업체) | J17: 지반조사 결과 오류 및 지반정수의 적합성 검토 | K17: • 입찰설계 지반조사 보고서 검토 • 시추조사 위치 및 심도의 적정성 검토 • 실내시험 결과 등급 적정성 검토 • 실시설계시 추가지반조사 필요구간 검토 | L17: 지반조사 결과 분석 의견서 | M17: 지반조사 결과 오류 및 지반정수의 적합성 검토 | 지반조사 결과 분석 의견서 | N17: =HYPERLINK(LEFT(CELL("filename",A1),FIND("[",CELL("filename",A1))-1)&"1.지반조사/16_지반조사 수렴 결과 분석/표준서/지반조사 수렴 결과 분석_표준서.html", "표준서 열기") | O17: • 입찰설계 지반조사 보고서 검토 • 시추조사 위치 및 심도의 적정성 검토 • 실내시험 결과 등급 적정성 검토 • 실시설계시 추가지반조사 필요구간 검토 | P17: =HYPERLINK(LEFT(CELL("filename",A1),FIND("[",CELL("filename",A1))-1)&"1.지반조사/16_지반조사 수렴 결과 분석/수행지침/지반조사 수렴 결과 분석_수행지침.html", "수행지침서 열기") | Q17: 1) 지반조사 수렴 결과 분석 적정성을 확인하였는가? 2) 지반조사 결과 분석 의견서 산출물을 확보하였는가? | R17: =HYPERLINK(LEFT(CELL("filename",A1),FIND("[",CELL("filename",A1))-1)&"1.지반조사/16_지반조사 수렴 결과 분석/체크리스트/지반조사 수렴 결과 분석_체크리스트.html", "체크리스트 열기")
A18: 9000 | B18: 9000-1 | C18: 지반조사 | D18: 9000-1-17 | E18: 9000-1-16 | F18: 9000-1-18, 9000-1-19, 9000-1-20, 9000-1-21, 9000-1-23 | G18: 입찰설계 지반조사 R/O 검토 (설계, 원가, 공정, 기타) | H18: D-30 | I18: 토목견적팀(원가), 토목수행팀(공정), 토목사업지원팀(기획) (협업: 포스코스마트엔지니어링팀) | J18: 입찰설계 지반조사 결과에 따른 직분야 R/O 및 Cost impact 반영 사항 검토 | K18: • 입찰설계 지반조사 결과 분석을 통한 원가 및 공정 영향 검토 • 미시추 구간 평가 및 공정 Risk 반영 사항 검토 • 지반조건을 고려한 발파공법성 여부 검토 | L18: 입찰설계 지반조사 검토서(설계, 원가, 공정, 기타) | M18: 입찰설계 지반조사 결과에 따른 직분야 R/O 및 Cost impact 반영 사항 검토 | 입찰설계 지반조사 검토서(설계, 원가, 공정, 기타) | N18: =HYPERLINK(LEFT(CELL("filename",A1),FIND("[",CELL("filename",A1))-1)&"1.지반조사/17_입찰설계 지반조사 R_O 검토 (설계, 원가, 공정, 기타)/표준서/입찰설계 지반조사 R_O 검토 (설계, 원가, 공정, 기타)_표준서.html", "표준서 열기") | O18: • 입찰설계 지반조사 결과 분석을 통한 원가 및 공정 영향 검토 • 미시추 구간 평가 및 공정 Risk 반영 사항 검토 • 지반조건을 고려한 발파공법성 여부 검토 | P18: =HYPERLINK(LEFT(CELL("filename",A1),FIND("[",CELL("filename",A1))-1)&"1.지반조사/17_입찰설계 지반조사 R_O 검토 (설계, 원가, 공정, 기타)/수행지침/입찰설계 지반조사 R_O 검토 (설계, 원가, 공정, 기타)_수행지침.html", "수행지침서 열기") | Q18: 1) 입찰설계 지반조사 R/O 검토 (설계, 원가, 공정, 기타) 적정성을 확인하였는가? 2) 입찰설계 지반조사 검토서(설계, 원가, 공정, 기타) 산출물을 확보하였는가? | R18: =HYPERLINK(LEFT(CELL("filename",A1),FIND("[",CELL("filename",A1))-1)&"1.지반조사/17_입찰설계 지반조사 R_O 검토 (설계, 원가, 공정, 기타)/체크리스트/입찰설계 지반조사 R_O 검토 (설계, 원가, 공정, 기타)_체크리스트.html", "체크리스트 열기")
A19: 9000 | B19: 9000-1 | C19: 지반조사 | D19: 9000-1-18 | E19: 9000-1-17 | F19: 9000-1-25, 9000-1-27 | G19: 지반조사 결과 R/O 종합검토 | H19: D-30 | I19: 포스코스마트엔지니어링팀 (협업: 토목견적팀(원가), 토목수행팀(공정), 토목사업지원팀(기획)) | J19: 원가 및 공정 검토 결과에 따른 입찰설계 R/O 최종 확정 | K19: • 입찰설계 지반조사 R/O별 Cost effect 분석 • 유사사업 L/L 분석, R/P 검토를 통한 실시설계시 고려사항 검토 | L19: 입찰설계 R/O 검토서 | M19: 원가 및 공정 검토 결과에 따른 입찰설계 R/O 최종 확정 | 입찰설계 R/O 검토서 | N19: =HYPERLINK(LEFT(CELL("filename",A1),FIND("[",CELL("filename",A1))-1)&"1.지반조사/18_지반조사 결과 R_O 종합검토/표준서/지반조사 결과 R_O 종합검토_표준서.html", "표준서 열기") | O19: • 입찰설계 지반조사 R/O별 Cost effect 분석 • 유사사업 L/L 분석, R/P 검토를 통한 실시설계시 고려사항 검토 | P19: =HYPERLINK(LEFT(CELL("filename",A1),FIND("[",CELL("filename",A1))-1)&"1.지반조사/18_지반조사 결과 R_O 종합검토/수행지침/지반조사 결과 R_O 종합검토_수행지침.html", "수행지침서 열기") | Q19: 1) 지반조사 결과 R/O 종합검토 적정성을 확인하였는가? 2) 입찰설계 R/O 검토서 산출물을 확보하였는가? | R19: =HYPERLINK(LEFT(CELL("filename",A1),FIND("[",CELL("filename",A1))-1)&"1.지반조사/18_지반조사 결과 R_O 종합검토/체크리스트/지반조사 결과 R_O 종합검토_체크리스트.html", "체크리스트 열기")
A20: 9000 | B20: 9000-1 | C20: 지반조사 | D20: 9000-1-19 | E20: 9000-1-17 | F20: 9000-1-27 | G20: REM 수립 | H20: D-30 | I20: 포스코스마트엔지니어링팀 (협업: 토목견적팀, 토목사업지원팀) | J20: REM 차트 작성(회사의 Core Risk, T/C 공정검토 결과, 경쟁사 동향, 발주 경향) 및 보고 | K20: • Risk Profiling/Merge 방안 검토 • 공정 착공성 검토 및 T/C 검토 • 설계차별화 및 Idea Frame 검토 | L20: REM 회의록 | M20: REM 차트 작성(회사의 Core Risk, T/C 공정검토 결과, 경쟁사 동향, 발주 경향) 및 보고 | REM 회의록 | N20: =HYPERLINK(LEFT(CELL("filename",A1),FIND("[",CELL("filename",A1))-1)&"1.지반조사/19_REM 수립/표준서/REM 수립_표준서.html", "표준서 열기") | O20: • Risk Profiling/Merge 방안 검토 • 공정 착공성 검토 및 T/C 검토 • 설계차별화 및 Idea Frame 검토 | P20: =HYPERLINK(LEFT(CELL("filename",A1),FIND("[",CELL("filename",A1))-1)&"1.지반조사/19_REM 수립/수행지침/REM 수립_수행지침.html", "수행지침서 열기") | Q20: 1) REM 수립 적정성을 확인하였는가? 2) REM 회의록 산출물을 확보하였는가? | R20: =HYPERLINK(LEFT(CELL("filename",A1),FIND("[",CELL("filename",A1))-1)&"1.지반조사/19_REM 수립/체크리스트/REM 수립_체크리스트.html", "체크리스트 열기")
A21: 9000 | B21: 9000-1 | C21: 지반조사 | D21: 9000-1-20 | E21: 9000-1-17 | F21: 9000-1-28, 9000-1-30 | G21: 추가지반조사 계획 수립 | H21: D-20 | I21: 포스코스마트엔지니어링팀 (협업: 토목견적팀(원가), 토목수행팀(공정), 토목사업지원팀(기획)) | J21: R/O 분석 결과에 기반한 추가지반조사 항목 도출 | K21: • 지반조사 수렴 결과 분석보고서 검토 • 지반조사 결과 R/O 종합검토 결과 검토 | L21: 추가지반조사 List | M21: R/O 분석 결과에 기반한 추가지반조사 항목 도출 | 추가지반조사 List | N21: =HYPERLINK(LEFT(CELL("filename",A1),FIND("[",CELL("filename",A1))-1)&"1.지반조사/20_추가지반조사 계획 수립/표준서/추가지반조사 계획 수립_표준서.html", "표준서 열기") | O21: • 지반조사 수렴 결과 분석보고서 검토 • 지반조사 결과 R/O 종합검토 결과 검토 | P21: =HYPERLINK(LEFT(CELL("filename",A1),FIND("[",CELL("filename",A1))-1)&"1.지반조사/20_추가지반조사 계획 수립/수행지침/추가지반조사 계획 수립_수행지침.html", "수행지침서 열기") | Q21: 1) 추가지반조사 계획 수립 적정성을 확인하였는가? 2) 추가지반조사 List 산출물을 확보하였는가? | R21: =HYPERLINK(LEFT(CELL("filename",A1),FIND("[",CELL("filename",A1))-1)&"1.지반조사/20_추가지반조사 계획 수립/체크리스트/추가지반조사 계획 수립_체크리스트.html", "체크리스트 열기")
A22: 9000 | B22: 9000-1 | C22: 지반조사 | D22: 9000-1-21 | E22: 9000-1-17 | F22: 9000-1-25, 9000-1-28 | G22: 3D GPR탐사 장비 사양(차량형) 검토 | H22: D-10 | I22: 현장 공무팀 (협업: 현장 공사팀) | J22: 적정 추가지반조사 규명을 위한 장비 사양 검토 | K22: • 3D GPR탐사 장비 사양(차량형) - 3D Radar(노르웨이)_200~3000Hz, 2.0m~3.0m : 하상도 높음 - MIRA(스웨덴)_400~1300Hz, 1.0m~2.0m : 정밀한 입체 형상 - StreamC(이탈리아)_200~600Hz, 1.5m~3.0m : 다양한 심도, 공동 탐지 - VGPR(호주)_100~4000Hz, 2.0m~3.0m : 고속주행 데이터 획득 - Road 3D(한국)_200~3000Hz, 2.0m~3.0m : 하상도 높음, 유용특화 | L22: - | M22: 적정 추가지반조사 규명을 위한 장비 사양 검토 | - | N22: =HYPERLINK(LEFT(CELL("filename",A1),FIND("[",CELL("filename",A1))-1)&"1.지반조사/21_3D GPR탐사 장비 사양(차량형) 검토/표준서/3D GPR탐사 장비 사양(차량형) 검토_표준서.html", "표준서 열기") | O22: • 3D GPR탐사 장비 사양(차량형) - 3D Radar(노르웨이)_200~3000Hz, 2.0m~3.0m : 하상도 높음 - MIRA(스웨덴)_400~1300Hz, 1.0m~2.0m : 정밀한 입체 형상 - St... | P22: =HYPERLINK(LEFT(CELL("filename",A1),FIND("[",CELL("filename",A1))-1)&"1.지반조사/21_3D GPR탐사 장비 사양(차량형) 검토/수행지침/3D GPR탐사 장비 사양(차량형) 검토_수행지침.html", "수행지침서 열기") | Q22: 1) 3D GPR탐사 장비 사양(차량형) 검토 적정성을 확인하였는가? 2) - 산출물을 확보하였는가? | R22: =HYPERLINK(LEFT(CELL("filename",A1),FIND("[",CELL("filename",A1))-1)&"1.지반조사/21_3D GPR탐사 장비 사양(차량형) 검토/체크리스트/3D GPR탐사 장비 사양(차량형) 검토_체크리스트.html", "체크리스트 열기")
A23: 9000 | B23: 9000-1 | C23: 지반조사 | D23: 9000-1-22 | E23: 9000-1-16 | F23: 9000-1-23, 9000-1-27 | G23: ECRM 수립 | H23: D+10~30 | I23: 토목견적팀(원가) (협업: 포스코스마트엔지니어링팀, 토목수행팀, 토목사업지원팀) | J23: 입찰설계 지반조사 결과에 따른 직분야 R/O 및 Cost impact 반영 사항 검토 | K23: • 입찰설계 지반조사 결과 분석을 통한 원가 및 공정 영향 검토 • 미시추 구간 평가 및 공정 Risk 반영 사항 검토 • 지반조건을 고려한 발파공법성 여부 검토 | L23: 입찰설계 지반조사 검토서(설계, 원가, 공정, 기타) | M23: 입찰설계 지반조사 결과에 따른 직분야 R/O 및 Cost impact 반영 사항 검토 | 입찰설계 지반조사 검토서(설계, 원가, 공정, 기타) | N23: =HYPERLINK(LEFT(CELL("filename",A1),FIND("[",CELL("filename",A1))-1)&"1.지반조사/22_ECRM 수립/표준서/ECRM 수립_표준서.html", "표준서 열기") | O23: • 입찰설계 지반조사 결과 분석을 통한 원가 및 공정 영향 검토 • 미시추 구간 평가 및 공정 Risk 반영 사항 검토 • 지반조건을 고려한 발파공법성 여부 검토 | P23: =HYPERLINK(LEFT(CELL("filename",A1),FIND("[",CELL("filename",A1))-1)&"1.지반조사/22_ECRM 수립/수행지침/ECRM 수립_수행지침.html", "수행지침서 열기") | Q23: 1) ECRM 수립 적정성을 확인하였는가? 2) 입찰설계 지반조사 검토서(설계, 원가, 공정, 기타) 산출물을 확보하였는가? | R23: =HYPERLINK(LEFT(CELL("filename",A1),FIND("[",CELL("filename",A1))-1)&"1.지반조사/22_ECRM 수립/체크리스트/ECRM 수립_체크리스트.html", "체크리스트 열기")
A24: 9000 | B24: 9000-1 | C24: 지반조사 | D24: 9000-1-23 | E24: 9000-1-17, 9000-1-22 | F24: 9000-1-27 | G24: 최종 Cost 검토 / 입찰 | H24: D+10~25 | I24: 토목견적팀 (협업: -) | J24: 입찰 | K24: • 최종 R/O를 반영한 투찰내역서 작성 | L24: 투찰내역서 | M24: 입찰 | 투찰내역서 | N24: =HYPERLINK(LEFT(CELL("filename",A1),FIND("[",CELL("filename",A1))-1)&"1.지반조사/23_최종 Cost 검토 _ 입찰/표준서/최종 Cost 검토 _ 입찰_표준서.html", "표준서 열기") | O24: • 최종 R/O를 반영한 투찰내역서 작성 | P24: =HYPERLINK(LEFT(CELL("filename",A1),FIND("[",CELL("filename",A1))-1)&"1.지반조사/23_최종 Cost 검토 _ 입찰/수행지침/최종 Cost 검토 _ 입찰_수행지침.html", "수행지침서 열기") | Q24: 1) 최종 Cost 검토 / 입찰 적정성을 확인하였는가? 2) 투찰내역서 산출물을 확보하였는가? | R24: =HYPERLINK(LEFT(CELL("filename",A1),FIND("[",CELL("filename",A1))-1)&"1.지반조사/23_최종 Cost 검토 _ 입찰/체크리스트/최종 Cost 검토 _ 입찰_체크리스트.html", "체크리스트 열기")
A25: 9000 | B25: 9000-1 | C25: 지반조사 | D25: 9000-1-24 | E25: 9000-1-16 | F25: 9000-1-27, 9000-1-28 | G25: 입찰설계 현장 인수인계 | H25: D+10~30 | I25: 현장소장 (협업: 토목수행팀) | J25: 지반조사 포함 전체 R/O 승계자료 인수인계 및 추가지반조사 계획 공유 | K25: • 최종 R/O 결과 및 입찰도서 인출 | L25: 인수인계서 | M25: 지반조사 포함 전체 R/O 승계자료 인수인계 및 추가지반조사 계획 공유 | 인수인계서 | N25: =HYPERLINK(LEFT(CELL("filename",A1),FIND("[",CELL("filename",A1))-1)&"1.지반조사/24_입찰설계 현장 인수인계/표준서/입찰설계 현장 인수인계_표준서.html", "표준서 열기") | O25: • 최종 R/O 결과 및 입찰도서 인출 | P25: =HYPERLINK(LEFT(CELL("filename",A1),FIND("[",CELL("filename",A1))-1)&"1.지반조사/24_입찰설계 현장 인수인계/수행지침/입찰설계 현장 인수인계_수행지침.html", "수행지침서 열기") | Q25: 1) 입찰설계 현장 인수인계 적정성을 확인하였는가? 2) 인수인계서 산출물을 확보하였는가? | R25: =HYPERLINK(LEFT(CELL("filename",A1),FIND("[",CELL("filename",A1))-1)&"1.지반조사/24_입찰설계 현장 인수인계/체크리스트/입찰설계 현장 인수인계_체크리스트.html", "체크리스트 열기")
A26: 9000 | B26: 9000-1 | C26: 지반조사 | D26: 9000-1-25 | E26: 9000-1-18, 9000-1-21 | F26: 9000-1-26, 9000-1-27 | G26: 추가지반조사 수행 | H26: D+10~30 | I26: 지반조사업체 (협업: 현장 공사팀/공무팀, 포스코스마트엔지니어링팀, 토목수행팀) | J26: 미시추구간 지반조사 수행을 통한 지반 Risk Hedge | K26: • 추가 지반조사 계획 및 시점 확인 - 탄성파탐사/전기비저항탐사 등 물리탐사 추가조사 (현장 및 위치 확인) - 추가시추조사 수행(물리탐사, 시추조사) - 토질 및 암석 실내시험 수행 및 결과분석 확인 - 공종별 핵심시설(교량, 접속도로, 토공, #200m 통과점, 터널 발파/심벽진입) 확인 | L26: 추가 지반조사 보고서 | M26: 미시추구간 지반조사 수행을 통한 지반 Risk Hedge | 추가 지반조사 보고서 | N26: =HYPERLINK(LEFT(CELL("filename",A1),FIND("[",CELL("filename",A1))-1)&"1.지반조사/25_추가지반조사 수행/표준서/추가지반조사 수행_표준서.html", "표준서 열기") | O26: • 추가 지반조사 계획 및 시점 확인 - 탄성파탐사/전기비저항탐사 등 물리탐사 추가조사 (현장 및 위치 확인) - 추가시추조사 수행(물리탐사, 시추조사) - 토질 및 암석 실내시험 수행 및 결과분석 확인 - 공종별 ... | P26: =HYPERLINK(LEFT(CELL("filename",A1),FIND("[",CELL("filename",A1))-1)&"1.지반조사/25_추가지반조사 수행/수행지침/추가지반조사 수행_수행지침.html", "수행지침서 열기") | Q26: 1) 추가지반조사 수행 적정성을 확인하였는가? 2) 추가 지반조사 보고서 산출물을 확보하였는가? | R26: =HYPERLINK(LEFT(CELL("filename",A1),FIND("[",CELL("filename",A1))-1)&"1.지반조사/25_추가지반조사 수행/체크리스트/추가지반조사 수행_체크리스트.html", "체크리스트 열기")
A27: 9000 | B27: 9000-1 | C27: 지반조사 | D27: 9000-1-26 | E27: 9000-1-25 | F27: 9000-1-27 | G27: 추가지반조사 결과 분석 | H27: D+10~30 | I27: 외부지질전문가 3인 이상 (협업: 현장 공사팀/공무팀, 포스코스마트엔지니어링팀, 토목수행팀) | J27: 추가지반조사 결과에 기반한 최종 R/O 확정 | K27: • 외부전문가 검토 통한 지반특성 최종 Cross-check 확인 • 입찰설계 지반조사 대비 지반특성 변경구간 제원도 확인 | L27: 추가 지반조사결과 종합보고서 | M27: 추가지반조사 결과에 기반한 최종 R/O 확정 | 추가 지반조사결과 종합보고서 | N27: =HYPERLINK(LEFT(CELL("filename",A1),FIND("[",CELL("filename",A1))-1)&"1.지반조사/26_추가지반조사 결과 분석/표준서/추가지반조사 결과 분석_표준서.html", "표준서 열기") | O27: • 외부전문가 검토 통한 지반특성 최종 Cross-check 확인 • 입찰설계 지반조사 대비 지반특성 변경구간 제원도 확인 | P27: =HYPERLINK(LEFT(CELL("filename",A1),FIND("[",CELL("filename",A1))-1)&"1.지반조사/26_추가지반조사 결과 분석/수행지침/추가지반조사 결과 분석_수행지침.html", "수행지침서 열기") | Q27: 1) 추가지반조사 결과 분석 적정성을 확인하였는가? 2) 추가 지반조사결과 종합보고서 산출물을 확보하였는가? | R27: =HYPERLINK(LEFT(CELL("filename",A1),FIND("[",CELL("filename",A1))-1)&"1.지반조사/26_추가지반조사 결과 분석/체크리스트/추가지반조사 결과 분석_체크리스트.html", "체크리스트 열기")
A28: 9000 | B28: 9000-1 | C28: 지반조사 | D28: 9000-1-27 | E28: 9000-1-18, 9000-1-19, 9000-1-22, 9000-1-23, 9000-1-24, 9000-1-25, 9000-1-26 | F28: 9000-1-28, 9000-1-29, 9000-1-30 | G28: 실시설계 지반조사 R/O 검토 (설계, 원가, 공정, 기타) | H28: D+10~30 | I28: 포스코스마트엔지니어링팀 (협업: 현장 공사팀/품질팀/공무팀, 토목견적팀(원가), 토목수행팀(공정), 토목사업지원팀(기획)) | J28: 실시설계 지반조사 결과에 따른 직분야 R/O 및 Cost impact 반영 사항 검토 | K28: • 실시설계 추가지반조사 결과 분석을 통한 원가 및 공정 영향 검토 • 미시추 구간 평가 및 공정 Risk 반영 사항 검토 • 지반조건을 고려한 발파공법성 검토 | L28: 실시설계 지반조사 검토서(설계, 원가, 공정, 기타) | M28: 실시설계 지반조사 결과에 따른 직분야 R/O 및 Cost impact 반영 사항 검토 | 실시설계 지반조사 검토서(설계, 원가, 공정, 기타) | N28: =HYPERLINK(LEFT(CELL("filename",A1),FIND("[",CELL("filename",A1))-1)&"1.지반조사/27_실시설계 지반조사 R_O 검토 (설계, 원가, 공정, 기타)/표준서/실시설계 지반조사 R_O 검토 (설계, 원가, 공정, 기타)_표준서.html", "표준서 열기") | O28: • 실시설계 추가지반조사 결과 분석을 통한 원가 및 공정 영향 검토 • 미시추 구간 평가 및 공정 Risk 반영 사항 검토 • 지반조건을 고려한 발파공법성 검토 | P28: =HYPERLINK(LEFT(CELL("filename",A1),FIND("[",CELL("filename",A1))-1)&"1.지반조사/27_실시설계 지반조사 R_O 검토 (설계, 원가, 공정, 기타)/수행지침/실시설계 지반조사 R_O 검토 (설계, 원가, 공정, 기타)_수행지침.html", "수행지침서 열기") | Q28: 1) 실시설계 지반조사 R/O 검토 (설계, 원가, 공정, 기타) 적정성을 확인하였는가? 2) 실시설계 지반조사 검토서(설계, 원가, 공정, 기타) 산출물을 확보하였는가? | R28: =HYPERLINK(LEFT(CELL("filename",A1),FIND("[",CELL("filename",A1))-1)&"1.지반조사/27_실시설계 지반조사 R_O 검토 (설계, 원가, 공정, 기타)/체크리스트/실시설계 지반조사 R_O 검토 (설계, 원가, 공정, 기타)_체크리스트.html", "체크리스트 열기")
A29: 9000 | B29: 9000-1 | C29: 지반조사 | D29: 9000-1-28 | E29: 9000-1-20, 9000-1-21, 9000-1-24, 9000-1-27 | F29: 9000-1-31 | G29: 실시설계 추가지반조사 결과 검토 | H29: D+10~30 | I29: 포스코스마트엔지니어링팀 (협업: 현장 공사팀/품질팀/공무팀, 토목견적팀(원가), 토목수행팀(공정), 토목사업지원팀(기획)) | J29: 추가지반조사 결과에 기반한 최종 R/O 확정 | K29: • 추가지반조사 결과 검토 | L29: 실시설계 최종 R/O | M29: 추가지반조사 결과에 기반한 최종 R/O 확정 | 실시설계 최종 R/O | N29: =HYPERLINK(LEFT(CELL("filename",A1),FIND("[",CELL("filename",A1))-1)&"1.지반조사/28_실시설계 추가지반조사 결과 검토/표준서/실시설계 추가지반조사 결과 검토_표준서.html", "표준서 열기") | O29: • 추가지반조사 결과 검토 | P29: =HYPERLINK(LEFT(CELL("filename",A1),FIND("[",CELL("filename",A1))-1)&"1.지반조사/28_실시설계 추가지반조사 결과 검토/수행지침/실시설계 추가지반조사 결과 검토_수행지침.html", "수행지침서 열기") | Q29: 1) 실시설계 추가지반조사 결과 검토 적정성을 확인하였는가? 2) 실시설계 최종 R/O 산출물을 확보하였는가? | R29: =HYPERLINK(LEFT(CELL("filename",A1),FIND("[",CELL("filename",A1))-1)&"1.지반조사/28_실시설계 추가지반조사 결과 검토/체크리스트/실시설계 추가지반조사 결과 검토_체크리스트.html", "체크리스트 열기")
A30: 9000 | B30: 9000-1 | C30: 지반조사 | D30: 9000-1-29 | E30: 9000-1-27 | F30: 9000-1-31 | G30: 최종 R/O 이행방안 수립 | H30: D+75일 이후 | I30: 현장소장 (협업: 토목수행팀) | J30: 최종 지반조사 결과에 따른 R/O 이행방안 수립 | K30: • Core Risk 및 Hedge 방안 수립 • Opportunity에 따른 본공 상가 추가 개선 방안 수립 | L30: 최종 R/O 이행계획서 | M30: 최종 지반조사 결과에 따른 R/O 이행방안 수립 | 최종 R/O 이행계획서 | N30: =HYPERLINK(LEFT(CELL("filename",A1),FIND("[",CELL("filename",A1))-1)&"1.지반조사/29_최종 R_O 이행방안 수립/표준서/최종 R_O 이행방안 수립_표준서.html", "표준서 열기") | O30: • Core Risk 및 Hedge 방안 수립 • Opportunity에 따른 본공 상가 추가 개선 방안 수립 | P30: =HYPERLINK(LEFT(CELL("filename",A1),FIND("[",CELL("filename",A1))-1)&"1.지반조사/29_최종 R_O 이행방안 수립/수행지침/최종 R_O 이행방안 수립_수행지침.html", "수행지침서 열기") | Q30: 1) 최종 R/O 이행방안 수립 적정성을 확인하였는가? 2) 최종 R/O 이행계획서 산출물을 확보하였는가? | R30: =HYPERLINK(LEFT(CELL("filename",A1),FIND("[",CELL("filename",A1))-1)&"1.지반조사/29_최종 R_O 이행방안 수립/체크리스트/최종 R_O 이행방안 수립_체크리스트.html", "체크리스트 열기")
A31: 9000 | B31: 9000-1 | C31: 지반조사 | D31: 9000-1-30 | E31: 9000-1-20, 9000-1-27 | F31: 9000-1-31 | G31: 외부지질전문가 업무평가 | H31: D+75일 이후 | I31: 포스코스마트엔지니어링팀 (협업: 현장 공사팀/공무팀) | J31: 참여인력 전문성 평가 및 특이사항 기록 | K31: • 외부지질 전문가 업무평가서 작성 | L31: 외부지질 전문가 업무평가서 | M31: 참여인력 전문성 평가 및 특이사항 기록 | 외부지질 전문가 업무평가서 | N31: =HYPERLINK(LEFT(CELL("filename",A1),FIND("[",CELL("filename",A1))-1)&"1.지반조사/30_외부지질전문가 업무평가/표준서/외부지질전문가 업무평가_표준서.html", "표준서 열기") | O31: • 외부지질 전문가 업무평가서 작성 | P31: =HYPERLINK(LEFT(CELL("filename",A1),FIND("[",CELL("filename",A1))-1)&"1.지반조사/30_외부지질전문가 업무평가/수행지침/외부지질전문가 업무평가_수행지침.html", "수행지침서 열기") | Q31: 1) 외부지질전문가 업무평가 적정성을 확인하였는가? 2) 외부지질 전문가 업무평가서 산출물을 확보하였는가? | R31: =HYPERLINK(LEFT(CELL("filename",A1),FIND("[",CELL("filename",A1))-1)&"1.지반조사/30_외부지질전문가 업무평가/체크리스트/외부지질전문가 업무평가_체크리스트.html", "체크리스트 열기")
A32: 9000 | B32: 9000-1 | C32: 지반조사 | D32: 9000-1-31 | E32: 9000-1-28, 9000-1-29, 9000-1-30 | F32: 9000-1-32 | G32: 조사업체 PM 업무평가 | H32: D+75일 이후 | I32: 포스코스마트엔지니어링팀 (협업: 현장 공사팀/공무팀) | J32: 조사업체 PM 전문성 평가 및 특이사항 기록 | K32: • 지반조사 PM 업무평가서 작성 | L32: PM업무평가서 | M32: 조사업체 PM 전문성 평가 및 특이사항 기록 | PM업무평가서 | N32: =HYPERLINK(LEFT(CELL("filename",A1),FIND("[",CELL("filename",A1))-1)&"1.지반조사/31_조사업체 PM 업무평가/표준서/조사업체 PM 업무평가_표준서.html", "표준서 열기") | O32: • 지반조사 PM 업무평가서 작성 | P32: =HYPERLINK(LEFT(CELL("filename",A1),FIND("[",CELL("filename",A1))-1)&"1.지반조사/31_조사업체 PM 업무평가/수행지침/조사업체 PM 업무평가_수행지침.html", "수행지침서 열기") | Q32: 1) 조사업체 PM 업무평가 적정성을 확인하였는가? 2) PM업무평가서 산출물을 확보하였는가? | R32: =HYPERLINK(LEFT(CELL("filename",A1),FIND("[",CELL("filename",A1))-1)&"1.지반조사/31_조사업체 PM 업무평가/체크리스트/조사업체 PM 업무평가_체크리스트.html", "체크리스트 열기")
A33: 9000 | B33: 9000-1 | C33: 지반조사 | D33: 9000-1-32 | E33: 9000-1-31 | F33: 9000-1-33 | G33: 지반조사업체 업무평가 | I33: 현장소장 (협업: 현장 공사팀/공무팀) | J33: 조사업체 업무평가 및 특이사항 기록 | K33: • 협력업체 업무평가서 | L33: 협력업체 업무평가서 | M33: 조사업체 업무평가 및 특이사항 기록 | 협력업체 업무평가서 | N33: =HYPERLINK(LEFT(CELL("filename",A1),FIND("[",CELL("filename",A1))-1)&"1.지반조사/32_지반조사업체 업무평가/표준서/지반조사업체 업무평가_표준서.html", "표준서 열기") | O33: • 협력업체 업무평가서 | P33: =HYPERLINK(LEFT(CELL("filename",A1),FIND("[",CELL("filename",A1))-1)&"1.지반조사/32_지반조사업체 업무평가/수행지침/지반조사업체 업무평가_수행지침.html", "수행지침서 열기") | Q33: 1) 지반조사업체 업무평가 적정성을 확인하였는가? 2) 협력업체 업무평가서 산출물을 확보하였는가? | R33: =HYPERLINK(LEFT(CELL("filename",A1),FIND("[",CELL("filename",A1))-1)&"1.지반조사/32_지반조사업체 업무평가/체크리스트/지반조사업체 업무평가_체크리스트.html", "체크리스트 열기")
A34: 9000 | B34: 9000-1 | C34: 지반조사 | D34: 9000-1-33 | E34: 9000-1-32 | F34: 9000-1-34 | G34: 설계변경 LL 리포트 작성 | I34: 현장소장 (협업: 현장 공무팀) | J34: 설계변경 사항 기록 | K34: • 설계변경 사유 기록관리 • 예상 R/O대비 설계변경 사항 비교 검토 | L34: LL리포트 | M34: 설계변경 사항 기록 | LL리포트 | N34: =HYPERLINK(LEFT(CELL("filename",A1),FIND("[",CELL("filename",A1))-1)&"1.지반조사/33_설계변경 LL 리포트 작성/표준서/설계변경 LL 리포트 작성_표준서.html", "표준서 열기") | O34: • 설계변경 사유 기록관리 • 예상 R/O대비 설계변경 사항 비교 검토 | P34: =HYPERLINK(LEFT(CELL("filename",A1),FIND("[",CELL("filename",A1))-1)&"1.지반조사/33_설계변경 LL 리포트 작성/수행지침/설계변경 LL 리포트 작성_수행지침.html", "수행지침서 열기") | Q34: 1) 설계변경 LL 리포트 작성 적정성을 확인하였는가? 2) LL리포트 산출물을 확보하였는가? | R34: =HYPERLINK(LEFT(CELL("filename",A1),FIND("[",CELL("filename",A1))-1)&"1.지반조사/33_설계변경 LL 리포트 작성/체크리스트/설계변경 LL 리포트 작성_체크리스트.html", "체크리스트 열기")
A35: 9000 | B35: 9000-1 | C35: 지반조사 | D35: 9000-1-34 | E35: 9000-1-33 | F35: 9000-1-35 | G35: 설계변경 LL 리포트 관리 | I35: 토목수행팀 (협업: 현장소장) | J35: 전체 현장 설계변경 사항 기록 | K35: • 현장별 설계변경 LL 리포트 취합 관리 | L35: LL리포트 List | M35: 전체 현장 설계변경 사항 기록 | LL리포트 List | N35: =HYPERLINK(LEFT(CELL("filename",A1),FIND("[",CELL("filename",A1))-1)&"1.지반조사/34_설계변경 LL 리포트 관리/표준서/설계변경 LL 리포트 관리_표준서.html", "표준서 열기") | O35: • 현장별 설계변경 LL 리포트 취합 관리 | P35: =HYPERLINK(LEFT(CELL("filename",A1),FIND("[",CELL("filename",A1))-1)&"1.지반조사/34_설계변경 LL 리포트 관리/수행지침/설계변경 LL 리포트 관리_수행지침.html", "수행지침서 열기") | Q35: 1) 설계변경 LL 리포트 관리 적정성을 확인하였는가? 2) LL리포트 List 산출물을 확보하였는가? | R35: =HYPERLINK(LEFT(CELL("filename",A1),FIND("[",CELL("filename",A1))-1)&"1.지반조사/34_설계변경 LL 리포트 관리/체크리스트/설계변경 LL 리포트 관리_체크리스트.html", "체크리스트 열기")
A36: 9000 | B36: 9000-1 | C36: 지반조사 | D36: 9000-1-35 | E36: 9000-1-34 | F36: 9000-1-36 | G36: 지반조사업체 정산계약 | I36: 일반구매팀 (협업: 현장 공무팀) | J36: 지반조사업체 정산 | K36: • 조사도 수량 Check 후 구매시스템 변경계약 수행 • 변경계약 후 정산금 집행 | L36: 정산계약서 | M36: 지반조사업체 정산 | 정산계약서 | N36: =HYPERLINK(LEFT(CELL("filename",A1),FIND("[",CELL("filename",A1))-1)&"1.지반조사/35_지반조사업체 정산계약/표준서/지반조사업체 정산계약_표준서.html", "표준서 열기") | O36: • 조사도 수량 Check 후 구매시스템 변경계약 수행 • 변경계약 후 정산금 집행 | P36: =HYPERLINK(LEFT(CELL("filename",A1),FIND("[",CELL("filename",A1))-1)&"1.지반조사/35_지반조사업체 정산계약/수행지침/지반조사업체 정산계약_수행지침.html", "수행지침서 열기") | Q36: 1) 지반조사업체 정산계약 적정성을 확인하였는가? 2) 정산계약서 산출물을 확보하였는가? | R36: =HYPERLINK(LEFT(CELL("filename",A1),FIND("[",CELL("filename",A1))-1)&"1.지반조사/35_지반조사업체 정산계약/체크리스트/지반조사업체 정산계약_체크리스트.html", "체크리스트 열기")
A37: 9000 | B37: 9000-1 | C37: 지반조사 | D37: 9000-1-36 | E37: 9000-1-35 | F37: - | G37: 매뉴얼 Update | I37: 혁신실장 (협업: 현장 공무팀) | J37: 지반조사 매뉴얼 Update | K37: • 매뉴얼 Update 및 개정사항 사내공지 | L37: 지반조사 매뉴얼 | M37: 지반조사 매뉴얼 Update | 지반조사 매뉴얼 | N37: =HYPERLINK(LEFT(CELL("filename",A1),FIND("[",CELL("filename",A1))-1)&"1.지반조사/36_매뉴얼 Update/표준서/매뉴얼 Update_표준서.html", "표준서 열기") | O37: • 매뉴얼 Update 및 개정사항 사내공지 | P37: =HYPERLINK(LEFT(CELL("filename",A1),FIND("[",CELL("filename",A1))-1)&"1.지반조사/36_매뉴얼 Update/수행지침/매뉴얼 Update_수행지침.html", "수행지침서 열기") | Q37: 1) 매뉴얼 Update 적정성을 확인하였는가? 2) 지반조사 매뉴얼 산출물을 확보하였는가? | R37: =HYPERLINK(LEFT(CELL("filename",A1),FIND("[",CELL("filename",A1))-1)&"1.지반조사/36_매뉴얼 Update/체크리스트/매뉴얼 Update_체크리스트.html", "체크리스트 열기")

Sheet 사전토공사
A1: L2 코드 | B1: L3 코드 | C1: L3 대공종명 | D1: L4 코드 | E1: 선행 | F1: 후행 | G1: 작업단위 (Level 4 Task/Activity) | H1: 일정 (D-Day) | I1: 주관 | J1: 목적 | K1: 방법 | L1: 산출물(결과) | M1: 표준서 (Standard) 요약 | N1: 표준서 파일 (HTML) | O1: 수행지침 (Guideline) 요약 | P1: 수행지침 파일 (HTML) | Q1: 체크리스트 (Checklist) 요약 | R1: 체크리스트 파일 (HTML) | S1: 비고
A2: 9000 | B2: 9000-2 | C2: 사전토공사 | D2: 9000-2-1 | E2: - | F2: 9000-2-2, 9000-2-3 | G2: Site Survey | H2: D-90 (D-120~D-90) | I2: 현장 공사팀 | J2: KDS 47 10 00 철도지반 설계기준 | 현장 가설 둔차선, 용지 경계 및 원지반 고저차 3D 레벨 현측 | 토공사 사전 현장 조사 보고서 | K2: 1) 현장 가설 도로 및 용지 경계 현측 ➔ 2) 광학 레벨 원지반 고저차 측정 ➔ 3) 진입 도로 장애 요소 매핑 ➔ 4) 현장 조사 보고서 감리 제출 | L2: 가설 도로 폭/구배 현측, 원지반 고저차 레벨 측량 및 3D BIM 도면 오차 점검 (현장 조사 보고서) | M2: KDS 47 10 00 철도지반 설계기준 | 현장 가설 둔차선, 용지 경계 및 원지반 고저차 3D 레벨 현측 | 토공사 사전 현장 조사 보고서 | N2: =HYPERLINK(LEFT(CELL("filename",A1),FIND("[",CELL("filename",A1))-1)&"2.사전토공사\1_Site Survey\표준서\Site Survey_표준서.html", "👉 [클릭] 표준서 열기 📄") | O2: 1) 현장 가설 도로 및 용지 경계 현측 ➔ 2) 광학 레벨 원지반 고저차 측정 ➔ 3) 진입 도로 장애 요소 매핑 ➔ 4) 현장 조사 보고서 감리 제출 | P2: =HYPERLINK(LEFT(CELL("filename",A1),FIND("[",CELL("filename",A1))-1)&"2.사전토공사\1_Site Survey\수행지침\Site Survey_수행지침.html", "👉 [클릭] 수행지침 열기 📄") | Q2: 가설 도로 폭/구배 현측, 원지반 고저차 레벨 측량 및 3D BIM 도면 오차 점검 (현장 조사 보고서) | R2: =HYPERLINK(LEFT(CELL("filename",A1),FIND("[",CELL("filename",A1))-1)&"2.사전토공사\1_Site Survey\체크리스트\Site Survey_체크리스트.html", "👉 [클릭] 체크리스트 열기 📄")
A3: 9000 | B3: 9000-2 | C3: 사전토공사 | D3: 9000-2-2 | E3: 9000-2-1 | F3: 9000-2-10, 9000-2-12 | G3: 공사중 교통처리계획 | H3: D-60 (D-80~D-60) | I3: 현장 공사팀 | J3: 도로교통법 제69조 | 동탄경찰서 교통안전 심의 및 우회 차선 설계 | 전담 신호수(2인 2조) & LED 경광등 배치 | K3: 1) 교통 우회 차선 & 둔차선 도면 설계 ➔ 2) 동탄경찰서 도로점용 허가 ➔ 3) 전담 신호수(2인 2조) 배치 ➔ 4) 교통소통 대책서 감리 서면 승인 | L3: 동탄경찰서 도로점용 허가, 가설 우회 차선 설계 및 전담 안전 신호수(2인 2조)/LED 경광등 배치 | M3: 도로교통법 제69조 | 동탄경찰서 교통안전 심의 및 우회 차선 설계 | 전담 신호수(2인 2조) & LED 경광등 배치 | N3: =HYPERLINK(LEFT(CELL("filename",A1),FIND("[",CELL("filename",A1))-1)&"2.사전토공사\2_발주전략 KOM\표준서\2_발주전략 KOM_표준서.html", "👉 [클릭] 표준서 열기 📄") | O3: 1) 교통 우회 차선 & 둔차선 도면 설계 ➔ 2) 동탄경찰서 도로점용 허가 ➔ 3) 전담 신호수(2인 2조) 배치 ➔ 4) 교통소통 대책서 감리 서면 승인 | P3: =HYPERLINK(LEFT(CELL("filename",A1),FIND("[",CELL("filename",A1))-1)&"2.사전토공사\2_발주전략 KOM\수행지침\2_발주전략 KOM_수행지침.html", "👉 [클릭] 수행지침 열기 📄") | Q3: 동탄경찰서 도로점용 허가, 가설 우회 차선 설계 및 전담 안전 신호수(2인 2조)/LED 경광등 배치 | R3: =HYPERLINK(LEFT(CELL("filename",A1),FIND("[",CELL("filename",A1))-1)&"2.사전토공사\2_발주전략 KOM\체크리스트\2_발주전략 KOM_체크리스트.html", "👉 [클릭] 체크리스트 열기 📄")
A4: 9000 | B4: 9000-2 | C4: 사전토공사 | D4: 9000-2-3 | E4: 9000-2-1 | F4: 9000-2-4, 9000-2-5 | G4: Site Survey Risk 검토 | H4: D-60 (D-70~D-60) | I4: 토목국내견적팀 | J4: 지하안전법 제23조 | 현장 지장물, 연약 지반 층후 및 사면 붕괴 위험 요소 추출 | 사전 토공 리스크 대책 승인 | K4: 1) 지하 매설 지장물 & 연약지반 현출 ➔ 2) 사면 붕괴 위험 구간 추출 ➔ 3) 흙막이 가설재 보강 수립 ➔ 4) 토공 리스크 대책서 감리 승인 | L4: 지중 매설물 탐사, 연약 지반 층후 분석 및 사면 붕괴 위험 구간 흙막이 가설재 보강 수립 | M4: 지하안전법 제23조 | 현장 지장물, 연약 지반 층후 및 사면 붕괴 위험 요소 추출 | 사전 토공 리스크 대책 승인 | N4: =HYPERLINK(LEFT(CELL("filename",A1),FIND("[",CELL("filename",A1))-1)&"2.사전토공사\3_Site Survey Risk 검토\표준서\Site Survey Risk 검토_표준서.html", "👉 [클릭] 표준서 열기 📄") | O4: 1) 지하 매설 지장물 & 연약지반 현출 ➔ 2) 사면 붕괴 위험 구간 추출 ➔ 3) 흙막이 가설재 보강 수립 ➔ 4) 토공 리스크 대책서 감리 승인 | P4: =HYPERLINK(LEFT(CELL("filename",A1),FIND("[",CELL("filename",A1))-1)&"2.사전토공사\3_Site Survey Risk 검토\수행지침\Site Survey Risk 검토_수행지침.html", "👉 [클릭] 수행지침 열기 📄") | Q4: 지중 매설물 탐사, 연약 지반 층후 분석 및 사면 붕괴 위험 구간 흙막이 가설재 보강 수립 | R4: =HYPERLINK(LEFT(CELL("filename",A1),FIND("[",CELL("filename",A1))-1)&"2.사전토공사\3_Site Survey Risk 검토\체크리스트\Site Survey Risk 검토_체크리스트.html", "👉 [클릭] 체크리스트 열기 📄")
A5: 9000 | B5: 9000-2 | C5: 사전토공사 | D5: 9000-2-4 | E5: 9000-2-3 | F5: 9000-2-6 | G5: 최고의 팀 만들기 지원 | H5: D-50 (D-60~D-50) | I5: 외주관리팀 | J5: 건산법 상생협력 수칙 | 토공 전문 기술자 1:1 전담 배치 & 3자 주간 소통 회의 | 일일 Safety TBM 100% 이행 | K5: 1) 토공 전담 기술자 1:1 배치 ➔ 2) 3자 주간 소통 회의 개최 ➔ 3) 근로자 복지 지원 & Safety TBM ➔ 4) One-Team 조직표 감리 서면 승인 | L5: 토공 전담 기술자 1:1 현장 배치, 발주·감리·시공 3자 주간 소통 회의 및 일일 Safety TBM/음주 측정 | M5: 건산법 상생협력 수칙 | 토공 전문 기술자 1:1 전담 배치 & 3자 주간 소통 회의 | 일일 Safety TBM 100% 이행 | N5: =HYPERLINK(LEFT(CELL("filename",A1),FIND("[",CELL("filename",A1))-1)&"2.사전토공사\4_최고의 팀 만들기 지원\표준서\최고의 팀 만들기 지원_표준서.html", "👉 [클릭] 표준서 열기 📄") | O5: 1) 토공 전담 기술자 1:1 배치 ➔ 2) 3자 주간 소통 회의 개최 ➔ 3) 근로자 복지 지원 & Safety TBM ➔ 4) One-Team 조직표 감리 서면 승인 | P5: =HYPERLINK(LEFT(CELL("filename",A1),FIND("[",CELL("filename",A1))-1)&"2.사전토공사\4_최고의 팀 만들기 지원\수행지침\최고의 팀 만들기 지원_수행지침.html", "👉 [클릭] 수행지침 열기 📄") | Q5: 토공 전담 기술자 1:1 현장 배치, 발주·감리·시공 3자 주간 소통 회의 및 일일 Safety TBM/음주 측정 | R5: =HYPERLINK(LEFT(CELL("filename",A1),FIND("[",CELL("filename",A1))-1)&"2.사전토공사\4_최고의 팀 만들기 지원\체크리스트\최고의 팀 만들기 지원_체크리스트.html", "👉 [클릭] 체크리스트 열기 📄")
A6: 9000 | B6: 9000-2 | C6: 사전토공사 | D6: 9000-2-5 | E6: 9000-2-3 | F6: 9000-2-6 | G6: 발주전략 KOM | H6: D-80 (D-120~D-80) | I6: 현장소장 | J6: KCS 47 10 25 시방 검토 | 사전 토공 토사/암석 깎기 및 성토 시방 규정 | 발주처·감리·시공 3자 킥오프 결재 | K6: 1) 사전 토공 시방 요구조건 분석 ➔ 2) 3D BIM 도면 깎기/성토 수량 검증 ➔ 3) 토공 리스크 예비비 수립 ➔ 4) 발주·감리·시공 3자 킥오프 결재 | L6: KCS 47 10 25 사전 토공 시방 검토, 토사/암석 깎기 수량 산출 및 3D BIM 간섭 zero (3자 킥오프 결재) | M6: KCS 47 10 25 시방 검토 | 사전 토공 토사/암석 깎기 및 성토 시방 규정 | 발주처·감리·시공 3자 킥오프 결재 | N6: =HYPERLINK(LEFT(CELL("filename",A1),FIND("[",CELL("filename",A1))-1)&"2.사전토공사\5_공사중 교통처리계획\표준서\공사중 교통처리계획_표준서.html", "👉 [클릭] 표준서 열기 📄") | O6: 1) 사전 토공 시방 요구조건 분석 ➔ 2) 3D BIM 도면 깎기/성토 수량 검증 ➔ 3) 토공 리스크 예비비 수립 ➔ 4) 발주·감리·시공 3자 킥오프 결재 | P6: =HYPERLINK(LEFT(CELL("filename",A1),FIND("[",CELL("filename",A1))-1)&"2.사전토공사\5_공사중 교통처리계획\수행지침\공사중 교통처리계획_수행지침.html", "👉 [클릭] 수행지침 열기 📄") | Q6: KCS 47 10 25 사전 토공 시방 검토, 토사/암석 깎기 수량 산출 및 3D BIM 간섭 zero (3자 킥오프 결재) | R6: =HYPERLINK(LEFT(CELL("filename",A1),FIND("[",CELL("filename",A1))-1)&"2.사전토공사\5_공사중 교통처리계획\체크리스트\공사중 교통처리계획_체크리스트.html", "👉 [클릭] 체크리스트 열기 📄")
A7: 9000 | B7: 9000-2 | C7: 사전토공사 | D7: 9000-2-6 | E7: 9000-2-4, 9000-2-5 | F7: 9000-2-7 | G7: 착수전 Big Room 회의 | H7: D-40 | I7: 현장소장 | J7: 현장 통합 관리 지침 | 발주처·감리·지자체·시공사 4자 빅룸 회의 | 사전 토공 마일스톤 서명 결재 | K7: 1) 4자(발주·감리·지자체·시공) 빅룸 결성 ➔ 2) 사전 토공 마일스톤 연동 ➔ 3) 간섭 리스크 즉시 해소 ➔ 4) 빅룸 회의록 4자 서명 완수 | L7: 4자(발주·감리·지자체·시공) 빅룸 회의 결성, 사전 토공 마일스톤 연동 및 간섭 리스크 서명 | M7: 현장 통합 관리 지침 | 발주처·감리·지자체·시공사 4자 빅룸 회의 | 사전 토공 마일스톤 서명 결재 | N7: =HYPERLINK(LEFT(CELL("filename",A1),FIND("[",CELL("filename",A1))-1)&"2.사전토공사\6_자재발주 요청\표준서\자재발주 요청_표준서.html", "👉 [클릭] 표준서 열기 📄") | O7: 1) 4자(발주·감리·지자체·시공) 빅룸 결성 ➔ 2) 사전 토공 마일스톤 연동 ➔ 3) 간섭 리스크 즉시 해소 ➔ 4) 빅룸 회의록 4자 서명 완수 | P7: =HYPERLINK(LEFT(CELL("filename",A1),FIND("[",CELL("filename",A1))-1)&"2.사전토공사\6_자재발주 요청\수행지침\착수전 Big Room 회의_수행지침.html", "👉 [클릭] 수행지침 열기 📄") | Q7: 4자(발주·감리·지자체·시공) 빅룸 회의 결성, 사전 토공 마일스톤 연동 및 간섭 리스크 서명 | R7: =HYPERLINK(LEFT(CELL("filename",A1),FIND("[",CELL("filename",A1))-1)&"2.사전토공사\6_자재발주 요청\체크리스트\착수전 Big Room 회의_체크리스트.html", "👉 [클릭] 체크리스트 열기 📄")
A8: 9000 | B8: 9000-2 | C8: 사전토공사 | D8: 9000-2-7 | E8: 9000-2-6 | F8: 9000-2-8, 9000-2-9 | G8: 자재발주 요청 | H8: D-65 (D-65~D-55) | I8: 현장 공무팀 | J8: KCS 47 10 25 자재 시방 | 굴착 장비, 가설 펜스 및 배수관 자재 발주 승인 | 공인시험기관 성적표 수속 | K8: 1) 굴착 장비 및 가설 펜스 자재 선정 ➔ 2) 공인시험기관 시험성적서 검수 ➔ 3) 자재 발주 신청서 제출 ➔ 4) 자재 반입 검수 통보서 결재 | L8: KCS 47 10 25 굴착 장비/가설재 자재 승인, 공인시험기관 시험성적서 검수 및 자재 반입 통보 | M8: KCS 47 10 25 자재 시방 | 굴착 장비, 가설 펜스 및 배수관 자재 발주 승인 | 공인시험기관 성적표 수속 | N8: =HYPERLINK(LEFT(CELL("filename",A1),FIND("[",CELL("filename",A1))-1)&"2.사전토공사\7_용지 사용 Risk 검토\표준서\용지 사용 Risk 검토_표준서.html", "👉 [클릭] 표준서 열기 📄") | O8: 1) 굴착 장비 및 가설 펜스 자재 선정 ➔ 2) 공인시험기관 시험성적서 검수 ➔ 3) 자재 발주 신청서 제출 ➔ 4) 자재 반입 검수 통보서 결재 | P8: =HYPERLINK(LEFT(CELL("filename",A1),FIND("[",CELL("filename",A1))-1)&"2.사전토공사\7_용지 사용 Risk 검토\수행지침\용지 사용 Risk 검토_수행지침.html", "👉 [클릭] 수행지침 열기 📄") | Q8: KCS 47 10 25 굴착 장비/가설재 자재 승인, 공인시험기관 시험성적서 검수 및 자재 반입 통보 | R8: =HYPERLINK(LEFT(CELL("filename",A1),FIND("[",CELL("filename",A1))-1)&"2.사전토공사\7_용지 사용 Risk 검토\체크리스트\용지 사용 Risk 검토_체크리스트.html", "👉 [클릭] 체크리스트 열기 📄")
A9: 9000 | B9: 9000-2 | C9: 사전토공사 | D9: 9000-2-8 | E9: 9000-2-7 | F9: 9000-2-11 | G9: 용지 사용 Risk 검토 | H9: D-40 (D-60~D-40) | I9: 토목계약관리팀 | J9: 토지보상법 준수 | 미보상 사유지 경계 현출 및 가설 펜스(H=1.8m) 차단 | 3D 우회 토공 동선 마일스톤 연동 | K9: 1) 미보상 사유지 경계 현출 ➔ 2) 가설 펜스(H=1.8m) 차단 ➔ 3) 3D 우회 토공 동선 수립 ➔ 4) 용지 보상 리스크 대책 감리 승인 | L9: 미보상 사유지 경계 현출, 가설 펜스(H=1.8m) 차단 및 3D 우회 토공 동선 마일스톤 연동 | M9: 토지보상법 준수 | 미보상 사유지 경계 현출 및 가설 펜스(H=1.8m) 차단 | 3D 우회 토공 동선 마일스톤 연동 | N9: =HYPERLINK(LEFT(CELL("filename",A1),FIND("[",CELL("filename",A1))-1)&"2.사전토공사\8_착수전 Big Room 회의\표준서\착수전 Big Room 회의_표준서.html", "👉 [클릭] 표준서 열기 📄") | O9: 1) 미보상 사유지 경계 현출 ➔ 2) 가설 펜스(H=1.8m) 차단 ➔ 3) 3D 우회 토공 동선 수립 ➔ 4) 용지 보상 리스크 대책 감리 승인 | P9: =HYPERLINK(LEFT(CELL("filename",A1),FIND("[",CELL("filename",A1))-1)&"2.사전토공사\8_착수전 Big Room 회의\수행지침\착수전 Big Room 회의_수행지침.html", "👉 [클릭] 수행지침 열기 📄") | Q9: 미보상 사유지 경계 현출, 가설 펜스(H=1.8m) 차단 및 3D 우회 토공 동선 마일스톤 연동 | R9: =HYPERLINK(LEFT(CELL("filename",A1),FIND("[",CELL("filename",A1))-1)&"2.사전토공사\8_착수전 Big Room 회의\체크리스트\착수전 Big Room 회의_체크리스트.html", "👉 [클릭] 체크리스트 열기 📄")
A10: 9000 | B10: 9000-2 | C10: 사전토공사 | D10: 9000-2-9 | E10: 9000-2-7 | F10: 9000-2-11 | G10: 인허가 절차 진행 | H10: D-30 | I10: 현장 공무팀 | J10: 도로법 및 환경영향평가법 | 지자체 도로점용 허가 및 비산먼지 발생신고 수속 | 법정 인허가 필증 수속 | K10: 1) 지자체 도로/하천점용 허가서 작성 ➔ 2) 관련 부서 서류 제출 & 심의 ➔ 3) 보증보험 증권 부착 ➔ 4) 법정 인허가 필증 감리 수속 | L10: 지자체 도로/하천점용 허가서 접수, 비산먼지 발생사업 신고 필증 수속 및 보증보험 제출 | M10: 도로법 및 환경영향평가법 | 지자체 도로점용 허가 및 비산먼지 발생신고 수속 | 법정 인허가 필증 수속 | N10: =HYPERLINK(LEFT(CELL("filename",A1),FIND("[",CELL("filename",A1))-1)&"2.사전토공사\9_인허가 절차 진행\표준서\인허가 절차 진행_표준서.html", "👉 [클릭] 표준서 열기 📄") | O10: 1) 지자체 도로/하천점용 허가서 작성 ➔ 2) 관련 부서 서류 제출 & 심의 ➔ 3) 보증보험 증권 부착 ➔ 4) 법정 인허가 필증 감리 수속 | P10: =HYPERLINK(LEFT(CELL("filename",A1),FIND("[",CELL("filename",A1))-1)&"2.사전토공사\9_인허가 절차 진행\수행지침\인허가 절차 진행_수행지침.html", "👉 [클릭] 수행지침 열기 📄") | Q10: 지자체 도로/하천점용 허가서 접수, 비산먼지 발생사업 신고 필증 수속 및 보증보험 제출 | R10: =HYPERLINK(LEFT(CELL("filename",A1),FIND("[",CELL("filename",A1))-1)&"2.사전토공사\9_인허가 절차 진행\체크리스트\인허가 절차 진행_체크리스트.html", "👉 [클릭] 체크리스트 열기 📄")
A11: 9000 | B11: 9000-2 | C11: 사전토공사 | D11: 9000-2-10 | E11: 9000-2-2 | F11: 9000-2-12, 9000-2-13 | G11: 교통처리대책 협의 및 승인 | H11: D-30 | I11: 현장 공무팀 | J11: 도로교통법 안전 수칙 | 경찰서 차선 점용 허가 및 가설 둔차선 도로 복구 이행 보증보험 | 교통대책 감리 승인 | K11: 1) 경찰서 차선 점용 허가증 수령 ➔ 2) 도로 복구 보증보험 증권 제출 ➔ 3) 전담 신호수 & LED 경광등 배치 ➔ 4) 교통대책서 감리 서면 승인 | L11: 동탄경찰서 차선 점용 허가, 도로 복구 이행 보증보험 제출 및 전담 신호수(2인 2조) 100% 배치 | M11: 도로교통법 안전 수칙 | 경찰서 차선 점용 허가 및 가설 둔차선 도로 복구 이행 보증보험 | 교통대책 감리 승인 | N11: =HYPERLINK(LEFT(CELL("filename",A1),FIND("[",CELL("filename",A1))-1)&"2.사전토공사\10_교통처리대책 협의 및 승인\표준서\교통처리대책 협의 및 승인_표준서.html", "👉 [클릭] 표준서 열기 📄") | O11: 1) 경찰서 차선 점용 허가증 수령 ➔ 2) 도로 복구 보증보험 증권 제출 ➔ 3) 전담 신호수 & LED 경광등 배치 ➔ 4) 교통대책서 감리 서면 승인 | P11: =HYPERLINK(LEFT(CELL("filename",A1),FIND("[",CELL("filename",A1))-1)&"2.사전토공사\10_교통처리대책 협의 및 승인\수행지침\교통처리대책 협의 및 승인_수행지침.html", "👉 [클릭] 수행지침 열기 📄") | Q11: 동탄경찰서 차선 점용 허가, 도로 복구 이행 보증보험 제출 및 전담 신호수(2인 2조) 100% 배치 | R11: =HYPERLINK(LEFT(CELL("filename",A1),FIND("[",CELL("filename",A1))-1)&"2.사전토공사\10_교통처리대책 협의 및 승인\체크리스트\교통처리대책 협의 및 승인_체크리스트.html", "👉 [클릭] 체크리스트 열기 📄")
A12: 9000 | B12: 9000-2 | C12: 사전토공사 | D12: 9000-2-11 | E12: 9000-2-8, 9000-2-9 | F12: 9000-2-13 | G12: 지장물 검토 및 협의 | H12: D-30 | I12: 현장 공무팀/공사팀 | J12: 지하안전관리에 관한 특별법 | GPR 3D 관로 탐사 & 인력 시탐 줄파기(깊이 1.5m) | 점용기관 현장 입회 이설 방호 | K12: 1) GPR 3D 지중 관로 탐사 ➔ 2) 인력 시탐 줄파기(깊이 1.5m) ➔ 3) 관할 점용기관 1:1 현장 입회 ➔ 4) 매달기 방호 & 지장물 서면 승인 | L12: GPR 3D 관로 탐사, 인력 시탐 줄파기(폭 0.5m, 깊이 1.5m) 및 점용기관 1:1 현장 입회 매달기 방호 | M12: 지하안전관리에 관한 특별법 | GPR 3D 관로 탐사 & 인력 시탐 줄파기(깊이 1.5m) | 점용기관 현장 입회 이설 방호 | N12: =HYPERLINK(LEFT(CELL("filename",A1),FIND("[",CELL("filename",A1))-1)&"2.사전토공사\11_지장물 검토 및 협의\표준서\지장물 검토 및 협의_표준서.html", "👉 [클릭] 표준서 열기 📄") | O12: 1) GPR 3D 지중 관로 탐사 ➔ 2) 인력 시탐 줄파기(깊이 1.5m) ➔ 3) 관할 점용기관 1:1 현장 입회 ➔ 4) 매달기 방호 & 지장물 서면 승인 | P12: =HYPERLINK(LEFT(CELL("filename",A1),FIND("[",CELL("filename",A1))-1)&"2.사전토공사\11_지장물 검토 및 협의\수행지침\지장물 검토 및 협의_수행지침.html", "👉 [클릭] 수행지침 열기 📄") | Q12: GPR 3D 관로 탐사, 인력 시탐 줄파기(폭 0.5m, 깊이 1.5m) 및 점용기관 1:1 현장 입회 매달기 방호 | R12: =HYPERLINK(LEFT(CELL("filename",A1),FIND("[",CELL("filename",A1))-1)&"2.사전토공사\11_지장물 검토 및 협의\체크리스트\지장물 검토 및 협의_체크리스트.html", "👉 [클릭] 체크리스트 열기 📄")
A13: 9000 | B13: 9000-2 | C13: 사전토공사 | D13: 9000-2-12 | E13: 9000-2-2, 9000-2-10 | F13: 9000-2-14, 9000-2-15 | G13: 기공승낙 적정성 검토 | H13: D-30 | I13: 현장 공무팀 | J13: 국유재산법 및 공유재산법 | 토지 기공승낙서 인허가 확인 및 진입로 점용 범위 실측 | 토지 사용 승인서 결재 | K13: 1) 국유지/공유지 기공승낙서 수속 ➔ 2) 진입 도로 점용 범위 실측 ➔ 3) 토지 소유주 사용 협의 ➔ 4) 기공승낙서 감리 서면 승인 | L13: 국유지/공유지 기공승낙서 인허가 검증, 진입 도로 점용 범위 실측 및 토지 사용 승인서 결재 | M13: 국유재산법 및 공유재산법 | 토지 기공승낙서 인허가 확인 및 진입로 점용 범위 실측 | 토지 사용 승인서 결재 | N13: =HYPERLINK(LEFT(CELL("filename",A1),FIND("[",CELL("filename",A1))-1)&"2.사전토공사\12_기공승낙 적정성 검토\표준서\기공승낙 적정성 검토_표준서.html", "👉 [클릭] 표준서 열기 📄") | O13: 1) 국유지/공유지 기공승낙서 수속 ➔ 2) 진입 도로 점용 범위 실측 ➔ 3) 토지 소유주 사용 협의 ➔ 4) 기공승낙서 감리 서면 승인 | P13: =HYPERLINK(LEFT(CELL("filename",A1),FIND("[",CELL("filename",A1))-1)&"2.사전토공사\12_기공승낙 적정성 검토\수행지침\기공승낙 적정성 검토_수행지침.html", "👉 [클릭] 수행지침 열기 📄") | Q13: 국유지/공유지 기공승낙서 인허가 검증, 진입 도로 점용 범위 실측 및 토지 사용 승인서 결재 | R13: =HYPERLINK(LEFT(CELL("filename",A1),FIND("[",CELL("filename",A1))-1)&"2.사전토공사\12_기공승낙 적정성 검토\체크리스트\기공승낙 적정성 검토_체크리스트.html", "👉 [클릭] 체크리스트 열기 📄")
A14: 9000 | B14: 9000-2 | C14: 사전토공사 | D14: 9000-2-13 | E14: 9000-2-10, 9000-2-11 | F14: 9000-2-14 | G14: 민원 저감 대책 수립 | H14: D-30 | I14: 현장 안전팀/공무팀 | J14: 소음진동관리법 준수 | 야간 공사 소음 방음벽(H=3m) 및 세륜기(깊이 1.2m) 가동 | 단수/단전 주민 사전 안내 | K14: 1) 야간 공사 소음 방음벽(H=3m) 설치 ➔ 2) 세륜기 가동 & 분무 살수 ➔ 3) 단수/단전 사전 주민 공지 ➔ 4) 민원 대응반 서면 승인 | L14: 야간 공사 소음 방음벽(H=3m) 가동, 세륜기(깊이 1.2m) 가동 및 단수/단전 주민 사전 고지 | M14: 소음진동관리법 준수 | 야간 공사 소음 방음벽(H=3m) 및 세륜기(깊이 1.2m) 가동 | 단수/단전 주민 사전 안내 | N14: =HYPERLINK(LEFT(CELL("filename",A1),FIND("[",CELL("filename",A1))-1)&"2.사전토공사\13_민원 저감 대책 수립\표준서\민원 저감 대책 수립_표준서.html", "👉 [클릭] 표준서 열기 📄") | O14: 1) 야간 공사 소음 방음벽(H=3m) 설치 ➔ 2) 세륜기 가동 & 분무 살수 ➔ 3) 단수/단전 사전 주민 공지 ➔ 4) 민원 대응반 서면 승인 | P14: =HYPERLINK(LEFT(CELL("filename",A1),FIND("[",CELL("filename",A1))-1)&"2.사전토공사\13_민원 저감 대책 수립\수행지침\민원 저감 대책 수립_수행지침.html", "👉 [클릭] 수행지침 열기 📄") | Q14: 야간 공사 소음 방음벽(H=3m) 가동, 세륜기(깊이 1.2m) 가동 및 단수/단전 주민 사전 고지 | R14: =HYPERLINK(LEFT(CELL("filename",A1),FIND("[",CELL("filename",A1))-1)&"2.사전토공사\13_민원 저감 대책 수립\체크리스트\민원 저감 대책 수립_체크리스트.html", "👉 [클릭] 체크리스트 열기 📄")
A15: 9000 | B15: 9000-2 | C15: 사전토공사 | D15: 9000-2-14 | E15: 9000-2-12, 9000-2-13 | F15: 9000-2-15, 9000-2-16 | G15: 용지보상 Risk 파악 | H15: D-30 | I15: 현장 공무팀 | J15: 토지보상법 준수 | 지장물 이설 부지 용지보상 현황 및 점용 경계 실측 | 미보상 사유지 가설 펜스 차단 | K15: 1) 미보상 필지 현출 & 지적 대조 ➔ 2) 가설 펜스(H=1.8m) 차단 ➔ 3) 우회 토공 동선 수립 ➔ 4) 용지 보상 대책서 감리 승인 | L15: 미보상 필지 지적 대조, 경계 가설 펜스(H=1.8m) 차단 및 우회 토공 동선 서면 승인 | M15: 토지보상법 준수 | 지장물 이설 부지 용지보상 현황 및 점용 경계 실측 | 미보상 사유지 가설 펜스 차단 | N15: =HYPERLINK(LEFT(CELL("filename",A1),FIND("[",CELL("filename",A1))-1)&"2.사전토공사\14_용지보상 Risk 파악\표준서\용지보상 Risk 파악_표준서.html", "👉 [클릭] 표준서 열기 📄") | O15: 1) 미보상 필지 현출 & 지적 대조 ➔ 2) 가설 펜스(H=1.8m) 차단 ➔ 3) 우회 토공 동선 수립 ➔ 4) 용지 보상 대책서 감리 승인 | P15: =HYPERLINK(LEFT(CELL("filename",A1),FIND("[",CELL("filename",A1))-1)&"2.사전토공사\14_용지보상 Risk 파악\수행지침\용지보상 Risk 파악_수행지침.html", "👉 [클릭] 수행지침 열기 📄") | Q15: 미보상 필지 지적 대조, 경계 가설 펜스(H=1.8m) 차단 및 우회 토공 동선 서면 승인 | R15: =HYPERLINK(LEFT(CELL("filename",A1),FIND("[",CELL("filename",A1))-1)&"2.사전토공사\14_용지보상 Risk 파악\체크리스트\용지보상 Risk 파악_체크리스트.html", "👉 [클릭] 체크리스트 열기 📄")
A16: 9000 | B16: 9000-2 | C16: 사전토공사 | D16: 9000-2-15 | E16: 9000-2-12, 9000-2-14 | F16: 9000-2-16, 9000-2-17 | G16: 시공계획서 검토 지원 | H16: D-30 | I16: 토목품질팀 | J16: 건진법 시행령 제89조 | 사전 토공 시공계획서 표준 8대 목차 검토 | 착공 14일 전 감리 서면 승인 | K16: 1) 사전 토공 시공계획서 작성 ➔ 2) 8대 목차 & KCS 수치 명시 ➔ 3) 착공 14일 전 감리단 제출 ➔ 4) 시공계획서 감리 서면 승인 | L16: 사전 토공 시공계획서 표준 8대 목차, KCS 수치 수록 및 착공 14일 전 감리 서면 승인 | M16: 건진법 시행령 제89조 | 사전 토공 시공계획서 표준 8대 목차 검토 | 착공 14일 전 감리 서면 승인 | N16: =HYPERLINK(LEFT(CELL("filename",A1),FIND("[",CELL("filename",A1))-1)&"2.사전토공사\15_시공계획서 검토 지원\표준서\시공계획서 검토 지원_표준서.html", "👉 [클릭] 표준서 열기 📄") | O16: 1) 사전 토공 시공계획서 작성 ➔ 2) 8대 목차 & KCS 수치 명시 ➔ 3) 착공 14일 전 감리단 제출 ➔ 4) 시공계획서 감리 서면 승인 | P16: =HYPERLINK(LEFT(CELL("filename",A1),FIND("[",CELL("filename",A1))-1)&"2.사전토공사\15_시공계획서 검토 지원\수행지침\시공계획서 검토 지원_수행지침.html", "👉 [클릭] 수행지침 열기 📄") | Q16: 사전 토공 시공계획서 표준 8대 목차, KCS 수치 수록 및 착공 14일 전 감리 서면 승인 | R16: =HYPERLINK(LEFT(CELL("filename",A1),FIND("[",CELL("filename",A1))-1)&"2.사전토공사\15_시공계획서 검토 지원\체크리스트\시공계획서 검토 지원_체크리스트.html", "👉 [클릭] 체크리스트 열기 📄")
A17: 9000 | B17: 9000-2 | C17: 사전토공사 | D17: 9000-2-16 | E17: 9000-2-14, 9000-2-15 | F17: 9000-2-17, 9000-2-18 | G17: 설계변경 (착수전) | H17: D-30 | I17: 현장 공무팀/공사팀 | J17: 지방계약법 정산 수칙 | 착수 전 토종 변경 및 수량 증감 실정보고 작성 | 총사업비 변경 승인 수속 | K17: 1) 토질 변경 & 수량 증감 실정보고 작성 ➔ 2) 단가 비교표 작성 ➔ 3) 설계변경 도서 제출 ➔ 4) 총사업비 변경 승인 결재 | L17: 토질 변경 & 수량 증감 실정보고서 작성, 단가 비교표 작성 및 총사업비 변경 승인 결재 | M17: 지방계약법 정산 수칙 | 착수 전 토종 변경 및 수량 증감 실정보고 작성 | 총사업비 변경 승인 수속 | N17: =HYPERLINK(LEFT(CELL("filename",A1),FIND("[",CELL("filename",A1))-1)&"2.사전토공사\16_시공계획 수립\표준서\설계변경 (착수전)_표준서.html", "👉 [클릭] 표준서 열기 📄") | O17: 1) 토질 변경 & 수량 증감 실정보고 작성 ➔ 2) 단가 비교표 작성 ➔ 3) 설계변경 도서 제출 ➔ 4) 총사업비 변경 승인 결재 | P17: =HYPERLINK(LEFT(CELL("filename",A1),FIND("[",CELL("filename",A1))-1)&"2.사전토공사\16_시공계획 수립\수행지침\설계변경 (착수전)_수행지침.html", "👉 [클릭] 수행지침 열기 📄") | Q17: 토질 변경 & 수량 증감 실정보고서 작성, 단가 비교표 작성 및 총사업비 변경 승인 결재 | R17: =HYPERLINK(LEFT(CELL("filename",A1),FIND("[",CELL("filename",A1))-1)&"2.사전토공사\16_시공계획 수립\체크리스트\설계변경 (착수전)_체크리스트.html", "👉 [클릭] 체크리스트 열기 📄")
A18: 9000 | B18: 9000-2 | C18: 사전토공사 | D18: 9000-2-17 | E18: 9000-2-15, 9000-2-16 | F18: 9000-2-19 | G18: 시공계획 수립 | H18: D-30 | I18: 현장 공사팀 | J18: KCS 47 10 25 토공 시방 | 깎기/성토 토공 유동표 작성 및 3D BIM 도면 대조 | 책임감리원 최종 승인 | K18: 1) 토공 깎기/성토 유동표 작성 ➔ 2) 3D BIM 모델 표고 대조 ➔ 3) 사면 안성성 계산서 부착 ➔ 4) 토공 시공계획서 감리 최종 결재 | L18: 토공 깎기/성토 유동표 작성, 3D BIM 모델 표고 대조 및 사면 안전성 계산서 감리 결재 | M18: KCS 47 10 25 토공 시방 | 깎기/성토 토공 유동표 작성 및 3D BIM 도면 대조 | 책임감리원 최종 승인 | N18: =HYPERLINK(LEFT(CELL("filename",A1),FIND("[",CELL("filename",A1))-1)&"2.사전토공사\17_후행공종 요구조건 반영 설계변경 검토\표준서\후행공종 요구조건 반영 설계변경 검토_표준서.html", "👉 [클릭] 표준서 열기 📄") | O18: 1) 토공 깎기/성토 유동표 작성 ➔ 2) 3D BIM 모델 표고 대조 ➔ 3) 사면 안성성 계산서 부착 ➔ 4) 토공 시공계획서 감리 최종 결재 | P18: =HYPERLINK(LEFT(CELL("filename",A1),FIND("[",CELL("filename",A1))-1)&"2.사전토공사\17_후행공종 요구조건 반영 설계변경 검토\수행지침\후행공종 요구조건 반영 설계변경 검토_수행지침.html", "👉 [클릭] 수행지침 열기 📄") | Q18: 토공 깎기/성토 유동표 작성, 3D BIM 모델 표고 대조 및 사면 안전성 계산서 감리 결재 | R18: =HYPERLINK(LEFT(CELL("filename",A1),FIND("[",CELL("filename",A1))-1)&"2.사전토공사\17_후행공종 요구조건 반영 설계변경 검토\체크리스트\후행공종 요구조건 반영 설계변경 검토_체크리스트.html", "👉 [클릭] 체크리스트 열기 📄")
A19: 9000 | B19: 9000-2 | C19: 사전토공사 | D19: 9000-2-18 | E19: 9000-2-16 | F19: 9000-2-19, 9000-2-20 | G19: 후행공종 요구조건 반영 설계변경 검토 | H19: D-30 | I19: 현장 공무팀/공사팀 | J19: 건진법 설계변경 수칙 | 궤도/구조물 후행 공종 요구 표고 오차(±10mm) 반영 | 설계변경 실정보고서 작성 | K19: 1) 궤도/구조물 후행 요구 조건 수집 ➔ 2) 마무리면 표고 오차(±10mm) 반영 ➔ 3) 설계변경 실정보고서 작성 ➔ 4) 책임감리원 기술 승인 | L19: 궤도/구조물 후행 요구 조건 반영, 마무리면 표고 오차(±10mm) 반영 및 설계변경 실정보고 | M19: 건진법 설계변경 수칙 | 궤도/구조물 후행 공종 요구 표고 오차(±10mm) 반영 | 설계변경 실정보고서 작성 | N19: =HYPERLINK(LEFT(CELL("filename",A1),FIND("[",CELL("filename",A1))-1)&"2.사전토공사\18_설계변경 (착수전)\표준서\설계변경 (착수전)_표준서.html", "👉 [클릭] 표준서 열기 📄") | O19: 1) 궤도/구조물 후행 요구 조건 수집 ➔ 2) 마무리면 표고 오차(±10mm) 반영 ➔ 3) 설계변경 실정보고서 작성 ➔ 4) 책임감리원 기술 승인 | P19: =HYPERLINK(LEFT(CELL("filename",A1),FIND("[",CELL("filename",A1))-1)&"2.사전토공사\18_설계변경 (착수전)\수행지침\설계변경 (착수전)_수행지침.html", "👉 [클릭] 수행지침 열기 📄") | Q19: 궤도/구조물 후행 요구 조건 반영, 마무리면 표고 오차(±10mm) 반영 및 설계변경 실정보고 | R19: =HYPERLINK(LEFT(CELL("filename",A1),FIND("[",CELL("filename",A1))-1)&"2.사전토공사\18_설계변경 (착수전)\체크리스트\설계변경 (착수전)_체크리스트.html", "👉 [클릭] 체크리스트 열기 📄")
A20: 9000 | B20: 9000-2 | C20: 사전토공사 | D20: 9000-2-19 | E20: 9000-2-17, 9000-2-18 | F20: 9000-2-21, 9000-2-22 | G20: 설계변경 지원 | H20: D-30 | I20: 토목수행팀 | J20: 건진법 설계변경 규정 | 수량 산출서 및 단가 비교표 작성 | 책임감리원 기술 검토 의견서 첨부 | K20: 1) 변경 수량 산출서 정밀 집계 ➔ 2) 신규 단가 산정 서류 부착 ➔ 3) 감리단 기술 검토 수속 ➔ 4) 설계변경 제출 서면 결재 | L20: 변경 수량 산출서 정밀 집계, 신규 단가 산정 서류 첨부 및 책임감리원 기술 검토 수속 | M20: 건진법 설계변경 규정 | 수량 산출서 및 단가 비교표 작성 | 책임감리원 기술 검토 의견서 첨부 | N20: =HYPERLINK(LEFT(CELL("filename",A1),FIND("[",CELL("filename",A1))-1)&"2.사전토공사\18_설계변경_착수전\표준서\후행공종 요구조건 반영 설계변경 검토_표준서.html", "👉 [클릭] 표준서 열기 📄") | O20: 1) 변경 수량 산출서 정밀 집계 ➔ 2) 신규 단가 산정 서류 부착 ➔ 3) 감리단 기술 검토 수속 ➔ 4) 설계변경 제출 서면 결재 | P20: =HYPERLINK(LEFT(CELL("filename",A1),FIND("[",CELL("filename",A1))-1)&"2.사전토공사\18_설계변경_착수전\수행지침\후행공종 요구조건 반영 설계변경 검토_수행지침.html", "👉 [클릭] 수행지침 열기 📄") | Q20: 변경 수량 산출서 정밀 집계, 신규 단가 산정 서류 첨부 및 책임감리원 기술 검토 수속 | R20: =HYPERLINK(LEFT(CELL("filename",A1),FIND("[",CELL("filename",A1))-1)&"2.사전토공사\18_설계변경_착수전\체크리스트\후행공종 요구조건 반영 설계변경 검토_체크리스트.html", "👉 [클릭] 체크리스트 열기 📄")
